Workbook

Sheet Q2 2026 Summary
C2: Multifamily Market Summary — Q2 2026 | P2: Hold Period (Yrs) | R2: Value Add Rev | S2: Expense Growth | AB2: Going-In Cap Rate | AD2: Basis Growth | AK2: Lev Yield
C3: Effective RPSF | Rent Roll PSF | Effective Rent Ratio (Eff. RPSF ÷ Rent Roll PSF) | P3: 5 | R3: 0.051 | S3: 0.025 | AB3: 0.05 | AD3: 0.08 | AK3: 0.05
B4: # | C4: Market | D4: Rent Roll PSF | E4: Asking RPSF | F4: Gross Rent Ratio | G4: Unit Starts as % of Inv | H4: Gross Embedded RR Mark to Market | I4: Effective RPSF | J4: Eff. Rent Ratio | K4: Effective Embedded RR Mark to Market | L4: 10-year Historical Avg Rent Growth (GSA) | M4: 10-year Historical Avg Rent Growth (RP) | N4: 10-year Avg Hist. Rent Growth (GSA & RP) | O4: PF Yrs Negative | P4: PF Organic Revenue Growth | Q4: PF Organic Rev CAGR | R4: PF Total Revenue Growth | S4: Expense Growth | T4: Initial NOI | U4: Initial Revenue | V4: Initial Expenses | W4: Terminal Revenue | X4: Terminal Expenses | Y4: Terminal NOI | Z4: Total PF NOI Growth | AA4: PF NOI CAGR | AB4: Going-In Cap Rate | AC4: Initial Basis | AD4: Residual Basis | AE4: Going in NOI | AF4: Residual NOI | AG4: Residual YOC | AH4: Cap Rate Growth | AI4: Rounded | AJ4: LIRR From Appreciation | AK4: LIRR from Yield | AL4: PF LIRR
B5: 1 | C5: Wichita, KS | D5: =SUMIFS(Realpage!$I:$I,Realpage!$A:$A,$C5,Realpage!$F:$F,"Rent Roll (Rev/OSF)") -> 2.1056087 | E5: =SUMIFS(Realpage!$I:$I,Realpage!$A:$A,$C5,Realpage!$F:$F,"Asking RPSF") -> 2.338 | F5: =E5/D5 -> 1.1103678 | G5: {=SUMPRODUCT(('RP - Unit Starts'!$C$2:$C$101=$C5)*('RP - Unit Starts'!$F$2:$F$101="Unit Starts")*'RP - Unit Starts'!$I$2:$L$101)/SUMIFS('RP - Unit Starts'!$L:$L,'RP - Unit Starts'!$C:$C,$C5,'RP - Unit Starts'!$F:$F,"Existing Units")} -> 0.0038874164 | H5: =F5-1 -> 0.11036776 | I5: =SUMIFS(Realpage!$I:$I,Realpage!$A:$A,$C5,Realpage!$F:$F,"Effective RPSF") -> 2.331 | J5: =I5/D5 -> 1.1070433 | K5: =J5-1 -> 0.1070433 | M5: =AVERAGEIF('Realpage - His. Rent Change'!$A$2:$A$577,'Q2 2026 Summary'!C5,'Realpage - His. Rent Change'!$I$2:$AV$577) -> 0.0451 | N5: =AVERAGE(L5:M5) -> 0.0451 | O5: =MAX(0,-(K5/M5)) -> 0 | P5: =($P$3*M5)+K5 -> 0.3325433 | Q5: =(1+P5)^(1/$P$3)-1 -> 0.059098289 | R5: =$R$3+P5 -> 0.3835433 | S5: =$S$3*$P$3 -> 0.125 | T5: =SUMIFS(Realpage!$I:$I,Realpage!$A:$A,$C5,Realpage!$F:$F,"NOI % of Revenue") -> 1.1619755 | U5: 1 | V5: =U5-T5 -> -0.1619755 | W5: =U5*(1+R5) -> 1.3835433 | X5: =V5*(1+S5) -> -0.18222243 | Y5: =W5-X5 -> 1.5657657 | Z5: =Y5/T5-1 -> 0.34750323 | AA5: =(Y5/T5)^(1/$P$3)-1 -> 0.061465695 | AB5: =$AB$3 -> 0.05 | AC5: =AB5/$AB$3 -> 1 | AD5: =AC5*(1+$AD$3) -> 1.08 | AE5: =AC5*AB5 -> 0.05 | AF5: =AE5*(1+Z5) -> 0.067375162 | AG5: =AF5/AD5 -> 0.062384409 | AH5: =AG5-AB5 -> 0.012384409 | AI5: =ROUND(AH5,4) -> 0.0124 | AJ5: {=INDEX('Cap Rate to IRR Map'!$F$3:$F$623,MATCH(ROUND(AI5,4),ROUND('Cap Rate to IRR Map'!$E$3:$E$623,4),0))} -> 0.111 | AK5: =$AK$3 -> 0.05 | AL5: 0.2075 | AO5: Any outsized VA opportuntiies to enhance growth
B6: 2 | C6: Salt Lake City/Ogden/Brigham City, UT-ID | D6: =SUMIFS(Realpage!$I:$I,Realpage!$A:$A,$C6,Realpage!$F:$F,"Rent Roll (Rev/OSF)") -> 3.1832356 | E6: =SUMIFS(Realpage!$I:$I,Realpage!$A:$A,$C6,Realpage!$F:$F,"Asking RPSF") -> 3.455 | F6: =E6/D6 -> 1.0853736 | G6: {=SUMPRODUCT(('RP - Unit Starts'!$C$2:$C$101=$C6)*('RP - Unit Starts'!$F$2:$F$101="Unit Starts")*'RP - Unit Starts'!$I$2:$L$101)/SUMIFS('RP - Unit Starts'!$L:$L,'RP - Unit Starts'!$C:$C,$C6,'RP - Unit Starts'!$F:$F,"Existing Units")} -> 0.011486296 | H6: =F6-1 -> 0.085373647 | I6: =SUMIFS(Realpage!$I:$I,Realpage!$A:$A,$C6,Realpage!$F:$F,"Effective RPSF") -> 3.351 | J6: =I6/D6 -> 1.0527025 | K6: =J6-1 -> 0.052702487 | L6: 0.0423 | M6: =AVERAGEIF('Realpage - His. Rent Change'!$A$2:$A$577,'Q2 2026 Summary'!C12,'Realpage - His. Rent Change'!$I$2:$AV$577) -> 0.038 | N6: =AVERAGE(L6:M6) -> 0.04015 | O6: =MAX(0,-(K6/M6)) -> 0 | P6: =($P$3*M6)+K6 -> 0.24270249 | Q6: =(1+P6)^(1/$P$3)-1 -> 0.044415801 | R6: =$R$3+P6 -> 0.29370249 | S6: =$S$3*$P$3 -> 0.125 | T6: =SUMIFS(Realpage!$I:$I,Realpage!$A:$A,$C6,Realpage!$F:$F,"NOI % of Revenue") -> 1.2728915 | U6: 1 | V6: =U6-T6 -> -0.27289146 | W6: =U6*(1+R6) -> 1.2937025 | X6: =V6*(1+S6) -> -0.30700289 | Y6: =W6-X6 -> 1.6007054 | Z6: =Y6/T6-1 -> 0.25753486 | AA6: =(Y6/T6)^(1/$P$3)-1 -> 0.046897123 | AB6: =$AB$3 -> 0.05 | AC6: =AB6/$AB$3 -> 1 | AD6: =AC6*(1+$AD$3) -> 1.08 | AE6: =AC6*AB6 -> 0.05 | AF6: =AE6*(1+Z6) -> 0.062876743 | AG6: =AF6/AD6 -> 0.058219206 | AH6: =AG6-AB6 -> 0.0082192063 | AI6: =ROUND(AH6,4) -> 0.0082 | AJ6: {=INDEX('Cap Rate to IRR Map'!$F$3:$F$623,MATCH(ROUND(AI6,4),ROUND('Cap Rate to IRR Map'!$E$3:$E$623,4),0))} -> 0.076333 | AK6: =$AK$3 -> 0.05 | AL6: 0.15 | AO6: Washington DC
B7: =B6+1 -> 3 | C7: Reno, NV | D7: =SUMIFS(Realpage!$I:$I,Realpage!$A:$A,$C7,Realpage!$F:$F,"Rent Roll (Rev/OSF)") -> 3.6695941 | E7: =SUMIFS(Realpage!$I:$I,Realpage!$A:$A,$C7,Realpage!$F:$F,"Asking RPSF") -> 3.965 | F7: =E7/D7 -> 1.080501 | G7: {=SUMPRODUCT(('RP - Unit Starts'!$C$2:$C$101=$C7)*('RP - Unit Starts'!$F$2:$F$101="Unit Starts")*'RP - Unit Starts'!$I$2:$L$101)/SUMIFS('RP - Unit Starts'!$L:$L,'RP - Unit Starts'!$C:$C,$C7,'RP - Unit Starts'!$F:$F,"Existing Units")} -> 0.023921244 | H7: =F7-1 -> 0.08050096 | I7: =SUMIFS(Realpage!$I:$I,Realpage!$A:$A,$C7,Realpage!$F:$F,"Effective RPSF") -> 3.929 | J7: =I7/D7 -> 1.0706906 | K7: =J7-1 -> 0.070690611 | M7: =AVERAGEIF('Realpage - His. Rent Change'!$A$2:$A$577,'Q2 2026 Summary'!C9,'Realpage - His. Rent Change'!$I$2:$AV$577) -> 0.0467 | N7: =AVERAGE(L7:M7) -> 0.0467 | O7: =MAX(0,-(K7/M7)) -> 0 | P7: =($P$3*M7)+K7 -> 0.30419061 | Q7: =(1+P7)^(1/$P$3)-1 -> 0.05455252 | R7: =$R$3+P7 -> 0.35519061 | S7: =$S$3*$P$3 -> 0.125 | T7: =SUMIFS(Realpage!$I:$I,Realpage!$A:$A,$C7,Realpage!$F:$F,"NOI % of Revenue") -> 1.19992 | U7: 1 | V7: =U7-T7 -> -0.19992 | W7: =U7*(1+R7) -> 1.3551906 | X7: =V7*(1+S7) -> -0.22491 | Y7: =W7-X7 -> 1.5801006 | Z7: =Y7/T7-1 -> 0.3168383 | AA7: =(Y7/T7)^(1/$P$3)-1 -> 0.056589985 | AB7: =$AB$3 -> 0.05 | AC7: =AB7/$AB$3 -> 1 | AD7: =AC7*(1+$AD$3) -> 1.08 | AE7: =AC7*AB7 -> 0.05 | AF7: =AE7*(1+Z7) -> 0.065841915 | AG7: =AF7/AD7 -> 0.060964736 | AH7: =AG7-AB7 -> 0.010964736 | AI7: =ROUND(AH7,4) -> 0.011 | AJ7: {=INDEX('Cap Rate to IRR Map'!$F$3:$F$623,MATCH(ROUND(AI7,4),ROUND('Cap Rate to IRR Map'!$E$3:$E$623,4),0))} -> 0.1 | AK7: =$AK$3 -> 0.05 | AL7: 0.1965
B8: =B7+1 -> 4 | C8: Columbus, OH | D8: =SUMIFS(Realpage!$I:$I,Realpage!$A:$A,$C8,Realpage!$F:$F,"Rent Roll (Rev/OSF)") -> 2.8266178 | E8: =SUMIFS(Realpage!$I:$I,Realpage!$A:$A,$C8,Realpage!$F:$F,"Asking RPSF") -> 2.999 | F8: =E8/D8 -> 1.0609853 | G8: {=SUMPRODUCT(('RP - Unit Starts'!$C$2:$C$101=$C8)*('RP - Unit Starts'!$F$2:$F$101="Unit Starts")*'RP - Unit Starts'!$I$2:$L$101)/SUMIFS('RP - Unit Starts'!$L:$L,'RP - Unit Starts'!$C:$C,$C8,'RP - Unit Starts'!$F:$F,"Existing Units")} -> 0.018135846 | H8: =F8-1 -> 0.060985307 | I8: =SUMIFS(Realpage!$I:$I,Realpage!$A:$A,$C8,Realpage!$F:$F,"Effective RPSF") -> 2.964 | J8: =I8/D8 -> 1.048603 | K8: =J8-1 -> 0.048603017 | L8: 0.044 | M8: =AVERAGEIF('Realpage - His. Rent Change'!$A$2:$A$577,'Q2 2026 Summary'!C6,'Realpage - His. Rent Change'!$I$2:$AV$577) -> 0.0759 | N8: =AVERAGE(L8:M8) -> 0.05995 | O8: =MAX(0,-(K8/M8)) -> 0 | P8: =($P$3*M8)+K8 -> 0.42810302 | Q8: =(1+P8)^(1/$P$3)-1 -> 0.073870488 | R8: =$R$3+P8 -> 0.47910302 | S8: =$S$3*$P$3 -> 0.125 | T8: =SUMIFS(Realpage!$I:$I,Realpage!$A:$A,$C8,Realpage!$F:$F,"NOI % of Revenue") -> 1.1013939 | U8: 1 | V8: =U8-T8 -> -0.10139388 | W8: =U8*(1+R8) -> 1.479103 | X8: =V8*(1+S8) -> -0.11406811 | Y8: =W8-X8 -> 1.5931711 | Z8: =Y8/T8-1 -> 0.44650444 | AA8: =(Y8/T8)^(1/$P$3)-1 -> 0.076623745 | AB8: =$AB$3 -> 0.05 | AC8: =AB8/$AB$3 -> 1 | AD8: =AC8*(1+$AD$3) -> 1.08 | AE8: =AC8*AB8 -> 0.05 | AF8: =AE8*(1+Z8) -> 0.072325222 | AG8: =AF8/AD8 -> 0.066967798 | AH8: =AG8-AB8 -> 0.016967798 | AI8: =ROUND(AH8,4) -> 0.017 | AJ8: {=INDEX('Cap Rate to IRR Map'!$F$3:$F$623,MATCH(ROUND(AI8,4),ROUND('Cap Rate to IRR Map'!$E$3:$E$623,4),0))} -> 0.146 | AK8: =$AK$3 -> 0.05 | AL8: 0.181
B9: =B8+1 -> 5 | C9: Savannah, GA | D9: =SUMIFS(Realpage!$I:$I,Realpage!$A:$A,$C9,Realpage!$F:$F,"Rent Roll (Rev/OSF)") -> 3.0129341 | E9: =SUMIFS(Realpage!$I:$I,Realpage!$A:$A,$C9,Realpage!$F:$F,"Asking RPSF") -> 3.196 | F9: =E9/D9 -> 1.06076 | G9: {=SUMPRODUCT(('RP - Unit Starts'!$C$2:$C$101=$C9)*('RP - Unit Starts'!$F$2:$F$101="Unit Starts")*'RP - Unit Starts'!$I$2:$L$101)/SUMIFS('RP - Unit Starts'!$L:$L,'RP - Unit Starts'!$C:$C,$C9,'RP - Unit Starts'!$F:$F,"Existing Units")} -> 0.018218772 | H9: =F9-1 -> 0.06076 | I9: =SUMIFS(Realpage!$I:$I,Realpage!$A:$A,$C9,Realpage!$F:$F,"Effective RPSF") -> 3.086 | J9: =I9/D9 -> 1.0242507 | K9: =J9-1 -> 0.024250738 | M9: =AVERAGEIF('Realpage - His. Rent Change'!$A$2:$A$577,'Q2 2026 Summary'!C13,'Realpage - His. Rent Change'!$I$2:$AV$577) -> 0.0663 | N9: =AVERAGE(L9:M9) -> 0.0663 | O9: =MAX(0,-(K9/M9)) -> 0 | P9: =($P$3*M9)+K9 -> 0.35575074 | Q9: =(1+P9)^(1/$P$3)-1 -> 0.062761884 | R9: =$R$3+P9 -> 0.40675074 | S9: =$S$3*$P$3 -> 0.125 | T9: =SUMIFS(Realpage!$I:$I,Realpage!$A:$A,$C9,Realpage!$F:$F,"NOI % of Revenue") -> 1.0744997 | U9: 1 | V9: =U9-T9 -> -0.074499718 | W9: =U9*(1+R9) -> 1.4067507 | X9: =V9*(1+S9) -> -0.083812183 | Y9: =W9-X9 -> 1.4905629 | Z9: =Y9/T9-1 -> 0.38721574 | AA9: =(Y9/T9)^(1/$P$3)-1 -> 0.067649747 | AB9: =$AB$3 -> 0.05 | AC9: =AB9/$AB$3 -> 1 | AD9: =AC9*(1+$AD$3) -> 1.08 | AE9: =AC9*AB9 -> 0.05 | AF9: =AE9*(1+Z9) -> 0.069360787 | AG9: =AF9/AD9 -> 0.064222951 | AH9: =AG9-AB9 -> 0.014222951 | AI9: =ROUND(AH9,4) -> 0.0142 | AJ9: {=INDEX('Cap Rate to IRR Map'!$F$3:$F$623,MATCH(ROUND(AI9,4),ROUND('Cap Rate to IRR Map'!$E$3:$E$623,4),0))} -> 0.125333 | AK9: =$AK$3 -> 0.05 | AL9: 0.105 | AN9: IF these markets have visibility to positive short term rent growth, and if longer term demand expectations are similar to previous 10 years
B10: =B9+1 -> 6 | C10: Miami-Miami Beach-Kendall, FL | D10: =SUMIFS(Realpage!$I:$I,Realpage!$A:$A,$C10,Realpage!$F:$F,"Rent Roll (Rev/OSF)") -> 5.6228267 | E10: =SUMIFS(Realpage!$I:$I,Realpage!$A:$A,$C10,Realpage!$F:$F,"Asking RPSF") -> 5.963 | F10: =E10/D10 -> 1.0604986 | G10: {=SUMPRODUCT(('RP - Unit Starts'!$C$2:$C$101=$C10)*('RP - Unit Starts'!$F$2:$F$101="Unit Starts")*'RP - Unit Starts'!$I$2:$L$101)/SUMIFS('RP - Unit Starts'!$L:$L,'RP - Unit Starts'!$C:$C,$C10,'RP - Unit Starts'!$F:$F,"Existing Units")} -> 0.024001428 | H10: =F10-1 -> 0.06049863 | I10: =SUMIFS(Realpage!$I:$I,Realpage!$A:$A,$C10,Realpage!$F:$F,"Effective RPSF") -> 5.857 | J10: =I10/D10 -> 1.0416469 | K10: =J10-1 -> 0.041646902 | M10: =AVERAGEIF('Realpage - His. Rent Change'!$A$2:$A$577,'Q2 2026 Summary'!C7,'Realpage - His. Rent Change'!$I$2:$AV$577) -> 0.1035 | N10: =AVERAGE(L10:M10) -> 0.1035 | O10: =MAX(0,-(K10/M10)) -> 0 | P10: =($P$3*M10)+K10 -> 0.5591469 | Q10: =(1+P10)^(1/$P$3)-1 -> 0.092892403 | R10: =$R$3+P10 -> 0.6101469 | S10: =$S$3*$P$3 -> 0.125 | T10: =SUMIFS(Realpage!$I:$I,Realpage!$A:$A,$C10,Realpage!$F:$F,"NOI % of Revenue") -> 1.1842603 | U10: 1 | V10: =U10-T10 -> -0.18426034 | W10: =U10*(1+R10) -> 1.6101469 | X10: =V10*(1+S10) -> -0.20729288 | Y10: =W10-X10 -> 1.8174398 | Z10: =Y10/T10-1 -> 0.53466238 | AA10: =(Y10/T10)^(1/$P$3)-1 -> 0.089438124 | AB10: =$AB$3 -> 0.05 | AC10: =AB10/$AB$3 -> 1 | AD10: =AC10*(1+$AD$3) -> 1.08 | AE10: =AC10*AB10 -> 0.05 | AF10: =AE10*(1+Z10) -> 0.076733119 | AG10: =AF10/AD10 -> 0.071049184 | AH10: =AG10-AB10 -> 0.021049184 | AI10: =ROUND(AH10,4) -> 0.021 | AJ10: {=INDEX('Cap Rate to IRR Map'!$F$3:$F$623,MATCH(ROUND(AI10,4),ROUND('Cap Rate to IRR Map'!$E$3:$E$623,4),0))} -> 0.173 | AK10: =$AK$3 -> 0.05 | AL10: 0.133667 | AO10: Dallas
B11: =B10+1 -> 7 | C11: Huntsville, AL | D11: =SUMIFS(Realpage!$I:$I,Realpage!$A:$A,$C11,Realpage!$F:$F,"Rent Roll (Rev/OSF)") -> 2.311599 | E11: =SUMIFS(Realpage!$I:$I,Realpage!$A:$A,$C11,Realpage!$F:$F,"Asking RPSF") -> 2.44 | F11: =E11/D11 -> 1.0555464 | G11: {=SUMPRODUCT(('RP - Unit Starts'!$C$2:$C$101=$C11)*('RP - Unit Starts'!$F$2:$F$101="Unit Starts")*'RP - Unit Starts'!$I$2:$L$101)/SUMIFS('RP - Unit Starts'!$L:$L,'RP - Unit Starts'!$C:$C,$C11,'RP - Unit Starts'!$F:$F,"Existing Units")} -> 0.028401115 | H11: =F11-1 -> 0.055546384 | I11: =SUMIFS(Realpage!$I:$I,Realpage!$A:$A,$C11,Realpage!$F:$F,"Effective RPSF") -> 2.336 | J11: =I11/D11 -> 1.0105559 | K11: =J11-1 -> 0.010555882 | M11: =AVERAGEIF('Realpage - His. Rent Change'!$A$2:$A$577,'Q2 2026 Summary'!C21,'Realpage - His. Rent Change'!$I$2:$AV$577) -> 0.0339 | N11: =AVERAGE(L11:M11) -> 0.0339 | O11: =MAX(0,-(K11/M11)) -> 0 | P11: =($P$3*M11)+K11 -> 0.18005588 | Q11: =(1+P11)^(1/$P$3)-1 -> 0.033666675 | R11: =$R$3+P11 -> 0.23105588 | S11: =$S$3*$P$3 -> 0.125 | T11: =SUMIFS(Realpage!$I:$I,Realpage!$A:$A,$C11,Realpage!$F:$F,"NOI % of Revenue") -> 1.062209 | U11: 1 | V11: =U11-T11 -> -0.062208979 | W11: =U11*(1+R11) -> 1.2310559 | X11: =V11*(1+S11) -> -0.069985102 | Y11: =W11-X11 -> 1.301041 | Z11: =Y11/T11-1 -> 0.22484465 | AA11: =(Y11/T11)^(1/$P$3)-1 -> 0.041396711 | AB11: =$AB$3 -> 0.05 | AC11: =AB11/$AB$3 -> 1 | AD11: =AC11*(1+$AD$3) -> 1.08 | AE11: =AC11*AB11 -> 0.05 | AF11: =AE11*(1+Z11) -> 0.061242232 | AG11: =AF11/AD11 -> 0.056705771 | AH11: =AG11-AB11 -> 0.0067057708 | AI11: =ROUND(AH11,4) -> 0.0067 | AJ11: {=INDEX('Cap Rate to IRR Map'!$F$3:$F$623,MATCH(ROUND(AI11,4),ROUND('Cap Rate to IRR Map'!$E$3:$E$623,4),0))} -> 0.063 | AK11: =$AK$3 -> 0.05 | AL11: 0.176 | AN11: No cap rate compression/expansion (5% going in and exit)
B12: =B11+1 -> 8 | C12: Richmond, VA | D12: =SUMIFS(Realpage!$I:$I,Realpage!$A:$A,$C12,Realpage!$F:$F,"Rent Roll (Rev/OSF)") -> 3.4093003 | E12: =SUMIFS(Realpage!$I:$I,Realpage!$A:$A,$C12,Realpage!$F:$F,"Asking RPSF") -> 3.589 | F12: =E12/D12 -> 1.0527087 | G12: {=SUMPRODUCT(('RP - Unit Starts'!$C$2:$C$101=$C12)*('RP - Unit Starts'!$F$2:$F$101="Unit Starts")*'RP - Unit Starts'!$I$2:$L$101)/SUMIFS('RP - Unit Starts'!$L:$L,'RP - Unit Starts'!$C:$C,$C12,'RP - Unit Starts'!$F:$F,"Existing Units")} -> 0.013758423 | H12: =F12-1 -> 0.052708661 | I12: =SUMIFS(Realpage!$I:$I,Realpage!$A:$A,$C12,Realpage!$F:$F,"Effective RPSF") -> 3.55 | J12: =I12/D12 -> 1.0412694 | K12: =J12-1 -> 0.041269364 | L12: 0.0451 | M12: =AVERAGEIF('Realpage - His. Rent Change'!$A$2:$A$577,'Q2 2026 Summary'!C10,'Realpage - His. Rent Change'!$I$2:$AV$577) -> 0.0591 | N12: =AVERAGE(L12:M12) -> 0.0521 | O12: =MAX(0,-(K12/M12)) -> 0 | P12: =($P$3*M12)+K12 -> 0.33676936 | Q12: =(1+P12)^(1/$P$3)-1 -> 0.059769208 | R12: =$R$3+P12 -> 0.38776936 | S12: =$S$3*$P$3 -> 0.125 | T12: =SUMIFS(Realpage!$I:$I,Realpage!$A:$A,$C12,Realpage!$F:$F,"NOI % of Revenue") -> 1.069903 | U12: 1 | V12: =U12-T12 -> -0.069903024 | W12: =U12*(1+R12) -> 1.3877694 | X12: =V12*(1+S12) -> -0.078640902 | Y12: =W12-X12 -> 1.4664103 | Z12: =Y12/T12-1 -> 0.3706011 | AA12: =(Y12/T12)^(1/$P$3)-1 -> 0.065079965 | AB12: =$AB$3 -> 0.05 | AC12: =AB12/$AB$3 -> 1 | AD12: =AC12*(1+$AD$3) -> 1.08 | AE12: =AC12*AB12 -> 0.05 | AF12: =AE12*(1+Z12) -> 0.068530055 | AG12: =AF12/AD12 -> 0.063453755 | AH12: =AG12-AB12 -> 0.013453755 | AI12: =ROUND(AH12,4) -> 0.0135 | AJ12: {=INDEX('Cap Rate to IRR Map'!$F$3:$F$623,MATCH(ROUND(AI12,4),ROUND('Cap Rate to IRR Map'!$E$3:$E$623,4),0))} -> 0.119667 | AK12: =$AK$3 -> 0.05 | AL12: 0.145 | AO12: WPB / Fort Lauderdale
B13: =B12+1 -> 9 | C13: Boise City, ID | D13: =SUMIFS(Realpage!$I:$I,Realpage!$A:$A,$C13,Realpage!$F:$F,"Rent Roll (Rev/OSF)") -> 1.7530692 | E13: =SUMIFS(Realpage!$I:$I,Realpage!$A:$A,$C13,Realpage!$F:$F,"Asking RPSF") -> 1.838 | F13: =E13/D13 -> 1.0484469 | G13: {=SUMPRODUCT(('RP - Unit Starts'!$C$2:$C$101=$C13)*('RP - Unit Starts'!$F$2:$F$101="Unit Starts")*'RP - Unit Starts'!$I$2:$L$101)/SUMIFS('RP - Unit Starts'!$L:$L,'RP - Unit Starts'!$C:$C,$C13,'RP - Unit Starts'!$F:$F,"Existing Units")} -> 0.011981268 | H13: =F13-1 -> 0.048446926 | I13: =SUMIFS(Realpage!$I:$I,Realpage!$A:$A,$C13,Realpage!$F:$F,"Effective RPSF") -> 1.824 | J13: =I13/D13 -> 1.0404609 | K13: =J13-1 -> 0.040460932 | M13: =AVERAGEIF('Realpage - His. Rent Change'!$A$2:$A$577,'Q2 2026 Summary'!C31,'Realpage - His. Rent Change'!$I$2:$AV$577) -> 0.0898 | N13: =AVERAGE(L13:M13) -> 0.0898 | O13: =MAX(0,-(K13/M13)) -> 0 | P13: =($P$3*M13)+K13 -> 0.48946093 | Q13: =(1+P13)^(1/$P$3)-1 -> 0.082943561 | R13: =$R$3+P13 -> 0.54046093 | S13: =$S$3*$P$3 -> 0.125 | T13: =SUMIFS(Realpage!$I:$I,Realpage!$A:$A,$C13,Realpage!$F:$F,"NOI % of Revenue") -> 0.66685537 | U13: 1 | V13: =U13-T13 -> 0.33314463 | W13: =U13*(1+R13) -> 1.5404609 | X13: =V13*(1+S13) -> 0.37478771 | Y13: =W13-X13 -> 1.1656732 | Z13: =Y13/T13-1 -> 0.74801505 | AA13: =(Y13/T13)^(1/$P$3)-1 -> 0.11817308 | AB13: =$AB$3 -> 0.05 | AC13: =AB13/$AB$3 -> 1 | AD13: =AC13*(1+$AD$3) -> 1.08 | AE13: =AC13*AB13 -> 0.05 | AF13: =AE13*(1+Z13) -> 0.087400752 | AG13: =AF13/AD13 -> 0.080926623 | AH13: =AG13-AB13 -> 0.030926623 | AI13: =ROUND(AH13,4) -> 0.0309 | AJ13: {=INDEX('Cap Rate to IRR Map'!$F$3:$F$623,MATCH(ROUND(AI13,4),ROUND('Cap Rate to IRR Map'!$E$3:$E$623,4),0))} -> 0.24000292 | AK13: =$AK$3 -> 0.05 | AL13: 0.169667 | AN13: THEN these markets should be actionable for us on a market pricing/market debt basis:
B14: =B13+1 -> 10 | C14: Wilmington, NC | D14: =SUMIFS(Realpage!$I:$I,Realpage!$A:$A,$C14,Realpage!$F:$F,"Rent Roll (Rev/OSF)") -> 3.01842 | E14: =SUMIFS(Realpage!$I:$I,Realpage!$A:$A,$C14,Realpage!$F:$F,"Asking RPSF") -> 3.154 | F14: =E14/D14 -> 1.0449175 | G14: {=SUMPRODUCT(('RP - Unit Starts'!$C$2:$C$101=$C14)*('RP - Unit Starts'!$F$2:$F$101="Unit Starts")*'RP - Unit Starts'!$I$2:$L$101)/SUMIFS('RP - Unit Starts'!$L:$L,'RP - Unit Starts'!$C:$C,$C14,'RP - Unit Starts'!$F:$F,"Existing Units")} -> 0.018594007 | H14: =F14-1 -> 0.044917537 | I14: =SUMIFS(Realpage!$I:$I,Realpage!$A:$A,$C14,Realpage!$F:$F,"Effective RPSF") -> 3.077 | J14: =I14/D14 -> 1.0194075 | K14: =J14-1 -> 0.019407502 | M14: =AVERAGEIF('Realpage - His. Rent Change'!$A$2:$A$577,'Q2 2026 Summary'!C18,'Realpage - His. Rent Change'!$I$2:$AV$577) -> 0.0396 | N14: =AVERAGE(L14:M14) -> 0.0396 | O14: =MAX(0,-(K14/M14)) -> 0 | P14: =($P$3*M14)+K14 -> 0.2174075 | Q14: =(1+P14)^(1/$P$3)-1 -> 0.040128975 | R14: =$R$3+P14 -> 0.2684075 | S14: =$S$3*$P$3 -> 0.125 | T14: =SUMIFS(Realpage!$I:$I,Realpage!$A:$A,$C14,Realpage!$F:$F,"NOI % of Revenue") -> 1.2239072 | U14: 1 | V14: =U14-T14 -> -0.22390722 | W14: =U14*(1+R14) -> 1.2684075 | X14: =V14*(1+S14) -> -0.25189563 | Y14: =W14-X14 -> 1.5203031 | Z14: =Y14/T14-1 -> 0.24217187 | AA14: =(Y14/T14)^(1/$P$3)-1 -> 0.044326596 | AB14: =$AB$3 -> 0.05 | AC14: =AB14/$AB$3 -> 1 | AD14: =AC14*(1+$AD$3) -> 1.08 | AE14: =AC14*AB14 -> 0.05 | AF14: =AE14*(1+Z14) -> 0.062108594 | AG14: =AF14/AD14 -> 0.057507957 | AH14: =AG14-AB14 -> 0.0075079571 | AI14: =ROUND(AH14,4) -> 0.0075 | AJ14: {=INDEX('Cap Rate to IRR Map'!$F$3:$F$623,MATCH(ROUND(AI14,4),ROUND('Cap Rate to IRR Map'!$E$3:$E$623,4),0))} -> 0.07 | AK14: =$AK$3 -> 0.05 | AL14: 0.174
B15: =B14+1 -> 11 | C15: Omaha, NE-IA | D15: =SUMIFS(Realpage!$I:$I,Realpage!$A:$A,$C15,Realpage!$F:$F,"Rent Roll (Rev/OSF)") -> 2.7537036 | E15: =SUMIFS(Realpage!$I:$I,Realpage!$A:$A,$C15,Realpage!$F:$F,"Asking RPSF") -> 2.877 | F15: =E15/D15 -> 1.0447748 | G15: {=SUMPRODUCT(('RP - Unit Starts'!$C$2:$C$101=$C15)*('RP - Unit Starts'!$F$2:$F$101="Unit Starts")*'RP - Unit Starts'!$I$2:$L$101)/SUMIFS('RP - Unit Starts'!$L:$L,'RP - Unit Starts'!$C:$C,$C15,'RP - Unit Starts'!$F:$F,"Existing Units")} -> 0.03111465 | H15: =F15-1 -> 0.044774754 | I15: =SUMIFS(Realpage!$I:$I,Realpage!$A:$A,$C15,Realpage!$F:$F,"Effective RPSF") -> 2.847 | J15: =I15/D15 -> 1.0338803 | K15: =J15-1 -> 0.033880335 | M15: =AVERAGEIF('Realpage - His. Rent Change'!$A$2:$A$577,'Q2 2026 Summary'!C11,'Realpage - His. Rent Change'!$I$2:$AV$577) -> 0.0346 | N15: =AVERAGE(L15:M15) -> 0.0346 | O15: =MAX(0,-(K15/M15)) -> 0 | P15: =($P$3*M15)+K15 -> 0.20688034 | Q15: =(1+P15)^(1/$P$3)-1 -> 0.03832388 | R15: =$R$3+P15 -> 0.25788034 | S15: =$S$3*$P$3 -> 0.125 | T15: =SUMIFS(Realpage!$I:$I,Realpage!$A:$A,$C15,Realpage!$F:$F,"NOI % of Revenue") -> 1.166822 | U15: 1 | V15: =U15-T15 -> -0.166822 | W15: =U15*(1+R15) -> 1.2578803 | X15: =V15*(1+S15) -> -0.18767475 | Y15: =W15-X15 -> 1.4455551 | Z15: =Y15/T15-1 -> 0.23888227 | AA15: =(Y15/T15)^(1/$P$3)-1 -> 0.043772877 | AB15: =$AB$3 -> 0.05 | AC15: =AB15/$AB$3 -> 1 | AD15: =AC15*(1+$AD$3) -> 1.08 | AE15: =AC15*AB15 -> 0.05 | AF15: =AE15*(1+Z15) -> 0.061944113 | AG15: =AF15/AD15 -> 0.057355661 | AH15: =AG15-AB15 -> 0.0073556605 | AI15: =ROUND(AH15,4) -> 0.0074 | AJ15: {=INDEX('Cap Rate to IRR Map'!$F$3:$F$623,MATCH(ROUND(AI15,4),ROUND('Cap Rate to IRR Map'!$E$3:$E$623,4),0))} -> 0.069 | AK15: =$AK$3 -> 0.05 | AL15: 0.187 | AO15: Nashville
B16: =B15+1 -> 12 | C16: Virginia Beach-Chesapeake-Norfolk, VA-NC | D16: =SUMIFS(Realpage!$I:$I,Realpage!$A:$A,$C16,Realpage!$F:$F,"Rent Roll (Rev/OSF)") -> 3.320201 | E16: =SUMIFS(Realpage!$I:$I,Realpage!$A:$A,$C16,Realpage!$F:$F,"Asking RPSF") -> 3.468 | F16: =E16/D16 -> 1.0445151 | G16: {=SUMPRODUCT(('RP - Unit Starts'!$C$2:$C$101=$C16)*('RP - Unit Starts'!$F$2:$F$101="Unit Starts")*'RP - Unit Starts'!$I$2:$L$101)/SUMIFS('RP - Unit Starts'!$L:$L,'RP - Unit Starts'!$C:$C,$C16,'RP - Unit Starts'!$F:$F,"Existing Units")} -> 0.0039863635 | H16: =F16-1 -> 0.044515078 | I16: =SUMIFS(Realpage!$I:$I,Realpage!$A:$A,$C16,Realpage!$F:$F,"Effective RPSF") -> 3.456 | J16: =I16/D16 -> 1.0409008 | K16: =J16-1 -> 0.040900838 | M16: =AVERAGEIF('Realpage - His. Rent Change'!$A$2:$A$577,'Q2 2026 Summary'!C8,'Realpage - His. Rent Change'!$I$2:$AV$577) -> 0.0513 | N16: =AVERAGE(L16:M16) -> 0.0513 | O16: =MAX(0,-(K16/M16)) -> 0 | P16: =($P$3*M16)+K16 -> 0.29740084 | Q16: =(1+P16)^(1/$P$3)-1 -> 0.053452201 | R16: =$R$3+P16 -> 0.34840084 | S16: =$S$3*$P$3 -> 0.125 | T16: =SUMIFS(Realpage!$I:$I,Realpage!$A:$A,$C16,Realpage!$F:$F,"NOI % of Revenue") -> 1.184724 | U16: 1 | V16: =U16-T16 -> -0.18472398 | W16: =U16*(1+R16) -> 1.3484008 | X16: =V16*(1+S16) -> -0.20781448 | Y16: =W16-X16 -> 1.5562153 | Z16: =Y16/T16-1 -> 0.31356784 | AA16: =(Y16/T16)^(1/$P$3)-1 -> 0.056064639 | AB16: =$AB$3 -> 0.05 | AC16: =AB16/$AB$3 -> 1 | AD16: =AC16*(1+$AD$3) -> 1.08 | AE16: =AC16*AB16 -> 0.05 | AF16: =AE16*(1+Z16) -> 0.065678392 | AG16: =AF16/AD16 -> 0.060813326 | AH16: =AG16-AB16 -> 0.010813326 | AI16: =ROUND(AH16,4) -> 0.0108 | AJ16: {=INDEX('Cap Rate to IRR Map'!$F$3:$F$623,MATCH(ROUND(AI16,4),ROUND('Cap Rate to IRR Map'!$E$3:$E$623,4),0))} -> 0.098 | AK16: =$AK$3 -> 0.05 | AL16: 0.123
B17: =B16+1 -> 13 | C17: Nashville-Davidson--Murfreesboro--Franklin, TN | D17: =SUMIFS(Realpage!$I:$I,Realpage!$A:$A,$C17,Realpage!$F:$F,"Rent Roll (Rev/OSF)") -> 3.3563372 | E17: =SUMIFS(Realpage!$I:$I,Realpage!$A:$A,$C17,Realpage!$F:$F,"Asking RPSF") -> 3.501 | F17: =E17/D17 -> 1.0431014 | G17: {=SUMPRODUCT(('RP - Unit Starts'!$C$2:$C$101=$C17)*('RP - Unit Starts'!$F$2:$F$101="Unit Starts")*'RP - Unit Starts'!$I$2:$L$101)/SUMIFS('RP - Unit Starts'!$L:$L,'RP - Unit Starts'!$C:$C,$C17,'RP - Unit Starts'!$F:$F,"Existing Units")} -> 0.028013395 | H17: =F17-1 -> 0.043101392 | I17: =SUMIFS(Realpage!$I:$I,Realpage!$A:$A,$C17,Realpage!$F:$F,"Effective RPSF") -> 3.368 | J17: =I17/D17 -> 1.0034749 | K17: =J17-1 -> 0.0034748612 | L17: 0.0365 | M17: =AVERAGEIF('Realpage - His. Rent Change'!$A$2:$A$577,'Q2 2026 Summary'!C19,'Realpage - His. Rent Change'!$I$2:$AV$577) -> 0.0535 | N17: =AVERAGE(L17:M17) -> 0.045 | O17: =MAX(0,-(K17/M17)) -> 0 | P17: =($P$3*M17)+K17 -> 0.27097486 | Q17: =(1+P17)^(1/$P$3)-1 -> 0.049125377 | R17: =$R$3+P17 -> 0.32197486 | S17: =$S$3*$P$3 -> 0.125 | T17: =SUMIFS(Realpage!$I:$I,Realpage!$A:$A,$C17,Realpage!$F:$F,"NOI % of Revenue") -> 1.1659141 | U17: 1 | V17: =U17-T17 -> -0.16591406 | W17: =U17*(1+R17) -> 1.3219749 | X17: =V17*(1+S17) -> -0.18665332 | Y17: =W17-X17 -> 1.5086282 | Z17: =Y17/T17-1 -> 0.29394458 | AA17: =(Y17/T17)^(1/$P$3)-1 -> 0.052890325 | AB17: =$AB$3 -> 0.05 | AC17: =AB17/$AB$3 -> 1 | AD17: =AC17*(1+$AD$3) -> 1.08 | AE17: =AC17*AB17 -> 0.05 | AF17: =AE17*(1+Z17) -> 0.064697229 | AG17: =AF17/AD17 -> 0.059904842 | AH17: =AG17-AB17 -> 0.0099048416 | AI17: =ROUND(AH17,4) -> 0.0099 | AJ17: {=INDEX('Cap Rate to IRR Map'!$F$3:$F$623,MATCH(ROUND(AI17,4),ROUND('Cap Rate to IRR Map'!$E$3:$E$623,4),0))} -> 0.09075 | AK17: =$AK$3 -> 0.05 | AL17: 0.086
B18: =B17+1 -> 14 | C18: Minneapolis-St. Paul-Bloomington, MN-WI | D18: =SUMIFS(Realpage!$I:$I,Realpage!$A:$A,$C18,Realpage!$F:$F,"Rent Roll (Rev/OSF)") -> 3.6840669 | E18: =SUMIFS(Realpage!$I:$I,Realpage!$A:$A,$C18,Realpage!$F:$F,"Asking RPSF") -> 3.794 | F18: =E18/D18 -> 1.0298401 | G18: {=SUMPRODUCT(('RP - Unit Starts'!$C$2:$C$101=$C18)*('RP - Unit Starts'!$F$2:$F$101="Unit Starts")*'RP - Unit Starts'!$I$2:$L$101)/SUMIFS('RP - Unit Starts'!$L:$L,'RP - Unit Starts'!$C:$C,$C18,'RP - Unit Starts'!$F:$F,"Existing Units")} -> 0.0093966239 | H18: =F18-1 -> 0.029840137 | I18: =SUMIFS(Realpage!$I:$I,Realpage!$A:$A,$C18,Realpage!$F:$F,"Effective RPSF") -> 3.736 | J18: =I18/D18 -> 1.0140967 | K18: =J18-1 -> 0.014096666 | L18: 0.0264 | M18: =AVERAGEIF('Realpage - His. Rent Change'!$A$2:$A$577,'Q2 2026 Summary'!C14,'Realpage - His. Rent Change'!$I$2:$AV$577) -> 0.0714 | N18: =AVERAGE(L18:M18) -> 0.0489 | O18: =MAX(0,-(K18/M18)) -> 0 | P18: =($P$3*M18)+K18 -> 0.37109667 | Q18: =(1+P18)^(1/$P$3)-1 -> 0.065156973 | R18: =$R$3+P18 -> 0.42209667 | S18: =$S$3*$P$3 -> 0.125 | T18: =SUMIFS(Realpage!$I:$I,Realpage!$A:$A,$C18,Realpage!$F:$F,"NOI % of Revenue") -> 1.0798477 | U18: 1 | V18: =U18-T18 -> -0.079847711 | W18: =U18*(1+R18) -> 1.4220967 | X18: =V18*(1+S18) -> -0.089828674 | Y18: =W18-X18 -> 1.5119253 | Z18: =Y18/T18-1 -> 0.4001283 | AA18: =(Y18/T18)^(1/$P$3)-1 -> 0.06962998 | AB18: =$AB$3 -> 0.05 | AC18: =AB18/$AB$3 -> 1 | AD18: =AC18*(1+$AD$3) -> 1.08 | AE18: =AC18*AB18 -> 0.05 | AF18: =AE18*(1+Z18) -> 0.070006415 | AG18: =AF18/AD18 -> 0.064820755 | AH18: =AG18-AB18 -> 0.014820755 | AI18: =ROUND(AH18,4) -> 0.0148 | AJ18: {=INDEX('Cap Rate to IRR Map'!$F$3:$F$623,MATCH(ROUND(AI18,4),ROUND('Cap Rate to IRR Map'!$E$3:$E$623,4),0))} -> 0.129667 | AK18: =$AK$3 -> 0.05 | AL18: 0.164667
B19: =B18+1 -> 15 | C19: Kansas City, MO-KS | D19: =SUMIFS(Realpage!$I:$I,Realpage!$A:$A,$C19,Realpage!$F:$F,"Rent Roll (Rev/OSF)") -> 2.9700488 | E19: =SUMIFS(Realpage!$I:$I,Realpage!$A:$A,$C19,Realpage!$F:$F,"Asking RPSF") -> 3.042 | F19: =E19/D19 -> 1.0242256 | G19: {=SUMPRODUCT(('RP - Unit Starts'!$C$2:$C$101=$C19)*('RP - Unit Starts'!$F$2:$F$101="Unit Starts")*'RP - Unit Starts'!$I$2:$L$101)/SUMIFS('RP - Unit Starts'!$L:$L,'RP - Unit Starts'!$C:$C,$C19,'RP - Unit Starts'!$F:$F,"Existing Units")} -> 0.025479466 | H19: =F19-1 -> 0.02422561 | I19: =SUMIFS(Realpage!$I:$I,Realpage!$A:$A,$C19,Realpage!$F:$F,"Effective RPSF") -> 3.017 | J19: =I19/D19 -> 1.0158082 | K19: =J19-1 -> 0.01580824 | L19: 0.0367 | M19: =AVERAGEIF('Realpage - His. Rent Change'!$A$2:$A$577,'Q2 2026 Summary'!C16,'Realpage - His. Rent Change'!$I$2:$AV$577) -> 0.0275 | N19: =AVERAGE(L19:M19) -> 0.0321 | O19: =MAX(0,-(K19/M19)) -> 0 | P19: =($P$3*M19)+K19 -> 0.15330824 | Q19: =(1+P19)^(1/$P$3)-1 -> 0.028937698 | R19: =$R$3+P19 -> 0.20430824 | S19: =$S$3*$P$3 -> 0.125 | T19: =SUMIFS(Realpage!$I:$I,Realpage!$A:$A,$C19,Realpage!$F:$F,"NOI % of Revenue") -> 1.104193 | U19: 1 | V19: =U19-T19 -> -0.104193 | W19: =U19*(1+R19) -> 1.2043082 | X19: =V19*(1+S19) -> -0.11721712 | Y19: =W19-X19 -> 1.3215254 | Z19: =Y19/T19-1 -> 0.19682462 | AA19: =(Y19/T19)^(1/$P$3)-1 -> 0.036587823 | AB19: =$AB$3 -> 0.05 | AC19: =AB19/$AB$3 -> 1 | AD19: =AC19*(1+$AD$3) -> 1.08 | AE19: =AC19*AB19 -> 0.05 | AF19: =AE19*(1+Z19) -> 0.059841231 | AG19: =AF19/AD19 -> 0.055408547 | AH19: =AG19-AB19 -> 0.0054085471 | AI19: =ROUND(AH19,4) -> 0.0054 | AJ19: {=INDEX('Cap Rate to IRR Map'!$F$3:$F$623,MATCH(ROUND(AI19,4),ROUND('Cap Rate to IRR Map'!$E$3:$E$623,4),0))} -> 0.051 | AK19: =$AK$3 -> 0.05 | AL19: 0.181
B20: =B19+1 -> 16 | C20: Birmingham, AL | D20: =SUMIFS(Realpage!$I:$I,Realpage!$A:$A,$C20,Realpage!$F:$F,"Rent Roll (Rev/OSF)") -> 1.272755 | E20: =SUMIFS(Realpage!$I:$I,Realpage!$A:$A,$C20,Realpage!$F:$F,"Asking RPSF") -> 1.303 | F20: =E20/D20 -> 1.0237634 | G20: {=SUMPRODUCT(('RP - Unit Starts'!$C$2:$C$101=$C20)*('RP - Unit Starts'!$F$2:$F$101="Unit Starts")*'RP - Unit Starts'!$I$2:$L$101)/SUMIFS('RP - Unit Starts'!$L:$L,'RP - Unit Starts'!$C:$C,$C20,'RP - Unit Starts'!$F:$F,"Existing Units")} -> 0.001636324 | H20: =F20-1 -> 0.023763405 | I20: =SUMIFS(Realpage!$I:$I,Realpage!$A:$A,$C20,Realpage!$F:$F,"Effective RPSF") -> 1.273 | J20: =I20/D20 -> 1.0001925 | K20: =J20-1 -> 0.00019248987 | M20: =AVERAGEIF('Realpage - His. Rent Change'!$A$2:$A$577,'Q2 2026 Summary'!C23,'Realpage - His. Rent Change'!$I$2:$AV$577) -> 0.0693 | N20: =AVERAGE(L20:M20) -> 0.0693 | O20: =MAX(0,-(K20/M20)) -> 0 | P20: =($P$3*M20)+K20 -> 0.34669249 | Q20: =(1+P20)^(1/$P$3)-1 -> 0.061337936 | R20: =$R$3+P20 -> 0.39769249 | S20: =$S$3*$P$3 -> 0.125 | T20: =SUMIFS(Realpage!$I:$I,Realpage!$A:$A,$C20,Realpage!$F:$F,"NOI % of Revenue") -> 0.51096299 | U20: 1 | V20: =U20-T20 -> 0.48903701 | W20: =U20*(1+R20) -> 1.3976925 | X20: =V20*(1+S20) -> 0.55016664 | Y20: =W20-X20 -> 0.84752585 | Z20: =Y20/T20-1 -> 0.65868345 | AA20: =(Y20/T20)^(1/$P$3)-1 -> 0.10650327 | AB20: =$AB$3 -> 0.05 | AC20: =AB20/$AB$3 -> 1 | AD20: =AC20*(1+$AD$3) -> 1.08 | AE20: =AC20*AB20 -> 0.05 | AF20: =AE20*(1+Z20) -> 0.082934172 | AG20: =AF20/AD20 -> 0.0767909 | AH20: =AG20-AB20 -> 0.0267909 | AI20: =ROUND(AH20,4) -> 0.0268 | AJ20: {=INDEX('Cap Rate to IRR Map'!$F$3:$F$623,MATCH(ROUND(AI20,4),ROUND('Cap Rate to IRR Map'!$E$3:$E$623,4),0))} -> 0.209 | AK20: =$AK$3 -> 0.05 | AL20: 0.187 | AO20: Raleigh
B21: =B20+1 -> 17 | C21: Louisville/Jefferson County, KY-IN | D21: =SUMIFS(Realpage!$I:$I,Realpage!$A:$A,$C21,Realpage!$F:$F,"Rent Roll (Rev/OSF)") -> 2.639315 | E21: =SUMIFS(Realpage!$I:$I,Realpage!$A:$A,$C21,Realpage!$F:$F,"Asking RPSF") -> 2.7 | F21: =E21/D21 -> 1.0229927 | G21: {=SUMPRODUCT(('RP - Unit Starts'!$C$2:$C$101=$C21)*('RP - Unit Starts'!$F$2:$F$101="Unit Starts")*'RP - Unit Starts'!$I$2:$L$101)/SUMIFS('RP - Unit Starts'!$L:$L,'RP - Unit Starts'!$C:$C,$C21,'RP - Unit Starts'!$F:$F,"Existing Units")} -> 0.021078337 | H21: =F21-1 -> 0.022992725 | I21: =SUMIFS(Realpage!$I:$I,Realpage!$A:$A,$C21,Realpage!$F:$F,"Effective RPSF") -> 2.655 | J21: =I21/D21 -> 1.0059428 | K21: =J21-1 -> 0.0059428458 | M21: =AVERAGEIF('Realpage - His. Rent Change'!$A$2:$A$577,'Q2 2026 Summary'!C20,'Realpage - His. Rent Change'!$I$2:$AV$577) -> 0.0419 | N21: =AVERAGE(L21:M21) -> 0.0419 | O21: =MAX(0,-(K21/M21)) -> 0 | P21: =($P$3*M21)+K21 -> 0.21544285 | Q21: =(1+P21)^(1/$P$3)-1 -> 0.039793045 | R21: =$R$3+P21 -> 0.26644285 | S21: =$S$3*$P$3 -> 0.125 | T21: =SUMIFS(Realpage!$I:$I,Realpage!$A:$A,$C21,Realpage!$F:$F,"NOI % of Revenue") -> 1.0370489 | U21: 1 | V21: =U21-T21 -> -0.037048852 | W21: =U21*(1+R21) -> 1.2664428 | X21: =V21*(1+S21) -> -0.041679958 | Y21: =W21-X21 -> 1.3081228 | Z21: =Y21/T21-1 -> 0.26138976 | AA21: =(Y21/T21)^(1/$P$3)-1 -> 0.047538179 | AB21: =$AB$3 -> 0.05 | AC21: =AB21/$AB$3 -> 1 | AD21: =AC21*(1+$AD$3) -> 1.08 | AE21: =AC21*AB21 -> 0.05 | AF21: =AE21*(1+Z21) -> 0.063069488 | AG21: =AF21/AD21 -> 0.058397674 | AH21: =AG21-AB21 -> 0.0083976742 | AI21: =ROUND(AH21,4) -> 0.0084 | AJ21: {=INDEX('Cap Rate to IRR Map'!$F$3:$F$623,MATCH(ROUND(AI21,4),ROUND('Cap Rate to IRR Map'!$E$3:$E$623,4),0))} -> 0.078 | AK21: =$AK$3 -> 0.05 | AL21: 0.171 | AN21: These other markets are fringe returns from a market pricing/debt, perspective
B22: =B21+1 -> 18 | C22: Cincinnati, OH-KY-IN | D22: =SUMIFS(Realpage!$I:$I,Realpage!$A:$A,$C22,Realpage!$F:$F,"Rent Roll (Rev/OSF)") -> 3.1663271 | E22: =SUMIFS(Realpage!$I:$I,Realpage!$A:$A,$C22,Realpage!$F:$F,"Asking RPSF") -> 3.238 | F22: =E22/D22 -> 1.022636 | G22: {=SUMPRODUCT(('RP - Unit Starts'!$C$2:$C$101=$C22)*('RP - Unit Starts'!$F$2:$F$101="Unit Starts")*'RP - Unit Starts'!$I$2:$L$101)/SUMIFS('RP - Unit Starts'!$L:$L,'RP - Unit Starts'!$C:$C,$C22,'RP - Unit Starts'!$F:$F,"Existing Units")} -> 0.014331659 | H22: =F22-1 -> 0.02263597 | I22: =SUMIFS(Realpage!$I:$I,Realpage!$A:$A,$C22,Realpage!$F:$F,"Effective RPSF") -> 3.218 | J22: =I22/D22 -> 1.0163195 | K22: =J22-1 -> 0.016319504 | M22: =AVERAGEIF('Realpage - His. Rent Change'!$A$2:$A$577,'Q2 2026 Summary'!C17,'Realpage - His. Rent Change'!$I$2:$AV$577) -> 0.0893 | N22: =AVERAGE(L22:M22) -> 0.0893 | O22: =MAX(0,-(K22/M22)) -> 0 | P22: =($P$3*M22)+K22 -> 0.4628195 | Q22: =(1+P22)^(1/$P$3)-1 -> 0.079041501 | R22: =$R$3+P22 -> 0.5138195 | S22: =$S$3*$P$3 -> 0.125 | T22: =SUMIFS(Realpage!$I:$I,Realpage!$A:$A,$C22,Realpage!$F:$F,"NOI % of Revenue") -> 1.013682 | U22: 1 | V22: =U22-T22 -> -0.013682018 | W22: =U22*(1+R22) -> 1.5138195 | X22: =V22*(1+S22) -> -0.01539227 | Y22: =W22-X22 -> 1.5292118 | Z22: =Y22/T22-1 -> 0.50857147 | AA22: =(Y22/T22)^(1/$P$3)-1 -> 0.08570835 | AB22: =$AB$3 -> 0.05 | AC22: =AB22/$AB$3 -> 1 | AD22: =AC22*(1+$AD$3) -> 1.08 | AE22: =AC22*AB22 -> 0.05 | AF22: =AE22*(1+Z22) -> 0.075428574 | AG22: =AF22/AD22 -> 0.069841272 | AH22: =AG22-AB22 -> 0.019841272 | AI22: =ROUND(AH22,4) -> 0.0198 | AJ22: {=INDEX('Cap Rate to IRR Map'!$F$3:$F$623,MATCH(ROUND(AI22,4),ROUND('Cap Rate to IRR Map'!$E$3:$E$623,4),0))} -> 0.165 | AK22: =$AK$3 -> 0.05 | AL22: 0.14225 | AO22: SLC
B23: =B22+1 -> 19 | C23: West Palm Beach-Boca Raton-Delray Beach, FL | D23: =SUMIFS(Realpage!$I:$I,Realpage!$A:$A,$C23,Realpage!$F:$F,"Rent Roll (Rev/OSF)") -> 4.8360194 | E23: =SUMIFS(Realpage!$I:$I,Realpage!$A:$A,$C23,Realpage!$F:$F,"Asking RPSF") -> 4.912 | F23: =E23/D23 -> 1.0157114 | G23: {=SUMPRODUCT(('RP - Unit Starts'!$C$2:$C$101=$C23)*('RP - Unit Starts'!$F$2:$F$101="Unit Starts")*'RP - Unit Starts'!$I$2:$L$101)/SUMIFS('RP - Unit Starts'!$L:$L,'RP - Unit Starts'!$C:$C,$C23,'RP - Unit Starts'!$F:$F,"Existing Units")} -> 0.022218027 | H23: =F23-1 -> 0.015711401 | I23: =SUMIFS(Realpage!$I:$I,Realpage!$A:$A,$C23,Realpage!$F:$F,"Effective RPSF") -> 4.884 | J23: =I23/D23 -> 1.0099215 | K23: =J23-1 -> 0.0099215155 | L23: 0.0503 | M23: =AVERAGEIF('Realpage - His. Rent Change'!$A$2:$A$577,'Q2 2026 Summary'!C15,'Realpage - His. Rent Change'!$I$2:$AV$577) -> 0.0329 | N23: =AVERAGE(L23:M23) -> 0.0416 | O23: =MAX(0,-(K23/M23)) -> 0 | P23: =($P$3*M23)+K23 -> 0.17442152 | Q23: =(1+P23)^(1/$P$3)-1 -> 0.032677702 | R23: =$R$3+P23 -> 0.22542152 | S23: =$S$3*$P$3 -> 0.125 | T23: =SUMIFS(Realpage!$I:$I,Realpage!$A:$A,$C23,Realpage!$F:$F,"NOI % of Revenue") -> 1.1956526 | U23: 1 | V23: =U23-T23 -> -0.1956526 | W23: =U23*(1+R23) -> 1.2254215 | X23: =V23*(1+S23) -> -0.22010918 | Y23: =W23-X23 -> 1.4455307 | Z23: =Y23/T23-1 -> 0.20898887 | AA23: =(Y23/T23)^(1/$P$3)-1 -> 0.038686437 | AB23: =$AB$3 -> 0.05 | AC23: =AB23/$AB$3 -> 1 | AD23: =AC23*(1+$AD$3) -> 1.08 | AE23: =AC23*AB23 -> 0.05 | AF23: =AE23*(1+Z23) -> 0.060449444 | AG23: =AF23/AD23 -> 0.055971707 | AH23: =AG23-AB23 -> 0.0059717071 | AI23: =ROUND(AH23,4) -> 0.006 | AJ23: {=INDEX('Cap Rate to IRR Map'!$F$3:$F$623,MATCH(ROUND(AI23,4),ROUND('Cap Rate to IRR Map'!$E$3:$E$623,4),0))} -> 0.056 | AK23: =$AK$3 -> 0.05 | AL23: 0.15 | AN23: Therefore they need incremental return support, pursue the following:
B24: =B23+1 -> 20 | C24: Charleston-North Charleston, SC | D24: =SUMIFS(Realpage!$I:$I,Realpage!$A:$A,$C24,Realpage!$F:$F,"Rent Roll (Rev/OSF)") -> 3.6438246 | E24: =SUMIFS(Realpage!$I:$I,Realpage!$A:$A,$C24,Realpage!$F:$F,"Asking RPSF") -> 3.692 | F24: =E24/D24 -> 1.0132211 | G24: {=SUMPRODUCT(('RP - Unit Starts'!$C$2:$C$101=$C24)*('RP - Unit Starts'!$F$2:$F$101="Unit Starts")*'RP - Unit Starts'!$I$2:$L$101)/SUMIFS('RP - Unit Starts'!$L:$L,'RP - Unit Starts'!$C:$C,$C24,'RP - Unit Starts'!$F:$F,"Existing Units")} -> 0.029310723 | H24: =F24-1 -> 0.013221118 | I24: =SUMIFS(Realpage!$I:$I,Realpage!$A:$A,$C24,Realpage!$F:$F,"Effective RPSF") -> 3.624 | J24: =I24/D24 -> 0.99455941 | K24: =J24-1 -> -0.0054405928 | M24: =AVERAGEIF('Realpage - His. Rent Change'!$A$2:$A$577,'Q2 2026 Summary'!C28,'Realpage - His. Rent Change'!$I$2:$AV$577) -> 0.0468 | N24: =AVERAGE(L24:M24) -> 0.0468 | O24: =MAX(0,-(K24/M24)) -> 0.11625198 | P24: =($P$3*M24)+K24 -> 0.22855941 | Q24: =(1+P24)^(1/$P$3)-1 -> 0.042027624 | R24: =$R$3+P24 -> 0.27955941 | S24: =$S$3*$P$3 -> 0.125 | T24: =SUMIFS(Realpage!$I:$I,Realpage!$A:$A,$C24,Realpage!$F:$F,"NOI % of Revenue") -> 1.0900598 | U24: 1 | V24: =U24-T24 -> -0.090059789 | W24: =U24*(1+R24) -> 1.2795594 | X24: =V24*(1+S24) -> -0.10131726 | Y24: =W24-X24 -> 1.3808767 | Z24: =Y24/T24-1 -> 0.26678984 | AA24: =(Y24/T24)^(1/$P$3)-1 -> 0.048433561 | AB24: =$AB$3 -> 0.05 | AC24: =AB24/$AB$3 -> 1 | AD24: =AC24*(1+$AD$3) -> 1.08 | AE24: =AC24*AB24 -> 0.05 | AF24: =AE24*(1+Z24) -> 0.063339492 | AG24: =AF24/AD24 -> 0.058647678 | AH24: =AG24-AB24 -> 0.008647678 | AI24: =ROUND(AH24,4) -> 0.0086 | AJ24: {=INDEX('Cap Rate to IRR Map'!$F$3:$F$623,MATCH(ROUND(AI24,4),ROUND('Cap Rate to IRR Map'!$E$3:$E$623,4),0))} -> 0.08 | AK24: =$AK$3 -> 0.05 | AL24: 0.103667
B25: =B24+1 -> 21 | C25: Columbia, SC | D25: =SUMIFS(Realpage!$I:$I,Realpage!$A:$A,$C25,Realpage!$F:$F,"Rent Roll (Rev/OSF)") -> 2.6995689 | E25: =SUMIFS(Realpage!$I:$I,Realpage!$A:$A,$C25,Realpage!$F:$F,"Asking RPSF") -> 2.734 | F25: =E25/D25 -> 1.0127543 | G25: {=SUMPRODUCT(('RP - Unit Starts'!$C$2:$C$101=$C25)*('RP - Unit Starts'!$F$2:$F$101="Unit Starts")*'RP - Unit Starts'!$I$2:$L$101)/SUMIFS('RP - Unit Starts'!$L:$L,'RP - Unit Starts'!$C:$C,$C25,'RP - Unit Starts'!$F:$F,"Existing Units")} -> 0.016225482 | H25: =F25-1 -> 0.012754304 | I25: =SUMIFS(Realpage!$I:$I,Realpage!$A:$A,$C25,Realpage!$F:$F,"Effective RPSF") -> 2.708 | J25: =I25/D25 -> 1.0031231 | K25: =J25-1 -> 0.0031231367 | M25: =AVERAGEIF('Realpage - His. Rent Change'!$A$2:$A$577,'Q2 2026 Summary'!C22,'Realpage - His. Rent Change'!$I$2:$AV$577) -> 0.0357 | N25: =AVERAGE(L25:M25) -> 0.0357 | O25: =MAX(0,-(K25/M25)) -> 0 | P25: =($P$3*M25)+K25 -> 0.18162314 | Q25: =(1+P25)^(1/$P$3)-1 -> 0.033941095 | R25: =$R$3+P25 -> 0.23262314 | S25: =$S$3*$P$3 -> 0.125 | T25: =SUMIFS(Realpage!$I:$I,Realpage!$A:$A,$C25,Realpage!$F:$F,"NOI % of Revenue") -> 1.1093339 | U25: 1 | V25: =U25-T25 -> -0.10933389 | W25: =U25*(1+R25) -> 1.2326231 | X25: =V25*(1+S25) -> -0.12300062 | Y25: =W25-X25 -> 1.3556238 | Z25: =Y25/T25-1 -> 0.222016 | AA25: =(Y25/T25)^(1/$P$3)-1 -> 0.040915267 | AB25: =$AB$3 -> 0.05 | AC25: =AB25/$AB$3 -> 1 | AD25: =AC25*(1+$AD$3) -> 1.08 | AE25: =AC25*AB25 -> 0.05 | AF25: =AE25*(1+Z25) -> 0.0611008 | AG25: =AF25/AD25 -> 0.056574815 | AH25: =AG25-AB25 -> 0.0065748148 | AI25: =ROUND(AH25,4) -> 0.0066 | AJ25: {=INDEX('Cap Rate to IRR Map'!$F$3:$F$623,MATCH(ROUND(AI25,4),ROUND('Cap Rate to IRR Map'!$E$3:$E$623,4),0))} -> 0.062 | AK25: =$AK$3 -> 0.05 | AL25: 0.2015 | AO25: Submarkets with outsized growth above mkt avg
B26: =B25+1 -> 22 | C26: Tucson, AZ | D26: =SUMIFS(Realpage!$I:$I,Realpage!$A:$A,$C26,Realpage!$F:$F,"Rent Roll (Rev/OSF)") -> 2.9490836 | E26: =SUMIFS(Realpage!$I:$I,Realpage!$A:$A,$C26,Realpage!$F:$F,"Asking RPSF") -> 2.986 | F26: =E26/D26 -> 1.0125179 | G26: {=SUMPRODUCT(('RP - Unit Starts'!$C$2:$C$101=$C26)*('RP - Unit Starts'!$F$2:$F$101="Unit Starts")*'RP - Unit Starts'!$I$2:$L$101)/SUMIFS('RP - Unit Starts'!$L:$L,'RP - Unit Starts'!$C:$C,$C26,'RP - Unit Starts'!$F:$F,"Existing Units")} -> 0.0050482755 | H26: =F26-1 -> 0.012517928 | I26: =SUMIFS(Realpage!$I:$I,Realpage!$A:$A,$C26,Realpage!$F:$F,"Effective RPSF") -> 2.92 | J26: =I26/D26 -> 0.99013809 | K26: =J26-1 -> -0.0098619052 | M26: =AVERAGEIF('Realpage - His. Rent Change'!$A$2:$A$577,'Q2 2026 Summary'!C32,'Realpage - His. Rent Change'!$I$2:$AV$577) -> 0.0782 | N26: =AVERAGE(L26:M26) -> 0.0782 | O26: =MAX(0,-(K26/M26)) -> 0.12611132 | P26: =($P$3*M26)+K26 -> 0.38113809 | Q26: =(1+P26)^(1/$P$3)-1 -> 0.06671259 | R26: =$R$3+P26 -> 0.43213809 | S26: =$S$3*$P$3 -> 0.125 | T26: =SUMIFS(Realpage!$I:$I,Realpage!$A:$A,$C26,Realpage!$F:$F,"NOI % of Revenue") -> 1.2121145 | U26: 1 | V26: =U26-T26 -> -0.21211451 | W26: =U26*(1+R26) -> 1.4321381 | X26: =V26*(1+S26) -> -0.23862882 | Y26: =W26-X26 -> 1.6707669 | Z26: =Y26/T26-1 -> 0.37839033 | AA26: =(Y26/T26)^(1/$P$3)-1 -> 0.066287808 | AB26: =$AB$3 -> 0.05 | AC26: =AB26/$AB$3 -> 1 | AD26: =AC26*(1+$AD$3) -> 1.08 | AE26: =AC26*AB26 -> 0.05 | AF26: =AE26*(1+Z26) -> 0.068919516 | AG26: =AF26/AD26 -> 0.063814367 | AH26: =AG26-AB26 -> 0.013814367 | AI26: =ROUND(AH26,4) -> 0.0138 | AJ26: {=INDEX('Cap Rate to IRR Map'!$F$3:$F$623,MATCH(ROUND(AI26,4),ROUND('Cap Rate to IRR Map'!$E$3:$E$623,4),0))} -> 0.122 | AK26: =$AK$3 -> 0.05 | AL26: 0.109
B27: =B26+1 -> 23 | C27: Des Moines-West Des Moines, IA | D27: =SUMIFS(Realpage!$I:$I,Realpage!$A:$A,$C27,Realpage!$F:$F,"Rent Roll (Rev/OSF)") -> 2.5974637 | E27: =SUMIFS(Realpage!$I:$I,Realpage!$A:$A,$C27,Realpage!$F:$F,"Asking RPSF") -> 2.627 | F27: =E27/D27 -> 1.0113712 | G27: {=SUMPRODUCT(('RP - Unit Starts'!$C$2:$C$101=$C27)*('RP - Unit Starts'!$F$2:$F$101="Unit Starts")*'RP - Unit Starts'!$I$2:$L$101)/SUMIFS('RP - Unit Starts'!$L:$L,'RP - Unit Starts'!$C:$C,$C27,'RP - Unit Starts'!$F:$F,"Existing Units")} -> 0.011765675 | H27: =F27-1 -> 0.011371189 | I27: =SUMIFS(Realpage!$I:$I,Realpage!$A:$A,$C27,Realpage!$F:$F,"Effective RPSF") -> 2.571 | J27: =I27/D27 -> 0.9898117 | K27: =J27-1 -> -0.010188304 | M27: =AVERAGEIF('Realpage - His. Rent Change'!$A$2:$A$577,'Q2 2026 Summary'!C30,'Realpage - His. Rent Change'!$I$2:$AV$577) -> 0.0686 | N27: =AVERAGE(L27:M27) -> 0.0686 | O27: =MAX(0,-(K27/M27)) -> 0.14851755 | P27: =($P$3*M27)+K27 -> 0.3328117 | Q27: =(1+P27)^(1/$P$3)-1 -> 0.059140948 | R27: =$R$3+P27 -> 0.3838117 | S27: =$S$3*$P$3 -> 0.125 | T27: =SUMIFS(Realpage!$I:$I,Realpage!$A:$A,$C27,Realpage!$F:$F,"NOI % of Revenue") -> 1.0647583 | U27: 1 | V27: =U27-T27 -> -0.064758277 | W27: =U27*(1+R27) -> 1.3838117 | X27: =V27*(1+S27) -> -0.072853061 | Y27: =W27-X27 -> 1.4566648 | Z27: =Y27/T27-1 -> 0.36807085 | AA27: =(Y27/T27)^(1/$P$3)-1 -> 0.064686427 | AB27: =$AB$3 -> 0.05 | AC27: =AB27/$AB$3 -> 1 | AD27: =AC27*(1+$AD$3) -> 1.08 | AE27: =AC27*AB27 -> 0.05 | AF27: =AE27*(1+Z27) -> 0.068403542 | AG27: =AF27/AD27 -> 0.063336613 | AH27: =AG27-AB27 -> 0.013336613 | AI27: =ROUND(AH27,4) -> 0.0133 | AJ27: {=INDEX('Cap Rate to IRR Map'!$F$3:$F$623,MATCH(ROUND(AI27,4),ROUND('Cap Rate to IRR Map'!$E$3:$E$623,4),0))} -> 0.11825 | AK27: =$AK$3 -> 0.05 | AL27: 0.169667 | AO27: Atlanta
B28: =B27+1 -> 24 | C28: Greensboro-High Point/Winston-Salem/Burlington, NC | D28: =SUMIFS(Realpage!$I:$I,Realpage!$A:$A,$C28,Realpage!$F:$F,"Rent Roll (Rev/OSF)") -> 2.6386152 | E28: =SUMIFS(Realpage!$I:$I,Realpage!$A:$A,$C28,Realpage!$F:$F,"Asking RPSF") -> 2.661 | F28: =E28/D28 -> 1.0084835 | G28: {=SUMPRODUCT(('RP - Unit Starts'!$C$2:$C$101=$C28)*('RP - Unit Starts'!$F$2:$F$101="Unit Starts")*'RP - Unit Starts'!$I$2:$L$101)/SUMIFS('RP - Unit Starts'!$L:$L,'RP - Unit Starts'!$C:$C,$C28,'RP - Unit Starts'!$F:$F,"Existing Units")} -> 0.015879717 | H28: =F28-1 -> 0.0084835233 | I28: =SUMIFS(Realpage!$I:$I,Realpage!$A:$A,$C28,Realpage!$F:$F,"Effective RPSF") -> 2.63 | J28: =I28/D28 -> 0.99673494 | K28: =J28-1 -> -0.0032650634 | M28: =AVERAGEIF('Realpage - His. Rent Change'!$A$2:$A$577,'Q2 2026 Summary'!C25,'Realpage - His. Rent Change'!$I$2:$AV$577) -> 0.0465 | N28: =AVERAGE(L28:M28) -> 0.0465 | O28: =MAX(0,-(K28/M28)) -> 0.070216418 | P28: =($P$3*M28)+K28 -> 0.22923494 | Q28: =(1+P28)^(1/$P$3)-1 -> 0.042142192 | R28: =$R$3+P28 -> 0.28023494 | S28: =$S$3*$P$3 -> 0.125 | T28: =SUMIFS(Realpage!$I:$I,Realpage!$A:$A,$C28,Realpage!$F:$F,"NOI % of Revenue") -> 1.0800774 | U28: 1 | V28: =U28-T28 -> -0.080077403 | W28: =U28*(1+R28) -> 1.2802349 | X28: =V28*(1+S28) -> -0.090087079 | Y28: =W28-X28 -> 1.370322 | Z28: =Y28/T28-1 -> 0.26872575 | AA28: =(Y28/T28)^(1/$P$3)-1 -> 0.048753809 | AB28: =$AB$3 -> 0.05 | AC28: =AB28/$AB$3 -> 1 | AD28: =AC28*(1+$AD$3) -> 1.08 | AE28: =AC28*AB28 -> 0.05 | AF28: =AE28*(1+Z28) -> 0.063436288 | AG28: =AF28/AD28 -> 0.058737303 | AH28: =AG28-AB28 -> 0.0087373033 | AI28: =ROUND(AH28,4) -> 0.0087 | AJ28: {=INDEX('Cap Rate to IRR Map'!$F$3:$F$623,MATCH(ROUND(AI28,4),ROUND('Cap Rate to IRR Map'!$E$3:$E$623,4),0))} -> 0.081 | AK28: =$AK$3 -> 0.05 | AL28: 0.164667
B29: =B28+1 -> 25 | C29: St. Louis, MO-IL | D29: =SUMIFS(Realpage!$I:$I,Realpage!$A:$A,$C29,Realpage!$F:$F,"Rent Roll (Rev/OSF)") -> 3.0998673 | E29: =SUMIFS(Realpage!$I:$I,Realpage!$A:$A,$C29,Realpage!$F:$F,"Asking RPSF") -> 3.118 | F29: =E29/D29 -> 1.0058495 | G29: {=SUMPRODUCT(('RP - Unit Starts'!$C$2:$C$101=$C29)*('RP - Unit Starts'!$F$2:$F$101="Unit Starts")*'RP - Unit Starts'!$I$2:$L$101)/SUMIFS('RP - Unit Starts'!$L:$L,'RP - Unit Starts'!$C:$C,$C29,'RP - Unit Starts'!$F:$F,"Existing Units")} -> 0.011046634 | H29: =F29-1 -> 0.0058495057 | I29: =SUMIFS(Realpage!$I:$I,Realpage!$A:$A,$C29,Realpage!$F:$F,"Effective RPSF") -> 3.091 | J29: =I29/D29 -> 0.99713946 | K29: =J29-1 -> -0.0028605445 | M29: =AVERAGEIF('Realpage - His. Rent Change'!$A$2:$A$577,'Q2 2026 Summary'!C24,'Realpage - His. Rent Change'!$I$2:$AV$577) -> 0.0618 | N29: =AVERAGE(L29:M29) -> 0.0618 | O29: =MAX(0,-(K29/M29)) -> 0.046287128 | P29: =($P$3*M29)+K29 -> 0.30613946 | Q29: =(1+P29)^(1/$P$3)-1 -> 0.054867494 | R29: =$R$3+P29 -> 0.35713946 | S29: =$S$3*$P$3 -> 0.125 | T29: =SUMIFS(Realpage!$I:$I,Realpage!$A:$A,$C29,Realpage!$F:$F,"NOI % of Revenue") -> 1.119636 | U29: 1 | V29: =U29-T29 -> -0.11963596 | W29: =U29*(1+R29) -> 1.3571395 | X29: =V29*(1+S29) -> -0.13459045 | Y29: =W29-X29 -> 1.4917299 | Z29: =Y29/T29-1 -> 0.33233476 | AA29: =(Y29/T29)^(1/$P$3)-1 -> 0.059065137 | AB29: =$AB$3 -> 0.05 | AC29: =AB29/$AB$3 -> 1 | AD29: =AC29*(1+$AD$3) -> 1.08 | AE29: =AC29*AB29 -> 0.05 | AF29: =AE29*(1+Z29) -> 0.066616738 | AG29: =AF29/AD29 -> 0.061682165 | AH29: =AG29-AB29 -> 0.011682165 | AI29: =ROUND(AH29,4) -> 0.0117 | AJ29: {=INDEX('Cap Rate to IRR Map'!$F$3:$F$623,MATCH(ROUND(AI29,4),ROUND('Cap Rate to IRR Map'!$E$3:$E$623,4),0))} -> 0.106 | AK29: =$AK$3 -> 0.05 | AL29: 0.171 | AN29: These markets should be monitored but materially de-prioritized until or unless there is an extraordinary opportunity that offsets the organic headwinds, or a submarket/location that is wildy different than market avg
B30: =B29+1 -> 26 | C30: Fort Lauderdale-Pompano Beach-Sunrise, FL | D30: =SUMIFS(Realpage!$I:$I,Realpage!$A:$A,$C30,Realpage!$F:$F,"Rent Roll (Rev/OSF)") -> 4.8866681 | E30: =SUMIFS(Realpage!$I:$I,Realpage!$A:$A,$C30,Realpage!$F:$F,"Asking RPSF") -> 4.901 | F30: =E30/D30 -> 1.0029329 | G30: {=SUMPRODUCT(('RP - Unit Starts'!$C$2:$C$101=$C30)*('RP - Unit Starts'!$F$2:$F$101="Unit Starts")*'RP - Unit Starts'!$I$2:$L$101)/SUMIFS('RP - Unit Starts'!$L:$L,'RP - Unit Starts'!$C:$C,$C30,'RP - Unit Starts'!$F:$F,"Existing Units")} -> 0.0097416072 | H30: =F30-1 -> 0.0029328568 | I30: =SUMIFS(Realpage!$I:$I,Realpage!$A:$A,$C30,Realpage!$F:$F,"Effective RPSF") -> 4.838 | J30: =I30/D30 -> 0.99004064 | K30: =J30-1 -> -0.0099593632 | L30: 0.0444 | M30: =AVERAGEIF('Realpage - His. Rent Change'!$A$2:$A$577,'Q2 2026 Summary'!C26,'Realpage - His. Rent Change'!$I$2:$AV$577) -> 0.0658 | N30: =AVERAGE(L30:M30) -> 0.0551 | O30: =MAX(0,-(K30/M30)) -> 0.1513581 | P30: =($P$3*M30)+K30 -> 0.31904064 | Q30: =(1+P30)^(1/$P$3)-1 -> 0.056943166 | R30: =$R$3+P30 -> 0.37004064 | S30: =$S$3*$P$3 -> 0.125 | T30: =SUMIFS(Realpage!$I:$I,Realpage!$A:$A,$C30,Realpage!$F:$F,"NOI % of Revenue") -> 1.1143069 | U30: 1 | V30: =U30-T30 -> -0.11430694 | W30: =U30*(1+R30) -> 1.3700406 | X30: =V30*(1+S30) -> -0.12859531 | Y30: =W30-X30 -> 1.4986359 | Z30: =Y30/T30-1 -> 0.34490407 | AA30: =(Y30/T30)^(1/$P$3)-1 -> 0.061055893 | AB30: =$AB$3 -> 0.05 | AC30: =AB30/$AB$3 -> 1 | AD30: =AC30*(1+$AD$3) -> 1.08 | AE30: =AC30*AB30 -> 0.05 | AF30: =AE30*(1+Z30) -> 0.067245204 | AG30: =AF30/AD30 -> 0.062264078 | AH30: =AG30-AB30 -> 0.012264078 | AI30: =ROUND(AH30,4) -> 0.0123 | AJ30: {=INDEX('Cap Rate to IRR Map'!$F$3:$F$623,MATCH(ROUND(AI30,4),ROUND('Cap Rate to IRR Map'!$E$3:$E$623,4),0))} -> 0.110333 | AK30: =$AK$3 -> 0.05 | AL30: 0.126333 | AN30: 65% Leverage, 5 years, 3 years IO, leverage neutral (5% fixed rate)
B31: =B30+1 -> 27 | C31: Cape Coral-Fort Myers, FL | D31: =SUMIFS(Realpage!$I:$I,Realpage!$A:$A,$C31,Realpage!$F:$F,"Rent Roll (Rev/OSF)") -> 3.338843 | E31: =SUMIFS(Realpage!$I:$I,Realpage!$A:$A,$C31,Realpage!$F:$F,"Asking RPSF") -> 3.348 | F31: =E31/D31 -> 1.0027426 | G31: {=SUMPRODUCT(('RP - Unit Starts'!$C$2:$C$101=$C31)*('RP - Unit Starts'!$F$2:$F$101="Unit Starts")*'RP - Unit Starts'!$I$2:$L$101)/SUMIFS('RP - Unit Starts'!$L:$L,'RP - Unit Starts'!$C:$C,$C31,'RP - Unit Starts'!$F:$F,"Existing Units")} -> 0.016965989 | H31: =F31-1 -> 0.0027425565 | I31: =SUMIFS(Realpage!$I:$I,Realpage!$A:$A,$C31,Realpage!$F:$F,"Effective RPSF") -> 3.145 | J31: =I31/D31 -> 0.94194305 | K31: =J31-1 -> -0.058056947 | M31: =AVERAGEIF('Realpage - His. Rent Change'!$A$2:$A$577,'Q2 2026 Summary'!C50,'Realpage - His. Rent Change'!$I$2:$AV$577) -> 0.0741 | N31: =AVERAGE(L31:M31) -> 0.0741 | O31: =MAX(0,-(K31/M31)) -> 0.78349457 | P31: =($P$3*M31)+K31 -> 0.31244305 | Q31: =(1+P31)^(1/$P$3)-1 -> 0.05588372 | R31: =$R$3+P31 -> 0.36344305 | S31: =$S$3*$P$3 -> 0.125 | T31: =SUMIFS(Realpage!$I:$I,Realpage!$A:$A,$C31,Realpage!$F:$F,"NOI % of Revenue") -> 1.0244956 | U31: 1 | V31: =U31-T31 -> -0.02449564 | W31: =U31*(1+R31) -> 1.3634431 | X31: =V31*(1+S31) -> -0.027557595 | Y31: =W31-X31 -> 1.3910006 | Z31: =Y31/T31-1 -> 0.35774189 | AA31: =(Y31/T31)^(1/$P$3)-1 -> 0.06307387 | AB31: =$AB$3 -> 0.05 | AC31: =AB31/$AB$3 -> 1 | AD31: =AC31*(1+$AD$3) -> 1.08 | AE31: =AC31*AB31 -> 0.05 | AF31: =AE31*(1+Z31) -> 0.067887095 | AG31: =AF31/AD31 -> 0.062858421 | AH31: =AG31-AB31 -> 0.012858421 | AI31: =ROUND(AH31,4) -> 0.0129 | AJ31: {=INDEX('Cap Rate to IRR Map'!$F$3:$F$623,MATCH(ROUND(AI31,4),ROUND('Cap Rate to IRR Map'!$E$3:$E$623,4),0))} -> 0.115333 | AK31: =$AK$3 -> 0.05 | AL31: 0.1915 | AO31: Houston
B32: =B31+1 -> 28 | C32: Colorado Springs, CO | D32: =SUMIFS(Realpage!$I:$I,Realpage!$A:$A,$C32,Realpage!$F:$F,"Rent Roll (Rev/OSF)") -> 3.4269127 | E32: =SUMIFS(Realpage!$I:$I,Realpage!$A:$A,$C32,Realpage!$F:$F,"Asking RPSF") -> 3.436 | F32: =E32/D32 -> 1.0026518 | G32: {=SUMPRODUCT(('RP - Unit Starts'!$C$2:$C$101=$C32)*('RP - Unit Starts'!$F$2:$F$101="Unit Starts")*'RP - Unit Starts'!$I$2:$L$101)/SUMIFS('RP - Unit Starts'!$L:$L,'RP - Unit Starts'!$C:$C,$C32,'RP - Unit Starts'!$F:$F,"Existing Units")} -> 0.0067899973 | H32: =F32-1 -> 0.0026517534 | I32: =SUMIFS(Realpage!$I:$I,Realpage!$A:$A,$C32,Realpage!$F:$F,"Effective RPSF") -> 3.333 | J32: =I32/D32 -> 0.97259555 | K32: =J32-1 -> -0.027404455 | M32: =AVERAGEIF('Realpage - His. Rent Change'!$A$2:$A$577,'Q2 2026 Summary'!C36,'Realpage - His. Rent Change'!$I$2:$AV$577) -> 0.0706 | N32: =AVERAGE(L32:M32) -> 0.0706 | O32: =MAX(0,-(K32/M32)) -> 0.38816508 | P32: =($P$3*M32)+K32 -> 0.32559555 | Q32: =(1+P32)^(1/$P$3)-1 -> 0.05799157 | R32: =$R$3+P32 -> 0.37659555 | S32: =$S$3*$P$3 -> 0.125 | T32: =SUMIFS(Realpage!$I:$I,Realpage!$A:$A,$C32,Realpage!$F:$F,"NOI % of Revenue") -> 1.2797618 | U32: 1 | V32: =U32-T32 -> -0.27976184 | W32: =U32*(1+R32) -> 1.3765955 | X32: =V32*(1+S32) -> -0.31473207 | Y32: =W32-X32 -> 1.6913276 | Z32: =Y32/T32-1 -> 0.3215956 | AA32: =(Y32/T32)^(1/$P$3)-1 -> 0.057352306 | AB32: =$AB$3 -> 0.05 | AC32: =AB32/$AB$3 -> 1 | AD32: =AC32*(1+$AD$3) -> 1.08 | AE32: =AC32*AB32 -> 0.05 | AF32: =AE32*(1+Z32) -> 0.06607978 | AG32: =AF32/AD32 -> 0.061184981 | AH32: =AG32-AB32 -> 0.011184981 | AI32: =ROUND(AH32,4) -> 0.0112 | AJ32: {=INDEX('Cap Rate to IRR Map'!$F$3:$F$623,MATCH(ROUND(AI32,4),ROUND('Cap Rate to IRR Map'!$E$3:$E$623,4),0))} -> 0.101667 | AK32: =$AK$3 -> 0.05 | AL32: 0.093
B33: =B32+1 -> 29 | C33: Albuquerque, NM | D33: =SUMIFS(Realpage!$I:$I,Realpage!$A:$A,$C33,Realpage!$F:$F,"Rent Roll (Rev/OSF)") -> 1.628002 | E33: =SUMIFS(Realpage!$I:$I,Realpage!$A:$A,$C33,Realpage!$F:$F,"Asking RPSF") -> 1.628 | F33: =E33/D33 -> 0.99999877 | G33: {=SUMPRODUCT(('RP - Unit Starts'!$C$2:$C$101=$C33)*('RP - Unit Starts'!$F$2:$F$101="Unit Starts")*'RP - Unit Starts'!$I$2:$L$101)/SUMIFS('RP - Unit Starts'!$L:$L,'RP - Unit Starts'!$C:$C,$C33,'RP - Unit Starts'!$F:$F,"Existing Units")} -> 0.0046547843 | H33: =F33-1 -> -1.2264529e-06 | I33: =SUMIFS(Realpage!$I:$I,Realpage!$A:$A,$C33,Realpage!$F:$F,"Effective RPSF") -> 1.612 | J33: =I33/D33 -> 0.99017078 | K33: =J33-1 -> -0.0098292242 | M33: =AVERAGEIF('Realpage - His. Rent Change'!$A$2:$A$577,'Q2 2026 Summary'!C27,'Realpage - His. Rent Change'!$I$2:$AV$577) -> 0.0261 | N33: =AVERAGE(L33:M33) -> 0.0261 | O33: =MAX(0,-(K33/M33)) -> 0.37659863 | P33: =($P$3*M33)+K33 -> 0.12067078 | Q33: =(1+P33)^(1/$P$3)-1 -> 0.023047055 | R33: =$R$3+P33 -> 0.17167078 | S33: =$S$3*$P$3 -> 0.125 | T33: =SUMIFS(Realpage!$I:$I,Realpage!$A:$A,$C33,Realpage!$F:$F,"NOI % of Revenue") -> 0.61413872 | U33: 1 | V33: =U33-T33 -> 0.38586128 | W33: =U33*(1+R33) -> 1.1716708 | X33: =V33*(1+S33) -> 0.43409394 | Y33: =W33-X33 -> 0.73757684 | Z33: =Y33/T33-1 -> 0.20099387 | AA33: =(Y33/T33)^(1/$P$3)-1 -> 0.037309028 | AB33: =$AB$3 -> 0.05 | AC33: =AB33/$AB$3 -> 1 | AD33: =AC33*(1+$AD$3) -> 1.08 | AE33: =AC33*AB33 -> 0.05 | AF33: =AE33*(1+Z33) -> 0.060049693 | AG33: =AF33/AD33 -> 0.055601568 | AH33: =AG33-AB33 -> 0.0056015679 | AI33: =ROUND(AH33,4) -> 0.0056 | AJ33: {=INDEX('Cap Rate to IRR Map'!$F$3:$F$623,MATCH(ROUND(AI33,4),ROUND('Cap Rate to IRR Map'!$E$3:$E$623,4),0))} -> 0.053 | AK33: =$AK$3 -> 0.05 | AL33: 0.32432749 | AN33: VA: 50% of units, 10k avg cost with a 20% ROC
B34: =B33+1 -> 30 | C34: Austin-Round Rock-San Marcos, TX | D34: =SUMIFS(Realpage!$I:$I,Realpage!$A:$A,$C34,Realpage!$F:$F,"Rent Roll (Rev/OSF)") -> 1.6921104 | E34: =SUMIFS(Realpage!$I:$I,Realpage!$A:$A,$C34,Realpage!$F:$F,"Asking RPSF") -> 1.691 | F34: =E34/D34 -> 0.9993438 | G34: {=SUMPRODUCT(('RP - Unit Starts'!$C$2:$C$101=$C34)*('RP - Unit Starts'!$F$2:$F$101="Unit Starts")*'RP - Unit Starts'!$I$2:$L$101)/SUMIFS('RP - Unit Starts'!$L:$L,'RP - Unit Starts'!$C:$C,$C34,'RP - Unit Starts'!$F:$F,"Existing Units")} -> 0.015673893 | H34: =F34-1 -> -0.00065620205 | I34: =SUMIFS(Realpage!$I:$I,Realpage!$A:$A,$C34,Realpage!$F:$F,"Effective RPSF") -> 1.595 | J34: =I34/D34 -> 0.94260991 | K34: =J34-1 -> -0.05739009 | L34: 0.0198 | M34: =AVERAGEIF('Realpage - His. Rent Change'!$A$2:$A$577,'Q2 2026 Summary'!C53,'Realpage - His. Rent Change'!$I$2:$AV$577) -> 0.016 | N34: =AVERAGE(L34:M34) -> 0.0179 | O34: =MAX(0,-(K34/M34)) -> 3.5868806 | P34: =($P$3*M34)+K34 -> 0.02260991 | Q34: =(1+P34)^(1/$P$3)-1 -> 0.0044816315 | R34: =$R$3+P34 -> 0.07360991 | S34: =$S$3*$P$3 -> 0.125 | T34: =SUMIFS(Realpage!$I:$I,Realpage!$A:$A,$C34,Realpage!$F:$F,"NOI % of Revenue") -> 0.45675923 | U34: 1 | V34: =U34-T34 -> 0.54324077 | W34: =U34*(1+R34) -> 1.0736099 | X34: =V34*(1+S34) -> 0.61114586 | Y34: =W34-X34 -> 0.46246405 | Z34: =Y34/T34-1 -> 0.012489762 | AA34: =(Y34/T34)^(1/$P$3)-1 -> 0.0024855656 | AB34: =$AB$3 -> 0.05 | AC34: =AB34/$AB$3 -> 1 | AD34: =AC34*(1+$AD$3) -> 1.08 | AE34: =AC34*AB34 -> 0.05 | AF34: =AE34*(1+Z34) -> 0.050624488 | AG34: =AF34/AD34 -> 0.046874526 | AH34: =AG34-AB34 -> -0.003125474 | AI34: =ROUND(AH34,4) -> -0.0031 | AJ34: {=INDEX('Cap Rate to IRR Map'!$F$3:$F$623,MATCH(ROUND(AI34,4),ROUND('Cap Rate to IRR Map'!$E$3:$E$623,4),0))} -> -0.045 | AK34: =$AK$3 -> 0.05 | AL34: 0.268 | AN34: 10-year historical rent growth continues for next 5 years
B35: =B34+1 -> 31 | C35: Jacksonville, FL | D35: =SUMIFS(Realpage!$I:$I,Realpage!$A:$A,$C35,Realpage!$F:$F,"Rent Roll (Rev/OSF)") -> 2.9831686 | E35: =SUMIFS(Realpage!$I:$I,Realpage!$A:$A,$C35,Realpage!$F:$F,"Asking RPSF") -> 2.979 | F35: =E35/D35 -> 0.99860263 | G35: {=SUMPRODUCT(('RP - Unit Starts'!$C$2:$C$101=$C35)*('RP - Unit Starts'!$F$2:$F$101="Unit Starts")*'RP - Unit Starts'!$I$2:$L$101)/SUMIFS('RP - Unit Starts'!$L:$L,'RP - Unit Starts'!$C:$C,$C35,'RP - Unit Starts'!$F:$F,"Existing Units")} -> 0.010989511 | H35: =F35-1 -> -0.0013973677 | I35: =SUMIFS(Realpage!$I:$I,Realpage!$A:$A,$C35,Realpage!$F:$F,"Effective RPSF") -> 2.904 | J35: =I35/D35 -> 0.97346158 | K35: =J35-1 -> -0.026538421 | L35: 0.0435 | M35: =AVERAGEIF('Realpage - His. Rent Change'!$A$2:$A$577,'Q2 2026 Summary'!C38,'Realpage - His. Rent Change'!$I$2:$AV$577) -> 0.0695 | N35: =AVERAGE(L35:M35) -> 0.0565 | O35: =MAX(0,-(K35/M35)) -> 0.38184778 | P35: =($P$3*M35)+K35 -> 0.32096158 | Q35: =(1+P35)^(1/$P$3)-1 -> 0.057250836 | R35: =$R$3+P35 -> 0.37196158 | S35: =$S$3*$P$3 -> 0.125 | T35: =SUMIFS(Realpage!$I:$I,Realpage!$A:$A,$C35,Realpage!$F:$F,"NOI % of Revenue") -> 1.0428326 | U35: 1 | V35: =U35-T35 -> -0.042832612 | W35: =U35*(1+R35) -> 1.3719616 | X35: =V35*(1+S35) -> -0.048186689 | Y35: =W35-X35 -> 1.4201483 | Z35: =Y35/T35-1 -> 0.36181804 | AA35: =(Y35/T35)^(1/$P$3)-1 -> 0.063711408 | AB35: =$AB$3 -> 0.05 | AC35: =AB35/$AB$3 -> 1 | AD35: =AC35*(1+$AD$3) -> 1.08 | AE35: =AC35*AB35 -> 0.05 | AF35: =AE35*(1+Z35) -> 0.068090902 | AG35: =AF35/AD35 -> 0.063047132 | AH35: =AG35-AB35 -> 0.013047132 | AI35: =ROUND(AH35,4) -> 0.013 | AJ35: {=INDEX('Cap Rate to IRR Map'!$F$3:$F$623,MATCH(ROUND(AI35,4),ROUND('Cap Rate to IRR Map'!$E$3:$E$623,4),0))} -> 0.116 | AK35: =$AK$3 -> 0.05 | AL35: 0.152333
B36: =B35+1 -> 32 | C36: Palm Bay-Melbourne-Titusville, FL | D36: =SUMIFS(Realpage!$I:$I,Realpage!$A:$A,$C36,Realpage!$F:$F,"Rent Roll (Rev/OSF)") -> 3.3272076 | E36: =SUMIFS(Realpage!$I:$I,Realpage!$A:$A,$C36,Realpage!$F:$F,"Asking RPSF") -> 3.318 | F36: =E36/D36 -> 0.99723263 | G36: {=SUMPRODUCT(('RP - Unit Starts'!$C$2:$C$101=$C36)*('RP - Unit Starts'!$F$2:$F$101="Unit Starts")*'RP - Unit Starts'!$I$2:$L$101)/SUMIFS('RP - Unit Starts'!$L:$L,'RP - Unit Starts'!$C:$C,$C36,'RP - Unit Starts'!$F:$F,"Existing Units")} -> 0 | H36: =F36-1 -> -0.0027673696 | I36: =SUMIFS(Realpage!$I:$I,Realpage!$A:$A,$C36,Realpage!$F:$F,"Effective RPSF") -> 3.239 | J36: =I36/D36 -> 0.973489 | K36: =J36-1 -> -0.026511004 | M36: =AVERAGEIF('Realpage - His. Rent Change'!$A$2:$A$577,'Q2 2026 Summary'!C29,'Realpage - His. Rent Change'!$I$2:$AV$577) -> 0.0461 | N36: =AVERAGE(L36:M36) -> 0.0461 | O36: =MAX(0,-(K36/M36)) -> 0.575076 | P36: =($P$3*M36)+K36 -> 0.203989 | Q36: =(1+P36)^(1/$P$3)-1 -> 0.037825897 | R36: =$R$3+P36 -> 0.254989 | S36: =$S$3*$P$3 -> 0.125 | T36: =SUMIFS(Realpage!$I:$I,Realpage!$A:$A,$C36,Realpage!$F:$F,"NOI % of Revenue") -> 1.0697444 | U36: 1 | V36: =U36-T36 -> -0.069744449 | W36: =U36*(1+R36) -> 1.254989 | X36: =V36*(1+S36) -> -0.078462505 | Y36: =W36-X36 -> 1.3334515 | Z36: =Y36/T36-1 -> 0.24651406 | AA36: =(Y36/T36)^(1/$P$3)-1 -> 0.045055696 | AB36: =$AB$3 -> 0.05 | AC36: =AB36/$AB$3 -> 1 | AD36: =AC36*(1+$AD$3) -> 1.08 | AE36: =AC36*AB36 -> 0.05 | AF36: =AE36*(1+Z36) -> 0.062325703 | AG36: =AF36/AD36 -> 0.057708984 | AH36: =AG36-AB36 -> 0.0077089845 | AI36: =ROUND(AH36,4) -> 0.0077 | AJ36: {=INDEX('Cap Rate to IRR Map'!$F$3:$F$623,MATCH(ROUND(AI36,4),ROUND('Cap Rate to IRR Map'!$E$3:$E$623,4),0))} -> 0.072 | AK36: =$AK$3 -> 0.05 | AL36: 0.145 | AO36: Accretive loan assumptions that enhacne returns
