Workbook

Sheet Q2 2026 Summary
C2: Multifamily Market Summary — Recovery Screen
C3: Effective RPSF | Rent Roll (Rev/OSF) — RealPage Q2 2026 actuals + RealPage same-store forecast through 2029Q4. Rent roll held flat per CB spec (directional / conservative). Sorted by forecast years back to even.
B4: # | C4: Market | D4: Rent Roll PSF | E4: Asking RPSF | F4: Effective RPSF | G4: Gross Embedded RR Mark to Market | H4: Effective Embedded RR Mark to Market | I4: TTM Unit Starts as % of Inv | J4: Fwd 12-Mo Inventory Growth (RP Fcst) | K4: Fcst Rent Growth Yr 1 (26Q2→27Q2) | L4: Fcst Rent Growth Yr 2 (27Q2→28Q2) | M4: Fcst Rent Growth Yr 3 (28Q2→29Q2) | N4: Fcst MtM +1 Yr | O4: Fcst MtM +2 Yrs | P4: Fcst MtM +3 Yrs | Q4: Years to Rent Roll Even (RP Forecast) | S4: 10-Yr Hist Avg Rent Growth (RP) | T4: 10-Yr Hist Avg Rent Growth (GSA) | U4: 10-Yr Avg Hist. Rent Growth (GSA & RP) | V4: Years to Even (Old Method: 10-Yr Hist Avg)
B5: =ROW()-4 -> 1 | C5: Madison, WI | D5: =SUMIFS('Realpage Data'!$R$2:$R$899,'Realpage Data'!$A$2:$A$899,$C5,'Realpage Data'!$F$2:$F$899,"Rent Roll (Rev/OSF)") -> 1.5625838 | E5: =SUMIFS('Realpage Data'!$R$2:$R$899,'Realpage Data'!$A$2:$A$899,$C5,'Realpage Data'!$F$2:$F$899,"Asking RPSF") -> 1.882 | F5: =SUMIFS('Realpage Data'!$R$2:$R$899,'Realpage Data'!$A$2:$A$899,$C5,'Realpage Data'!$F$2:$F$899,"Effective RPSF") -> 1.861 | G5: =E5/$D5-1 -> 0.20441542 | H5: =F5/$D5-1 -> 0.19097614 | I5: =SUMIFS('RP - Unit Starts'!$AC$2:$AC$451,'RP - Unit Starts'!$A$2:$A$451,$C5,'RP - Unit Starts'!$F$2:$F$451,"Annual Unit Starts")/SUMIFS('RP - Unit Starts'!$AC$2:$AC$451,'RP - Unit Starts'!$A$2:$A$451,$C5,'RP - Unit Starts'!$F$2:$F$451,"Existing Units") -> 0.034117814 | J5: =SUMIFS('Realpage Data'!$V$2:$V$899,'Realpage Data'!$A$2:$A$899,$C5,'Realpage Data'!$F$2:$F$899,"Existing Units")/SUMIFS('Realpage Data'!$R$2:$R$899,'Realpage Data'!$A$2:$A$899,$C5,'Realpage Data'!$F$2:$F$899,"Existing Units")-1 -> 0.035301638 | K5: =INDEX('Fcst Walk'!$J$5:$J$69,MATCH($C5,'Fcst Walk'!$A$5:$A$69,0))/INDEX('Fcst Walk'!$F$5:$F$69,MATCH($C5,'Fcst Walk'!$A$5:$A$69,0))-1 -> 0.027 | L5: =INDEX('Fcst Walk'!$N$5:$N$69,MATCH($C5,'Fcst Walk'!$A$5:$A$69,0))/INDEX('Fcst Walk'!$J$5:$J$69,MATCH($C5,'Fcst Walk'!$A$5:$A$69,0))-1 -> 0.027 | M5: =INDEX('Fcst Walk'!$R$5:$R$69,MATCH($C5,'Fcst Walk'!$A$5:$A$69,0))/INDEX('Fcst Walk'!$N$5:$N$69,MATCH($C5,'Fcst Walk'!$A$5:$A$69,0))-1 -> 0.028 | N5: =INDEX('Fcst Walk'!$J$5:$J$69,MATCH($C5,'Fcst Walk'!$A$5:$A$69,0))/$D5-1 -> 0.22313249 | O5: =INDEX('Fcst Walk'!$N$5:$N$69,MATCH($C5,'Fcst Walk'!$A$5:$A$69,0))/$D5-1 -> 0.25615707 | P5: =INDEX('Fcst Walk'!$R$5:$R$69,MATCH($C5,'Fcst Walk'!$A$5:$A$69,0))/$D5-1 -> 0.29132947 | Q5: =INDEX('Fcst Walk'!$AM$5:$AM$69,MATCH($C5,'Fcst Walk'!$A$5:$A$69,0)) -> 0 | R5: =INDEX('Fcst Walk'!$AN$5:$AN$69,MATCH($C5,'Fcst Walk'!$A$5:$A$69,0)) | S5: =AVERAGE(INDEX('Realpage - His. Rent Change'!$I$2:$AV$577,MATCH($C5,'Realpage - His. Rent Change'!$A$2:$A$577,0),0)) -> 0.051645 | U5: =IF(T5="",S5,AVERAGE(S5,T5)) -> 0.051645 | V5: =IF(H5>=0,0,-H5/U5) -> 0
B6: =ROW()-4 -> 2 | C6: Sioux Falls, SD-MN | D6: =SUMIFS('Realpage Data'!$R$2:$R$899,'Realpage Data'!$A$2:$A$899,$C6,'Realpage Data'!$F$2:$F$899,"Rent Roll (Rev/OSF)") -> 1.1192592 | E6: =SUMIFS('Realpage Data'!$R$2:$R$899,'Realpage Data'!$A$2:$A$899,$C6,'Realpage Data'!$F$2:$F$899,"Asking RPSF") -> 1.303 | F6: =SUMIFS('Realpage Data'!$R$2:$R$899,'Realpage Data'!$A$2:$A$899,$C6,'Realpage Data'!$F$2:$F$899,"Effective RPSF") -> 1.284 | G6: =E6/$D6-1 -> 0.16416289 | H6: =F6/$D6-1 -> 0.14718738 | I6: =SUMIFS('RP - Unit Starts'!$AC$2:$AC$451,'RP - Unit Starts'!$A$2:$A$451,$C6,'RP - Unit Starts'!$F$2:$F$451,"Annual Unit Starts")/SUMIFS('RP - Unit Starts'!$AC$2:$AC$451,'RP - Unit Starts'!$A$2:$A$451,$C6,'RP - Unit Starts'!$F$2:$F$451,"Existing Units") -> 0.0021427697 | J6: =SUMIFS('Realpage Data'!$V$2:$V$899,'Realpage Data'!$A$2:$A$899,$C6,'Realpage Data'!$F$2:$F$899,"Existing Units")/SUMIFS('Realpage Data'!$R$2:$R$899,'Realpage Data'!$A$2:$A$899,$C6,'Realpage Data'!$F$2:$F$899,"Existing Units")-1 -> 0.006550753 | K6: =INDEX('Fcst Walk'!$J$5:$J$69,MATCH($C6,'Fcst Walk'!$A$5:$A$69,0))/INDEX('Fcst Walk'!$F$5:$F$69,MATCH($C6,'Fcst Walk'!$A$5:$A$69,0))-1 -> 0.028 | L6: =INDEX('Fcst Walk'!$N$5:$N$69,MATCH($C6,'Fcst Walk'!$A$5:$A$69,0))/INDEX('Fcst Walk'!$J$5:$J$69,MATCH($C6,'Fcst Walk'!$A$5:$A$69,0))-1 -> 0.022 | M6: =INDEX('Fcst Walk'!$R$5:$R$69,MATCH($C6,'Fcst Walk'!$A$5:$A$69,0))/INDEX('Fcst Walk'!$N$5:$N$69,MATCH($C6,'Fcst Walk'!$A$5:$A$69,0))-1 -> 0.021 | N6: =INDEX('Fcst Walk'!$J$5:$J$69,MATCH($C6,'Fcst Walk'!$A$5:$A$69,0))/$D6-1 -> 0.17930862 | O6: =INDEX('Fcst Walk'!$N$5:$N$69,MATCH($C6,'Fcst Walk'!$A$5:$A$69,0))/$D6-1 -> 0.20525341 | P6: =INDEX('Fcst Walk'!$R$5:$R$69,MATCH($C6,'Fcst Walk'!$A$5:$A$69,0))/$D6-1 -> 0.23056374 | Q6: =INDEX('Fcst Walk'!$AM$5:$AM$69,MATCH($C6,'Fcst Walk'!$A$5:$A$69,0)) -> 0 | R6: =INDEX('Fcst Walk'!$AN$5:$AN$69,MATCH($C6,'Fcst Walk'!$A$5:$A$69,0)) | S6: =AVERAGE(INDEX('Realpage - His. Rent Change'!$I$2:$AV$577,MATCH($C6,'Realpage - His. Rent Change'!$A$2:$A$577,0),0)) -> 0.03717 | U6: =IF(T6="",S6,AVERAGE(S6,T6)) -> 0.03717 | V6: =IF(H6>=0,0,-H6/U6) -> 0
B7: =ROW()-4 -> 3 | C7: Milwaukee-Waukesha/Racine, WI | D7: =SUMIFS('Realpage Data'!$R$2:$R$899,'Realpage Data'!$A$2:$A$899,$C7,'Realpage Data'!$F$2:$F$899,"Rent Roll (Rev/OSF)") -> 1.6017733 | E7: =SUMIFS('Realpage Data'!$R$2:$R$899,'Realpage Data'!$A$2:$A$899,$C7,'Realpage Data'!$F$2:$F$899,"Asking RPSF") -> 1.819 | F7: =SUMIFS('Realpage Data'!$R$2:$R$899,'Realpage Data'!$A$2:$A$899,$C7,'Realpage Data'!$F$2:$F$899,"Effective RPSF") -> 1.807 | G7: =E7/$D7-1 -> 0.13561636 | H7: =F7/$D7-1 -> 0.12812466 | I7: =SUMIFS('RP - Unit Starts'!$AC$2:$AC$451,'RP - Unit Starts'!$A$2:$A$451,$C7,'RP - Unit Starts'!$F$2:$F$451,"Annual Unit Starts")/SUMIFS('RP - Unit Starts'!$AC$2:$AC$451,'RP - Unit Starts'!$A$2:$A$451,$C7,'RP - Unit Starts'!$F$2:$F$451,"Existing Units") -> 0.011136083 | J7: =SUMIFS('Realpage Data'!$V$2:$V$899,'Realpage Data'!$A$2:$A$899,$C7,'Realpage Data'!$F$2:$F$899,"Existing Units")/SUMIFS('Realpage Data'!$R$2:$R$899,'Realpage Data'!$A$2:$A$899,$C7,'Realpage Data'!$F$2:$F$899,"Existing Units")-1 -> 0.01303184 | K7: =INDEX('Fcst Walk'!$J$5:$J$69,MATCH($C7,'Fcst Walk'!$A$5:$A$69,0))/INDEX('Fcst Walk'!$F$5:$F$69,MATCH($C7,'Fcst Walk'!$A$5:$A$69,0))-1 -> 0.035 | L7: =INDEX('Fcst Walk'!$N$5:$N$69,MATCH($C7,'Fcst Walk'!$A$5:$A$69,0))/INDEX('Fcst Walk'!$J$5:$J$69,MATCH($C7,'Fcst Walk'!$A$5:$A$69,0))-1 -> 0.025 | M7: =INDEX('Fcst Walk'!$R$5:$R$69,MATCH($C7,'Fcst Walk'!$A$5:$A$69,0))/INDEX('Fcst Walk'!$N$5:$N$69,MATCH($C7,'Fcst Walk'!$A$5:$A$69,0))-1 -> 0.022 | N7: =INDEX('Fcst Walk'!$J$5:$J$69,MATCH($C7,'Fcst Walk'!$A$5:$A$69,0))/$D7-1 -> 0.16760903 | O7: =INDEX('Fcst Walk'!$N$5:$N$69,MATCH($C7,'Fcst Walk'!$A$5:$A$69,0))/$D7-1 -> 0.19679925 | P7: =INDEX('Fcst Walk'!$R$5:$R$69,MATCH($C7,'Fcst Walk'!$A$5:$A$69,0))/$D7-1 -> 0.22312884 | Q7: =INDEX('Fcst Walk'!$AM$5:$AM$69,MATCH($C7,'Fcst Walk'!$A$5:$A$69,0)) -> 0 | R7: =INDEX('Fcst Walk'!$AN$5:$AN$69,MATCH($C7,'Fcst Walk'!$A$5:$A$69,0)) | S7: =AVERAGE(INDEX('Realpage - His. Rent Change'!$I$2:$AV$577,MATCH($C7,'Realpage - His. Rent Change'!$A$2:$A$577,0),0)) -> 0.050155 | U7: =IF(T7="",S7,AVERAGE(S7,T7)) -> 0.050155 | V7: =IF(H7>=0,0,-H7/U7) -> 0
B8: =ROW()-4 -> 4 | C8: Reno, NV | D8: =SUMIFS('Realpage Data'!$R$2:$R$899,'Realpage Data'!$A$2:$A$899,$C8,'Realpage Data'!$F$2:$F$899,"Rent Roll (Rev/OSF)") -> 1.8196774 | E8: =SUMIFS('Realpage Data'!$R$2:$R$899,'Realpage Data'!$A$2:$A$899,$C8,'Realpage Data'!$F$2:$F$899,"Asking RPSF") -> 2.025 | F8: =SUMIFS('Realpage Data'!$R$2:$R$899,'Realpage Data'!$A$2:$A$899,$C8,'Realpage Data'!$F$2:$F$899,"Effective RPSF") -> 2.008 | G8: =E8/$D8-1 -> 0.11283464 | H8: =F8/$D8-1 -> 0.10349233 | I8: =SUMIFS('RP - Unit Starts'!$AC$2:$AC$451,'RP - Unit Starts'!$A$2:$A$451,$C8,'RP - Unit Starts'!$F$2:$F$451,"Annual Unit Starts")/SUMIFS('RP - Unit Starts'!$AC$2:$AC$451,'RP - Unit Starts'!$A$2:$A$451,$C8,'RP - Unit Starts'!$F$2:$F$451,"Existing Units") -> 0.023921244 | J8: =SUMIFS('Realpage Data'!$V$2:$V$899,'Realpage Data'!$A$2:$A$899,$C8,'Realpage Data'!$F$2:$F$899,"Existing Units")/SUMIFS('Realpage Data'!$R$2:$R$899,'Realpage Data'!$A$2:$A$899,$C8,'Realpage Data'!$F$2:$F$899,"Existing Units")-1 -> 0.0056306928 | K8: =INDEX('Fcst Walk'!$J$5:$J$69,MATCH($C8,'Fcst Walk'!$A$5:$A$69,0))/INDEX('Fcst Walk'!$F$5:$F$69,MATCH($C8,'Fcst Walk'!$A$5:$A$69,0))-1 -> 0.034 | L8: =INDEX('Fcst Walk'!$N$5:$N$69,MATCH($C8,'Fcst Walk'!$A$5:$A$69,0))/INDEX('Fcst Walk'!$J$5:$J$69,MATCH($C8,'Fcst Walk'!$A$5:$A$69,0))-1 -> 0.037 | M8: =INDEX('Fcst Walk'!$R$5:$R$69,MATCH($C8,'Fcst Walk'!$A$5:$A$69,0))/INDEX('Fcst Walk'!$N$5:$N$69,MATCH($C8,'Fcst Walk'!$A$5:$A$69,0))-1 -> 0.05 | N8: =INDEX('Fcst Walk'!$J$5:$J$69,MATCH($C8,'Fcst Walk'!$A$5:$A$69,0))/$D8-1 -> 0.14101107 | O8: =INDEX('Fcst Walk'!$N$5:$N$69,MATCH($C8,'Fcst Walk'!$A$5:$A$69,0))/$D8-1 -> 0.18322847 | P8: =INDEX('Fcst Walk'!$R$5:$R$69,MATCH($C8,'Fcst Walk'!$A$5:$A$69,0))/$D8-1 -> 0.2423899 | Q8: =INDEX('Fcst Walk'!$AM$5:$AM$69,MATCH($C8,'Fcst Walk'!$A$5:$A$69,0)) -> 0 | R8: =INDEX('Fcst Walk'!$AN$5:$AN$69,MATCH($C8,'Fcst Walk'!$A$5:$A$69,0)) | S8: =AVERAGE(INDEX('Realpage - His. Rent Change'!$I$2:$AV$577,MATCH($C8,'Realpage - His. Rent Change'!$A$2:$A$577,0),0)) -> 0.068635 | U8: =IF(T8="",S8,AVERAGE(S8,T8)) -> 0.068635 | V8: =IF(H8>=0,0,-H8/U8) -> 0
B9: =ROW()-4 -> 5 | C9: Wichita, KS | D9: =SUMIFS('Realpage Data'!$R$2:$R$899,'Realpage Data'!$A$2:$A$899,$C9,'Realpage Data'!$F$2:$F$899,"Rent Roll (Rev/OSF)") -> 1.0723395 | E9: =SUMIFS('Realpage Data'!$R$2:$R$899,'Realpage Data'!$A$2:$A$899,$C9,'Realpage Data'!$F$2:$F$899,"Asking RPSF") -> 1.176 | F9: =SUMIFS('Realpage Data'!$R$2:$R$899,'Realpage Data'!$A$2:$A$899,$C9,'Realpage Data'!$F$2:$F$899,"Effective RPSF") -> 1.173 | G9: =E9/$D9-1 -> 0.096667613 | H9: =F9/$D9-1 -> 0.093869991 | I9: =SUMIFS('RP - Unit Starts'!$AC$2:$AC$451,'RP - Unit Starts'!$A$2:$A$451,$C9,'RP - Unit Starts'!$F$2:$F$451,"Annual Unit Starts")/SUMIFS('RP - Unit Starts'!$AC$2:$AC$451,'RP - Unit Starts'!$A$2:$A$451,$C9,'RP - Unit Starts'!$F$2:$F$451,"Existing Units") -> 0.0038874164 | J9: =SUMIFS('Realpage Data'!$V$2:$V$899,'Realpage Data'!$A$2:$A$899,$C9,'Realpage Data'!$F$2:$F$899,"Existing Units")/SUMIFS('Realpage Data'!$R$2:$R$899,'Realpage Data'!$A$2:$A$899,$C9,'Realpage Data'!$F$2:$F$899,"Existing Units")-1 -> 0.0081534772 | K9: =INDEX('Fcst Walk'!$J$5:$J$69,MATCH($C9,'Fcst Walk'!$A$5:$A$69,0))/INDEX('Fcst Walk'!$F$5:$F$69,MATCH($C9,'Fcst Walk'!$A$5:$A$69,0))-1 -> 0.025 | L9: =INDEX('Fcst Walk'!$N$5:$N$69,MATCH($C9,'Fcst Walk'!$A$5:$A$69,0))/INDEX('Fcst Walk'!$J$5:$J$69,MATCH($C9,'Fcst Walk'!$A$5:$A$69,0))-1 -> 0.026 | M9: =INDEX('Fcst Walk'!$R$5:$R$69,MATCH($C9,'Fcst Walk'!$A$5:$A$69,0))/INDEX('Fcst Walk'!$N$5:$N$69,MATCH($C9,'Fcst Walk'!$A$5:$A$69,0))-1 -> 0.026 | N9: =INDEX('Fcst Walk'!$J$5:$J$69,MATCH($C9,'Fcst Walk'!$A$5:$A$69,0))/$D9-1 -> 0.12121674 | O9: =INDEX('Fcst Walk'!$N$5:$N$69,MATCH($C9,'Fcst Walk'!$A$5:$A$69,0))/$D9-1 -> 0.15036838 | P9: =INDEX('Fcst Walk'!$R$5:$R$69,MATCH($C9,'Fcst Walk'!$A$5:$A$69,0))/$D9-1 -> 0.18027795 | Q9: =INDEX('Fcst Walk'!$AM$5:$AM$69,MATCH($C9,'Fcst Walk'!$A$5:$A$69,0)) -> 0 | R9: =INDEX('Fcst Walk'!$AN$5:$AN$69,MATCH($C9,'Fcst Walk'!$A$5:$A$69,0)) | S9: =AVERAGE(INDEX('Realpage - His. Rent Change'!$I$2:$AV$577,MATCH($C9,'Realpage - His. Rent Change'!$A$2:$A$577,0),0)) -> 0.0425925 | U9: =IF(T9="",S9,AVERAGE(S9,T9)) -> 0.0425925 | V9: =IF(H9>=0,0,-H9/U9) -> 0
B10: =ROW()-4 -> 6 | C10: Salt Lake City/Ogden/Brigham City, UT-ID | D10: =SUMIFS('Realpage Data'!$R$2:$R$899,'Realpage Data'!$A$2:$A$899,$C10,'Realpage Data'!$F$2:$F$899,"Rent Roll (Rev/OSF)") -> 1.5782176 | E10: =SUMIFS('Realpage Data'!$R$2:$R$899,'Realpage Data'!$A$2:$A$899,$C10,'Realpage Data'!$F$2:$F$899,"Asking RPSF") -> 1.744 | F10: =SUMIFS('Realpage Data'!$R$2:$R$899,'Realpage Data'!$A$2:$A$899,$C10,'Realpage Data'!$F$2:$F$899,"Effective RPSF") -> 1.695 | G10: =E10/$D10-1 -> 0.10504407 | H10: =F10/$D10-1 -> 0.073996388 | I10: =SUMIFS('RP - Unit Starts'!$AC$2:$AC$451,'RP - Unit Starts'!$A$2:$A$451,$C10,'RP - Unit Starts'!$F$2:$F$451,"Annual Unit Starts")/SUMIFS('RP - Unit Starts'!$AC$2:$AC$451,'RP - Unit Starts'!$A$2:$A$451,$C10,'RP - Unit Starts'!$F$2:$F$451,"Existing Units") -> 0.011486296 | J10: =SUMIFS('Realpage Data'!$V$2:$V$899,'Realpage Data'!$A$2:$A$899,$C10,'Realpage Data'!$F$2:$F$899,"Existing Units")/SUMIFS('Realpage Data'!$R$2:$R$899,'Realpage Data'!$A$2:$A$899,$C10,'Realpage Data'!$F$2:$F$899,"Existing Units")-1 -> 0.027027409 | K10: =INDEX('Fcst Walk'!$J$5:$J$69,MATCH($C10,'Fcst Walk'!$A$5:$A$69,0))/INDEX('Fcst Walk'!$F$5:$F$69,MATCH($C10,'Fcst Walk'!$A$5:$A$69,0))-1 -> 0.021 | L10: =INDEX('Fcst Walk'!$N$5:$N$69,MATCH($C10,'Fcst Walk'!$A$5:$A$69,0))/INDEX('Fcst Walk'!$J$5:$J$69,MATCH($C10,'Fcst Walk'!$A$5:$A$69,0))-1 -> 0.023 | M10: =INDEX('Fcst Walk'!$R$5:$R$69,MATCH($C10,'Fcst Walk'!$A$5:$A$69,0))/INDEX('Fcst Walk'!$N$5:$N$69,MATCH($C10,'Fcst Walk'!$A$5:$A$69,0))-1 -> 0.024 | N10: =INDEX('Fcst Walk'!$J$5:$J$69,MATCH($C10,'Fcst Walk'!$A$5:$A$69,0))/$D10-1 -> 0.096550312 | O10: =INDEX('Fcst Walk'!$N$5:$N$69,MATCH($C10,'Fcst Walk'!$A$5:$A$69,0))/$D10-1 -> 0.12177097 | P10: =INDEX('Fcst Walk'!$R$5:$R$69,MATCH($C10,'Fcst Walk'!$A$5:$A$69,0))/$D10-1 -> 0.14869347 | Q10: =INDEX('Fcst Walk'!$AM$5:$AM$69,MATCH($C10,'Fcst Walk'!$A$5:$A$69,0)) -> 0 | R10: =INDEX('Fcst Walk'!$AN$5:$AN$69,MATCH($C10,'Fcst Walk'!$A$5:$A$69,0)) | S10: =AVERAGE(INDEX('Realpage - His. Rent Change'!$I$2:$AV$577,MATCH($C10,'Realpage - His. Rent Change'!$A$2:$A$577,0),0)) -> 0.05343 | T10: 0.0423 | U10: =IF(T10="",S10,AVERAGE(S10,T10)) -> 0.047865 | V10: =IF(H10>=0,0,-H10/U10) -> 0
B11: =ROW()-4 -> 7 | C11: Port St. Lucie/Sebastian-Vero Beach, FL | D11: =SUMIFS('Realpage Data'!$R$2:$R$899,'Realpage Data'!$A$2:$A$899,$C11,'Realpage Data'!$F$2:$F$899,"Rent Roll (Rev/OSF)") -> 1.763379 | E11: =SUMIFS('Realpage Data'!$R$2:$R$899,'Realpage Data'!$A$2:$A$899,$C11,'Realpage Data'!$F$2:$F$899,"Asking RPSF") -> 1.923 | F11: =SUMIFS('Realpage Data'!$R$2:$R$899,'Realpage Data'!$A$2:$A$899,$C11,'Realpage Data'!$F$2:$F$899,"Effective RPSF") -> 1.877 | G11: =E11/$D11-1 -> 0.090519951 | H11: =F11/$D11-1 -> 0.06443367 | I11: =SUMIFS('RP - Unit Starts'!$AC$2:$AC$451,'RP - Unit Starts'!$A$2:$A$451,$C11,'RP - Unit Starts'!$F$2:$F$451,"Annual Unit Starts")/SUMIFS('RP - Unit Starts'!$AC$2:$AC$451,'RP - Unit Starts'!$A$2:$A$451,$C11,'RP - Unit Starts'!$F$2:$F$451,"Existing Units") -> 0.0091623434 | J11: =SUMIFS('Realpage Data'!$V$2:$V$899,'Realpage Data'!$A$2:$A$899,$C11,'Realpage Data'!$F$2:$F$899,"Existing Units")/SUMIFS('Realpage Data'!$R$2:$R$899,'Realpage Data'!$A$2:$A$899,$C11,'Realpage Data'!$F$2:$F$899,"Existing Units")-1 -> 0.011862504 | K11: =INDEX('Fcst Walk'!$J$5:$J$69,MATCH($C11,'Fcst Walk'!$A$5:$A$69,0))/INDEX('Fcst Walk'!$F$5:$F$69,MATCH($C11,'Fcst Walk'!$A$5:$A$69,0))-1 -> 0.02 | L11: =INDEX('Fcst Walk'!$N$5:$N$69,MATCH($C11,'Fcst Walk'!$A$5:$A$69,0))/INDEX('Fcst Walk'!$J$5:$J$69,MATCH($C11,'Fcst Walk'!$A$5:$A$69,0))-1 -> 0.039 | M11: =INDEX('Fcst Walk'!$R$5:$R$69,MATCH($C11,'Fcst Walk'!$A$5:$A$69,0))/INDEX('Fcst Walk'!$N$5:$N$69,MATCH($C11,'Fcst Walk'!$A$5:$A$69,0))-1 -> 0.042 | N11: =INDEX('Fcst Walk'!$J$5:$J$69,MATCH($C11,'Fcst Walk'!$A$5:$A$69,0))/$D11-1 -> 0.085722343 | O11: =INDEX('Fcst Walk'!$N$5:$N$69,MATCH($C11,'Fcst Walk'!$A$5:$A$69,0))/$D11-1 -> 0.12806551 | P11: =INDEX('Fcst Walk'!$R$5:$R$69,MATCH($C11,'Fcst Walk'!$A$5:$A$69,0))/$D11-1 -> 0.17544427 | Q11: =INDEX('Fcst Walk'!$AM$5:$AM$69,MATCH($C11,'Fcst Walk'!$A$5:$A$69,0)) -> 0 | R11: =INDEX('Fcst Walk'!$AN$5:$AN$69,MATCH($C11,'Fcst Walk'!$A$5:$A$69,0)) | S11: =AVERAGE(INDEX('Realpage - His. Rent Change'!$I$2:$AV$577,MATCH($C11,'Realpage - His. Rent Change'!$A$2:$A$577,0),0)) -> 0.07217 | U11: =IF(T11="",S11,AVERAGE(S11,T11)) -> 0.07217 | V11: =IF(H11>=0,0,-H11/U11) -> 0
B12: =ROW()-4 -> 8 | C12: Columbus, OH | D12: =SUMIFS('Realpage Data'!$R$2:$R$899,'Realpage Data'!$A$2:$A$899,$C12,'Realpage Data'!$F$2:$F$899,"Rent Roll (Rev/OSF)") -> 1.4232332 | E12: =SUMIFS('Realpage Data'!$R$2:$R$899,'Realpage Data'!$A$2:$A$899,$C12,'Realpage Data'!$F$2:$F$899,"Asking RPSF") -> 1.511 | F12: =SUMIFS('Realpage Data'!$R$2:$R$899,'Realpage Data'!$A$2:$A$899,$C12,'Realpage Data'!$F$2:$F$899,"Effective RPSF") -> 1.494 | G12: =E12/$D12-1 -> 0.061667189 | H12: =F12/$D12-1 -> 0.049722555 | I12: =SUMIFS('RP - Unit Starts'!$AC$2:$AC$451,'RP - Unit Starts'!$A$2:$A$451,$C12,'RP - Unit Starts'!$F$2:$F$451,"Annual Unit Starts")/SUMIFS('RP - Unit Starts'!$AC$2:$AC$451,'RP - Unit Starts'!$A$2:$A$451,$C12,'RP - Unit Starts'!$F$2:$F$451,"Existing Units") -> 0.018135846 | J12: =SUMIFS('Realpage Data'!$V$2:$V$899,'Realpage Data'!$A$2:$A$899,$C12,'Realpage Data'!$F$2:$F$899,"Existing Units")/SUMIFS('Realpage Data'!$R$2:$R$899,'Realpage Data'!$A$2:$A$899,$C12,'Realpage Data'!$F$2:$F$899,"Existing Units")-1 -> 0.02854986 | K12: =INDEX('Fcst Walk'!$J$5:$J$69,MATCH($C12,'Fcst Walk'!$A$5:$A$69,0))/INDEX('Fcst Walk'!$F$5:$F$69,MATCH($C12,'Fcst Walk'!$A$5:$A$69,0))-1 -> 0.021 | L12: =INDEX('Fcst Walk'!$N$5:$N$69,MATCH($C12,'Fcst Walk'!$A$5:$A$69,0))/INDEX('Fcst Walk'!$J$5:$J$69,MATCH($C12,'Fcst Walk'!$A$5:$A$69,0))-1 -> 0.031 | M12: =INDEX('Fcst Walk'!$R$5:$R$69,MATCH($C12,'Fcst Walk'!$A$5:$A$69,0))/INDEX('Fcst Walk'!$N$5:$N$69,MATCH($C12,'Fcst Walk'!$A$5:$A$69,0))-1 -> 0.031 | N12: =INDEX('Fcst Walk'!$J$5:$J$69,MATCH($C12,'Fcst Walk'!$A$5:$A$69,0))/$D12-1 -> 0.071766729 | O12: =INDEX('Fcst Walk'!$N$5:$N$69,MATCH($C12,'Fcst Walk'!$A$5:$A$69,0))/$D12-1 -> 0.1049915 | P12: =INDEX('Fcst Walk'!$R$5:$R$69,MATCH($C12,'Fcst Walk'!$A$5:$A$69,0))/$D12-1 -> 0.13924623 | Q12: =INDEX('Fcst Walk'!$AM$5:$AM$69,MATCH($C12,'Fcst Walk'!$A$5:$A$69,0)) -> 0 | R12: =INDEX('Fcst Walk'!$AN$5:$AN$69,MATCH($C12,'Fcst Walk'!$A$5:$A$69,0)) | S12: =AVERAGE(INDEX('Realpage - His. Rent Change'!$I$2:$AV$577,MATCH($C12,'Realpage - His. Rent Change'!$A$2:$A$577,0),0)) -> 0.057095 | T12: 0.044 | U12: =IF(T12="",S12,AVERAGE(S12,T12)) -> 0.0505475 | V12: =IF(H12>=0,0,-H12/U12) -> 0
B13: =ROW()-4 -> 9 | C13: Boise City, ID | D13: =SUMIFS('Realpage Data'!$R$2:$R$899,'Realpage Data'!$A$2:$A$899,$C13,'Realpage Data'!$F$2:$F$899,"Rent Roll (Rev/OSF)") -> 1.7432193 | E13: =SUMIFS('Realpage Data'!$R$2:$R$899,'Realpage Data'!$A$2:$A$899,$C13,'Realpage Data'!$F$2:$F$899,"Asking RPSF") -> 1.838 | F13: =SUMIFS('Realpage Data'!$R$2:$R$899,'Realpage Data'!$A$2:$A$899,$C13,'Realpage Data'!$F$2:$F$899,"Effective RPSF") -> 1.824 | G13: =E13/$D13-1 -> 0.054371047 | H13: =F13/$D13-1 -> 0.046339929 | I13: =SUMIFS('RP - Unit Starts'!$AC$2:$AC$451,'RP - Unit Starts'!$A$2:$A$451,$C13,'RP - Unit Starts'!$F$2:$F$451,"Annual Unit Starts")/SUMIFS('RP - Unit Starts'!$AC$2:$AC$451,'RP - Unit Starts'!$A$2:$A$451,$C13,'RP - Unit Starts'!$F$2:$F$451,"Existing Units") -> 0.011981268 | J13: =SUMIFS('Realpage Data'!$V$2:$V$899,'Realpage Data'!$A$2:$A$899,$C13,'Realpage Data'!$F$2:$F$899,"Existing Units")/SUMIFS('Realpage Data'!$R$2:$R$899,'Realpage Data'!$A$2:$A$899,$C13,'Realpage Data'!$F$2:$F$899,"Existing Units")-1 -> 0.014347631 | K13: =INDEX('Fcst Walk'!$J$5:$J$69,MATCH($C13,'Fcst Walk'!$A$5:$A$69,0))/INDEX('Fcst Walk'!$F$5:$F$69,MATCH($C13,'Fcst Walk'!$A$5:$A$69,0))-1 -> 0.055 | L13: =INDEX('Fcst Walk'!$N$5:$N$69,MATCH($C13,'Fcst Walk'!$A$5:$A$69,0))/INDEX('Fcst Walk'!$J$5:$J$69,MATCH($C13,'Fcst Walk'!$A$5:$A$69,0))-1 -> 0.044 | M13: =INDEX('Fcst Walk'!$R$5:$R$69,MATCH($C13,'Fcst Walk'!$A$5:$A$69,0))/INDEX('Fcst Walk'!$N$5:$N$69,MATCH($C13,'Fcst Walk'!$A$5:$A$69,0))-1 -> 0.044 | N13: =INDEX('Fcst Walk'!$J$5:$J$69,MATCH($C13,'Fcst Walk'!$A$5:$A$69,0))/$D13-1 -> 0.10388863 | O13: =INDEX('Fcst Walk'!$N$5:$N$69,MATCH($C13,'Fcst Walk'!$A$5:$A$69,0))/$D13-1 -> 0.15245972 | P13: =INDEX('Fcst Walk'!$R$5:$R$69,MATCH($C13,'Fcst Walk'!$A$5:$A$69,0))/$D13-1 -> 0.20316795 | Q13: =INDEX('Fcst Walk'!$AM$5:$AM$69,MATCH($C13,'Fcst Walk'!$A$5:$A$69,0)) -> 0 | R13: =INDEX('Fcst Walk'!$AN$5:$AN$69,MATCH($C13,'Fcst Walk'!$A$5:$A$69,0)) | S13: =AVERAGE(INDEX('Realpage - His. Rent Change'!$I$2:$AV$577,MATCH($C13,'Realpage - His. Rent Change'!$A$2:$A$577,0),0)) -> 0.0689675 | U13: =IF(T13="",S13,AVERAGE(S13,T13)) -> 0.0689675 | V13: =IF(H13>=0,0,-H13/U13) -> 0
B14: =ROW()-4 -> 10 | C14: Richmond, VA | D14: =SUMIFS('Realpage Data'!$R$2:$R$899,'Realpage Data'!$A$2:$A$899,$C14,'Realpage Data'!$F$2:$F$899,"Rent Roll (Rev/OSF)") -> 1.7161987 | E14: =SUMIFS('Realpage Data'!$R$2:$R$899,'Realpage Data'!$A$2:$A$899,$C14,'Realpage Data'!$F$2:$F$899,"Asking RPSF") -> 1.812 | F14: =SUMIFS('Realpage Data'!$R$2:$R$899,'Realpage Data'!$A$2:$A$899,$C14,'Realpage Data'!$F$2:$F$899,"Effective RPSF") -> 1.793 | G14: =E14/$D14-1 -> 0.055821774 | H14: =F14/$D14-1 -> 0.044750795 | I14: =SUMIFS('RP - Unit Starts'!$AC$2:$AC$451,'RP - Unit Starts'!$A$2:$A$451,$C14,'RP - Unit Starts'!$F$2:$F$451,"Annual Unit Starts")/SUMIFS('RP - Unit Starts'!$AC$2:$AC$451,'RP - Unit Starts'!$A$2:$A$451,$C14,'RP - Unit Starts'!$F$2:$F$451,"Existing Units") -> 0.013758423 | J14: =SUMIFS('Realpage Data'!$V$2:$V$899,'Realpage Data'!$A$2:$A$899,$C14,'Realpage Data'!$F$2:$F$899,"Existing Units")/SUMIFS('Realpage Data'!$R$2:$R$899,'Realpage Data'!$A$2:$A$899,$C14,'Realpage Data'!$F$2:$F$899,"Existing Units")-1 -> 0.030935706 | K14: =INDEX('Fcst Walk'!$J$5:$J$69,MATCH($C14,'Fcst Walk'!$A$5:$A$69,0))/INDEX('Fcst Walk'!$F$5:$F$69,MATCH($C14,'Fcst Walk'!$A$5:$A$69,0))-1 -> 0.021 | L14: =INDEX('Fcst Walk'!$N$5:$N$69,MATCH($C14,'Fcst Walk'!$A$5:$A$69,0))/INDEX('Fcst Walk'!$J$5:$J$69,MATCH($C14,'Fcst Walk'!$A$5:$A$69,0))-1 -> 0.036 | M14: =INDEX('Fcst Walk'!$R$5:$R$69,MATCH($C14,'Fcst Walk'!$A$5:$A$69,0))/INDEX('Fcst Walk'!$N$5:$N$69,MATCH($C14,'Fcst Walk'!$A$5:$A$69,0))-1 -> 0.033 | N14: =INDEX('Fcst Walk'!$J$5:$J$69,MATCH($C14,'Fcst Walk'!$A$5:$A$69,0))/$D14-1 -> 0.066690562 | O14: =INDEX('Fcst Walk'!$N$5:$N$69,MATCH($C14,'Fcst Walk'!$A$5:$A$69,0))/$D14-1 -> 0.10509142 | P14: =INDEX('Fcst Walk'!$R$5:$R$69,MATCH($C14,'Fcst Walk'!$A$5:$A$69,0))/$D14-1 -> 0.14155944 | Q14: =INDEX('Fcst Walk'!$AM$5:$AM$69,MATCH($C14,'Fcst Walk'!$A$5:$A$69,0)) -> 0 | R14: =INDEX('Fcst Walk'!$AN$5:$AN$69,MATCH($C14,'Fcst Walk'!$A$5:$A$69,0)) | S14: =AVERAGE(INDEX('Realpage - His. Rent Change'!$I$2:$AV$577,MATCH($C14,'Realpage - His. Rent Change'!$A$2:$A$577,0),0)) -> 0.0551825 | T14: 0.0451 | U14: =IF(T14="",S14,AVERAGE(S14,T14)) -> 0.05014125 | V14: =IF(H14>=0,0,-H14/U14) -> 0
B15: =ROW()-4 -> 11 | C15: Virginia Beach-Chesapeake-Norfolk, VA-NC | D15: =SUMIFS('Realpage Data'!$R$2:$R$899,'Realpage Data'!$A$2:$A$899,$C15,'Realpage Data'!$F$2:$F$899,"Rent Roll (Rev/OSF)") -> 1.6742534 | E15: =SUMIFS('Realpage Data'!$R$2:$R$899,'Realpage Data'!$A$2:$A$899,$C15,'Realpage Data'!$F$2:$F$899,"Asking RPSF") -> 1.752 | F15: =SUMIFS('Realpage Data'!$R$2:$R$899,'Realpage Data'!$A$2:$A$899,$C15,'Realpage Data'!$F$2:$F$899,"Effective RPSF") -> 1.746 | G15: =E15/$D15-1 -> 0.046436552 | H15: =F15/$D15-1 -> 0.042852865 | I15: =SUMIFS('RP - Unit Starts'!$AC$2:$AC$451,'RP - Unit Starts'!$A$2:$A$451,$C15,'RP - Unit Starts'!$F$2:$F$451,"Annual Unit Starts")/SUMIFS('RP - Unit Starts'!$AC$2:$AC$451,'RP - Unit Starts'!$A$2:$A$451,$C15,'RP - Unit Starts'!$F$2:$F$451,"Existing Units") -> 0.0039863635 | J15: =SUMIFS('Realpage Data'!$V$2:$V$899,'Realpage Data'!$A$2:$A$899,$C15,'Realpage Data'!$F$2:$F$899,"Existing Units")/SUMIFS('Realpage Data'!$R$2:$R$899,'Realpage Data'!$A$2:$A$899,$C15,'Realpage Data'!$F$2:$F$899,"Existing Units")-1 -> 0.0026892674 | K15: =INDEX('Fcst Walk'!$J$5:$J$69,MATCH($C15,'Fcst Walk'!$A$5:$A$69,0))/INDEX('Fcst Walk'!$F$5:$F$69,MATCH($C15,'Fcst Walk'!$A$5:$A$69,0))-1 -> 0.023 | L15: =INDEX('Fcst Walk'!$N$5:$N$69,MATCH($C15,'Fcst Walk'!$A$5:$A$69,0))/INDEX('Fcst Walk'!$J$5:$J$69,MATCH($C15,'Fcst Walk'!$A$5:$A$69,0))-1 -> 0.021 | M15: =INDEX('Fcst Walk'!$R$5:$R$69,MATCH($C15,'Fcst Walk'!$A$5:$A$69,0))/INDEX('Fcst Walk'!$N$5:$N$69,MATCH($C15,'Fcst Walk'!$A$5:$A$69,0))-1 -> 0.019 | N15: =INDEX('Fcst Walk'!$J$5:$J$69,MATCH($C15,'Fcst Walk'!$A$5:$A$69,0))/$D15-1 -> 0.066838481 | O15: =INDEX('Fcst Walk'!$N$5:$N$69,MATCH($C15,'Fcst Walk'!$A$5:$A$69,0))/$D15-1 -> 0.089242089 | P15: =INDEX('Fcst Walk'!$R$5:$R$69,MATCH($C15,'Fcst Walk'!$A$5:$A$69,0))/$D15-1 -> 0.10993769 | Q15: =INDEX('Fcst Walk'!$AM$5:$AM$69,MATCH($C15,'Fcst Walk'!$A$5:$A$69,0)) -> 0 | R15: =INDEX('Fcst Walk'!$AN$5:$AN$69,MATCH($C15,'Fcst Walk'!$A$5:$A$69,0)) | S15: =AVERAGE(INDEX('Realpage - His. Rent Change'!$I$2:$AV$577,MATCH($C15,'Realpage - His. Rent Change'!$A$2:$A$577,0),0)) -> 0.04796 | U15: =IF(T15="",S15,AVERAGE(S15,T15)) -> 0.04796 | V15: =IF(H15>=0,0,-H15/U15) -> 0
B16: =ROW()-4 -> 12 | C16: Miami-Miami Beach-Kendall, FL | D16: =SUMIFS('Realpage Data'!$R$2:$R$899,'Realpage Data'!$A$2:$A$899,$C16,'Realpage Data'!$F$2:$F$899,"Rent Roll (Rev/OSF)") -> 2.8346507 | E16: =SUMIFS('Realpage Data'!$R$2:$R$899,'Realpage Data'!$A$2:$A$899,$C16,'Realpage Data'!$F$2:$F$899,"Asking RPSF") -> 3.003 | F16: =SUMIFS('Realpage Data'!$R$2:$R$899,'Realpage Data'!$A$2:$A$899,$C16,'Realpage Data'!$F$2:$F$899,"Effective RPSF") -> 2.946 | G16: =E16/$D16-1 -> 0.059389778 | H16: =F16/$D16-1 -> 0.03928148 | I16: =SUMIFS('RP - Unit Starts'!$AC$2:$AC$451,'RP - Unit Starts'!$A$2:$A$451,$C16,'RP - Unit Starts'!$F$2:$F$451,"Annual Unit Starts")/SUMIFS('RP - Unit Starts'!$AC$2:$AC$451,'RP - Unit Starts'!$A$2:$A$451,$C16,'RP - Unit Starts'!$F$2:$F$451,"Existing Units") -> 0.024001428 | J16: =SUMIFS('Realpage Data'!$V$2:$V$899,'Realpage Data'!$A$2:$A$899,$C16,'Realpage Data'!$F$2:$F$899,"Existing Units")/SUMIFS('Realpage Data'!$R$2:$R$899,'Realpage Data'!$A$2:$A$899,$C16,'Realpage Data'!$F$2:$F$899,"Existing Units")-1 -> 0.019251805 | K16: =INDEX('Fcst Walk'!$J$5:$J$69,MATCH($C16,'Fcst Walk'!$A$5:$A$69,0))/INDEX('Fcst Walk'!$F$5:$F$69,MATCH($C16,'Fcst Walk'!$A$5:$A$69,0))-1 -> 0.034 | L16: =INDEX('Fcst Walk'!$N$5:$N$69,MATCH($C16,'Fcst Walk'!$A$5:$A$69,0))/INDEX('Fcst Walk'!$J$5:$J$69,MATCH($C16,'Fcst Walk'!$A$5:$A$69,0))-1 -> 0.032 | M16: =INDEX('Fcst Walk'!$R$5:$R$69,MATCH($C16,'Fcst Walk'!$A$5:$A$69,0))/INDEX('Fcst Walk'!$N$5:$N$69,MATCH($C16,'Fcst Walk'!$A$5:$A$69,0))-1 -> 0.038 | N16: =INDEX('Fcst Walk'!$J$5:$J$69,MATCH($C16,'Fcst Walk'!$A$5:$A$69,0))/$D16-1 -> 0.074617051 | O16: =INDEX('Fcst Walk'!$N$5:$N$69,MATCH($C16,'Fcst Walk'!$A$5:$A$69,0))/$D16-1 -> 0.1090048 | P16: =INDEX('Fcst Walk'!$R$5:$R$69,MATCH($C16,'Fcst Walk'!$A$5:$A$69,0))/$D16-1 -> 0.15114698 | Q16: =INDEX('Fcst Walk'!$AM$5:$AM$69,MATCH($C16,'Fcst Walk'!$A$5:$A$69,0)) -> 0 | R16: =INDEX('Fcst Walk'!$AN$5:$AN$69,MATCH($C16,'Fcst Walk'!$A$5:$A$69,0)) | S16: =AVERAGE(INDEX('Realpage - His. Rent Change'!$I$2:$AV$577,MATCH($C16,'Realpage - His. Rent Change'!$A$2:$A$577,0),0)) -> 0.060015 | U16: =IF(T16="",S16,AVERAGE(S16,T16)) -> 0.060015 | V16: =IF(H16>=0,0,-H16/U16) -> 0
B17: =ROW()-4 -> 13 | C17: Omaha, NE-IA | D17: =SUMIFS('Realpage Data'!$R$2:$R$899,'Realpage Data'!$A$2:$A$899,$C17,'Realpage Data'!$F$2:$F$899,"Rent Roll (Rev/OSF)") -> 1.3838771 | E17: =SUMIFS('Realpage Data'!$R$2:$R$899,'Realpage Data'!$A$2:$A$899,$C17,'Realpage Data'!$F$2:$F$899,"Asking RPSF") -> 1.445 | F17: =SUMIFS('Realpage Data'!$R$2:$R$899,'Realpage Data'!$A$2:$A$899,$C17,'Realpage Data'!$F$2:$F$899,"Effective RPSF") -> 1.431 | G17: =E17/$D17-1 -> 0.04416784 | H17: =F17/$D17-1 -> 0.034051335 | I17: =SUMIFS('RP - Unit Starts'!$AC$2:$AC$451,'RP - Unit Starts'!$A$2:$A$451,$C17,'RP - Unit Starts'!$F$2:$F$451,"Annual Unit Starts")/SUMIFS('RP - Unit Starts'!$AC$2:$AC$451,'RP - Unit Starts'!$A$2:$A$451,$C17,'RP - Unit Starts'!$F$2:$F$451,"Existing Units") -> 0.03111465 | J17: =SUMIFS('Realpage Data'!$V$2:$V$899,'Realpage Data'!$A$2:$A$899,$C17,'Realpage Data'!$F$2:$F$899,"Existing Units")/SUMIFS('Realpage Data'!$R$2:$R$899,'Realpage Data'!$A$2:$A$899,$C17,'Realpage Data'!$F$2:$F$899,"Existing Units")-1 -> 0.035063694 | K17: =INDEX('Fcst Walk'!$J$5:$J$69,MATCH($C17,'Fcst Walk'!$A$5:$A$69,0))/INDEX('Fcst Walk'!$F$5:$F$69,MATCH($C17,'Fcst Walk'!$A$5:$A$69,0))-1 -> 0.028 | L17: =INDEX('Fcst Walk'!$N$5:$N$69,MATCH($C17,'Fcst Walk'!$A$5:$A$69,0))/INDEX('Fcst Walk'!$J$5:$J$69,MATCH($C17,'Fcst Walk'!$A$5:$A$69,0))-1 -> 0.029 | M17: =INDEX('Fcst Walk'!$R$5:$R$69,MATCH($C17,'Fcst Walk'!$A$5:$A$69,0))/INDEX('Fcst Walk'!$N$5:$N$69,MATCH($C17,'Fcst Walk'!$A$5:$A$69,0))-1 -> 0.03 | N17: =INDEX('Fcst Walk'!$J$5:$J$69,MATCH($C17,'Fcst Walk'!$A$5:$A$69,0))/$D17-1 -> 0.063004772 | O17: =INDEX('Fcst Walk'!$N$5:$N$69,MATCH($C17,'Fcst Walk'!$A$5:$A$69,0))/$D17-1 -> 0.093831911 | P17: =INDEX('Fcst Walk'!$R$5:$R$69,MATCH($C17,'Fcst Walk'!$A$5:$A$69,0))/$D17-1 -> 0.12664687 | Q17: =INDEX('Fcst Walk'!$AM$5:$AM$69,MATCH($C17,'Fcst Walk'!$A$5:$A$69,0)) -> 0 | R17: =INDEX('Fcst Walk'!$AN$5:$AN$69,MATCH($C17,'Fcst Walk'!$A$5:$A$69,0)) | S17: =AVERAGE(INDEX('Realpage - His. Rent Change'!$I$2:$AV$577,MATCH($C17,'Realpage - His. Rent Change'!$A$2:$A$577,0),0)) -> 0.04881 | U17: =IF(T17="",S17,AVERAGE(S17,T17)) -> 0.04881 | V17: =IF(H17>=0,0,-H17/U17) -> 0
B18: =ROW()-4 -> 14 | C18: Wilmington, NC | D18: =SUMIFS('Realpage Data'!$R$2:$R$899,'Realpage Data'!$A$2:$A$899,$C18,'Realpage Data'!$F$2:$F$899,"Rent Roll (Rev/OSF)") -> 1.5148793 | E18: =SUMIFS('Realpage Data'!$R$2:$R$899,'Realpage Data'!$A$2:$A$899,$C18,'Realpage Data'!$F$2:$F$899,"Asking RPSF") -> 1.596 | F18: =SUMIFS('Realpage Data'!$R$2:$R$899,'Realpage Data'!$A$2:$A$899,$C18,'Realpage Data'!$F$2:$F$899,"Effective RPSF") -> 1.559 | G18: =E18/$D18-1 -> 0.053549305 | H18: =F18/$D18-1 -> 0.029124916 | I18: =SUMIFS('RP - Unit Starts'!$AC$2:$AC$451,'RP - Unit Starts'!$A$2:$A$451,$C18,'RP - Unit Starts'!$F$2:$F$451,"Annual Unit Starts")/SUMIFS('RP - Unit Starts'!$AC$2:$AC$451,'RP - Unit Starts'!$A$2:$A$451,$C18,'RP - Unit Starts'!$F$2:$F$451,"Existing Units") -> 0.018594007 | J18: =SUMIFS('Realpage Data'!$V$2:$V$899,'Realpage Data'!$A$2:$A$899,$C18,'Realpage Data'!$F$2:$F$899,"Existing Units")/SUMIFS('Realpage Data'!$R$2:$R$899,'Realpage Data'!$A$2:$A$899,$C18,'Realpage Data'!$F$2:$F$899,"Existing Units")-1 -> 0.054304036 | K18: =INDEX('Fcst Walk'!$J$5:$J$69,MATCH($C18,'Fcst Walk'!$A$5:$A$69,0))/INDEX('Fcst Walk'!$F$5:$F$69,MATCH($C18,'Fcst Walk'!$A$5:$A$69,0))-1 -> 0.021 | L18: =INDEX('Fcst Walk'!$N$5:$N$69,MATCH($C18,'Fcst Walk'!$A$5:$A$69,0))/INDEX('Fcst Walk'!$J$5:$J$69,MATCH($C18,'Fcst Walk'!$A$5:$A$69,0))-1 -> 0.028 | M18: =INDEX('Fcst Walk'!$R$5:$R$69,MATCH($C18,'Fcst Walk'!$A$5:$A$69,0))/INDEX('Fcst Walk'!$N$5:$N$69,MATCH($C18,'Fcst Walk'!$A$5:$A$69,0))-1 -> 0.031 | N18: =INDEX('Fcst Walk'!$J$5:$J$69,MATCH($C18,'Fcst Walk'!$A$5:$A$69,0))/$D18-1 -> 0.050736539 | O18: =INDEX('Fcst Walk'!$N$5:$N$69,MATCH($C18,'Fcst Walk'!$A$5:$A$69,0))/$D18-1 -> 0.080157163 | P18: =INDEX('Fcst Walk'!$R$5:$R$69,MATCH($C18,'Fcst Walk'!$A$5:$A$69,0))/$D18-1 -> 0.11364203 | Q18: =INDEX('Fcst Walk'!$AM$5:$AM$69,MATCH($C18,'Fcst Walk'!$A$5:$A$69,0)) -> 0 | R18: =INDEX('Fcst Walk'!$AN$5:$AN$69,MATCH($C18,'Fcst Walk'!$A$5:$A$69,0)) | S18: =AVERAGE(INDEX('Realpage - His. Rent Change'!$I$2:$AV$577,MATCH($C18,'Realpage - His. Rent Change'!$A$2:$A$577,0),0)) -> 0.060755 | U18: =IF(T18="",S18,AVERAGE(S18,T18)) -> 0.060755 | V18: =IF(H18>=0,0,-H18/U18) -> 0
B19: =ROW()-4 -> 15 | C19: Fayetteville-Springdale-Rogers, AR | D19: =SUMIFS('Realpage Data'!$R$2:$R$899,'Realpage Data'!$A$2:$A$899,$C19,'Realpage Data'!$F$2:$F$899,"Rent Roll (Rev/OSF)") -> 1.3361114 | E19: =SUMIFS('Realpage Data'!$R$2:$R$899,'Realpage Data'!$A$2:$A$899,$C19,'Realpage Data'!$F$2:$F$899,"Asking RPSF") -> 1.392 | F19: =SUMIFS('Realpage Data'!$R$2:$R$899,'Realpage Data'!$A$2:$A$899,$C19,'Realpage Data'!$F$2:$F$899,"Effective RPSF") -> 1.372 | G19: =E19/$D19-1 -> 0.041829323 | H19: =F19/$D19-1 -> 0.026860511 | I19: =SUMIFS('RP - Unit Starts'!$AC$2:$AC$451,'RP - Unit Starts'!$A$2:$A$451,$C19,'RP - Unit Starts'!$F$2:$F$451,"Annual Unit Starts")/SUMIFS('RP - Unit Starts'!$AC$2:$AC$451,'RP - Unit Starts'!$A$2:$A$451,$C19,'RP - Unit Starts'!$F$2:$F$451,"Existing Units") -> 0.020668596 | J19: =SUMIFS('Realpage Data'!$V$2:$V$899,'Realpage Data'!$A$2:$A$899,$C19,'Realpage Data'!$F$2:$F$899,"Existing Units")/SUMIFS('Realpage Data'!$R$2:$R$899,'Realpage Data'!$A$2:$A$899,$C19,'Realpage Data'!$F$2:$F$899,"Existing Units")-1 -> 0.041747374 | K19: =INDEX('Fcst Walk'!$J$5:$J$69,MATCH($C19,'Fcst Walk'!$A$5:$A$69,0))/INDEX('Fcst Walk'!$F$5:$F$69,MATCH($C19,'Fcst Walk'!$A$5:$A$69,0))-1 -> 0 | L19: =INDEX('Fcst Walk'!$N$5:$N$69,MATCH($C19,'Fcst Walk'!$A$5:$A$69,0))/INDEX('Fcst Walk'!$J$5:$J$69,MATCH($C19,'Fcst Walk'!$A$5:$A$69,0))-1 -> 0.024 | M19: =INDEX('Fcst Walk'!$R$5:$R$69,MATCH($C19,'Fcst Walk'!$A$5:$A$69,0))/INDEX('Fcst Walk'!$N$5:$N$69,MATCH($C19,'Fcst Walk'!$A$5:$A$69,0))-1 -> 0.024 | N19: =INDEX('Fcst Walk'!$J$5:$J$69,MATCH($C19,'Fcst Walk'!$A$5:$A$69,0))/$D19-1 -> 0.026860511 | O19: =INDEX('Fcst Walk'!$N$5:$N$69,MATCH($C19,'Fcst Walk'!$A$5:$A$69,0))/$D19-1 -> 0.051505163 | P19: =INDEX('Fcst Walk'!$R$5:$R$69,MATCH($C19,'Fcst Walk'!$A$5:$A$69,0))/$D19-1 -> 0.076741287 | Q19: =INDEX('Fcst Walk'!$AM$5:$AM$69,MATCH($C19,'Fcst Walk'!$A$5:$A$69,0)) -> 0 | R19: =INDEX('Fcst Walk'!$AN$5:$AN$69,MATCH($C19,'Fcst Walk'!$A$5:$A$69,0)) | S19: =AVERAGE(INDEX('Realpage - His. Rent Change'!$I$2:$AV$577,MATCH($C19,'Realpage - His. Rent Change'!$A$2:$A$577,0),0)) -> 0.069365 | U19: =IF(T19="",S19,AVERAGE(S19,T19)) -> 0.069365 | V19: =IF(H19>=0,0,-H19/U19) -> 0
B20: =ROW()-4 -> 16 | C20: Savannah, GA | D20: =SUMIFS('Realpage Data'!$R$2:$R$899,'Realpage Data'!$A$2:$A$899,$C20,'Realpage Data'!$F$2:$F$899,"Rent Roll (Rev/OSF)") -> 1.4982507 | E20: =SUMIFS('Realpage Data'!$R$2:$R$899,'Realpage Data'!$A$2:$A$899,$C20,'Realpage Data'!$F$2:$F$899,"Asking RPSF") -> 1.593 | F20: =SUMIFS('Realpage Data'!$R$2:$R$899,'Realpage Data'!$A$2:$A$899,$C20,'Realpage Data'!$F$2:$F$899,"Effective RPSF") -> 1.538 | G20: =E20/$D20-1 -> 0.063239927 | H20: =F20/$D20-1 -> 0.02653045 | I20: =SUMIFS('RP - Unit Starts'!$AC$2:$AC$451,'RP - Unit Starts'!$A$2:$A$451,$C20,'RP - Unit Starts'!$F$2:$F$451,"Annual Unit Starts")/SUMIFS('RP - Unit Starts'!$AC$2:$AC$451,'RP - Unit Starts'!$A$2:$A$451,$C20,'RP - Unit Starts'!$F$2:$F$451,"Existing Units") -> 0.018218772 | J20: =SUMIFS('Realpage Data'!$V$2:$V$899,'Realpage Data'!$A$2:$A$899,$C20,'Realpage Data'!$F$2:$F$899,"Existing Units")/SUMIFS('Realpage Data'!$R$2:$R$899,'Realpage Data'!$A$2:$A$899,$C20,'Realpage Data'!$F$2:$F$899,"Existing Units")-1 -> 0.038176164 | K20: =INDEX('Fcst Walk'!$J$5:$J$69,MATCH($C20,'Fcst Walk'!$A$5:$A$69,0))/INDEX('Fcst Walk'!$F$5:$F$69,MATCH($C20,'Fcst Walk'!$A$5:$A$69,0))-1 -> 0.004 | L20: =INDEX('Fcst Walk'!$N$5:$N$69,MATCH($C20,'Fcst Walk'!$A$5:$A$69,0))/INDEX('Fcst Walk'!$J$5:$J$69,MATCH($C20,'Fcst Walk'!$A$5:$A$69,0))-1 -> 0.03 | M20: =INDEX('Fcst Walk'!$R$5:$R$69,MATCH($C20,'Fcst Walk'!$A$5:$A$69,0))/INDEX('Fcst Walk'!$N$5:$N$69,MATCH($C20,'Fcst Walk'!$A$5:$A$69,0))-1 -> 0.037 | N20: =INDEX('Fcst Walk'!$J$5:$J$69,MATCH($C20,'Fcst Walk'!$A$5:$A$69,0))/$D20-1 -> 0.030636572 | O20: =INDEX('Fcst Walk'!$N$5:$N$69,MATCH($C20,'Fcst Walk'!$A$5:$A$69,0))/$D20-1 -> 0.061555669 | P20: =INDEX('Fcst Walk'!$R$5:$R$69,MATCH($C20,'Fcst Walk'!$A$5:$A$69,0))/$D20-1 -> 0.10083323 | Q20: =INDEX('Fcst Walk'!$AM$5:$AM$69,MATCH($C20,'Fcst Walk'!$A$5:$A$69,0)) -> 0 | R20: =INDEX('Fcst Walk'!$AN$5:$AN$69,MATCH($C20,'Fcst Walk'!$A$5:$A$69,0)) | S20: =AVERAGE(INDEX('Realpage - His. Rent Change'!$I$2:$AV$577,MATCH($C20,'Realpage - His. Rent Change'!$A$2:$A$577,0),0)) -> 0.058045 | U20: =IF(T20="",S20,AVERAGE(S20,T20)) -> 0.058045 | V20: =IF(H20>=0,0,-H20/U20) -> 0
B21: =ROW()-4 -> 17 | C21: Cincinnati, OH-KY-IN | D21: =SUMIFS('Realpage Data'!$R$2:$R$899,'Realpage Data'!$A$2:$A$899,$C21,'Realpage Data'!$F$2:$F$899,"Rent Roll (Rev/OSF)") -> 1.578633 | E21: =SUMIFS('Realpage Data'!$R$2:$R$899,'Realpage Data'!$A$2:$A$899,$C21,'Realpage Data'!$F$2:$F$899,"Asking RPSF") -> 1.63 | F21: =SUMIFS('Realpage Data'!$R$2:$R$899,'Realpage Data'!$A$2:$A$899,$C21,'Realpage Data'!$F$2:$F$899,"Effective RPSF") -> 1.619 | G21: =E21/$D21-1 -> 0.032538929 | H21: =F21/$D21-1 -> 0.025570875 | I21: =SUMIFS('RP - Unit Starts'!$AC$2:$AC$451,'RP - Unit Starts'!$A$2:$A$451,$C21,'RP - Unit Starts'!$F$2:$F$451,"Annual Unit Starts")/SUMIFS('RP - Unit Starts'!$AC$2:$AC$451,'RP - Unit Starts'!$A$2:$A$451,$C21,'RP - Unit Starts'!$F$2:$F$451,"Existing Units") -> 0.014331659 | J21: =SUMIFS('Realpage Data'!$V$2:$V$899,'Realpage Data'!$A$2:$A$899,$C21,'Realpage Data'!$F$2:$F$899,"Existing Units")/SUMIFS('Realpage Data'!$R$2:$R$899,'Realpage Data'!$A$2:$A$899,$C21,'Realpage Data'!$F$2:$F$899,"Existing Units")-1 -> 0.014348919 | K21: =INDEX('Fcst Walk'!$J$5:$J$69,MATCH($C21,'Fcst Walk'!$A$5:$A$69,0))/INDEX('Fcst Walk'!$F$5:$F$69,MATCH($C21,'Fcst Walk'!$A$5:$A$69,0))-1 -> 0.029 | L21: =INDEX('Fcst Walk'!$N$5:$N$69,MATCH($C21,'Fcst Walk'!$A$5:$A$69,0))/INDEX('Fcst Walk'!$J$5:$J$69,MATCH($C21,'Fcst Walk'!$A$5:$A$69,0))-1 -> 0.027 | M21: =INDEX('Fcst Walk'!$R$5:$R$69,MATCH($C21,'Fcst Walk'!$A$5:$A$69,0))/INDEX('Fcst Walk'!$N$5:$N$69,MATCH($C21,'Fcst Walk'!$A$5:$A$69,0))-1 -> 0.028 | N21: =INDEX('Fcst Walk'!$J$5:$J$69,MATCH($C21,'Fcst Walk'!$A$5:$A$69,0))/$D21-1 -> 0.05531243 | O21: =INDEX('Fcst Walk'!$N$5:$N$69,MATCH($C21,'Fcst Walk'!$A$5:$A$69,0))/$D21-1 -> 0.083805866 | P21: =INDEX('Fcst Walk'!$R$5:$R$69,MATCH($C21,'Fcst Walk'!$A$5:$A$69,0))/$D21-1 -> 0.11415243 | Q21: =INDEX('Fcst Walk'!$AM$5:$AM$69,MATCH($C21,'Fcst Walk'!$A$5:$A$69,0)) -> 0 | R21: =INDEX('Fcst Walk'!$AN$5:$AN$69,MATCH($C21,'Fcst Walk'!$A$5:$A$69,0)) | S21: =AVERAGE(INDEX('Realpage - His. Rent Change'!$I$2:$AV$577,MATCH($C21,'Realpage - His. Rent Change'!$A$2:$A$577,0),0)) -> 0.060255 | U21: =IF(T21="",S21,AVERAGE(S21,T21)) -> 0.060255 | V21: =IF(H21>=0,0,-H21/U21) -> 0
B22: =ROW()-4 -> 18 | C22: Chattanooga, TN-GA | D22: =SUMIFS('Realpage Data'!$R$2:$R$899,'Realpage Data'!$A$2:$A$899,$C22,'Realpage Data'!$F$2:$F$899,"Rent Roll (Rev/OSF)") -> 1.3606319 | E22: =SUMIFS('Realpage Data'!$R$2:$R$899,'Realpage Data'!$A$2:$A$899,$C22,'Realpage Data'!$F$2:$F$899,"Asking RPSF") -> 1.44 | F22: =SUMIFS('Realpage Data'!$R$2:$R$899,'Realpage Data'!$A$2:$A$899,$C22,'Realpage Data'!$F$2:$F$899,"Effective RPSF") -> 1.395 | G22: =E22/$D22-1 -> 0.058331758 | H22: =F22/$D22-1 -> 0.025258891 | I22: =SUMIFS('RP - Unit Starts'!$AC$2:$AC$451,'RP - Unit Starts'!$A$2:$A$451,$C22,'RP - Unit Starts'!$F$2:$F$451,"Annual Unit Starts")/SUMIFS('RP - Unit Starts'!$AC$2:$AC$451,'RP - Unit Starts'!$A$2:$A$451,$C22,'RP - Unit Starts'!$F$2:$F$451,"Existing Units") -> 0.014355683 | J22: =SUMIFS('Realpage Data'!$V$2:$V$899,'Realpage Data'!$A$2:$A$899,$C22,'Realpage Data'!$F$2:$F$899,"Existing Units")/SUMIFS('Realpage Data'!$R$2:$R$899,'Realpage Data'!$A$2:$A$899,$C22,'Realpage Data'!$F$2:$F$899,"Existing Units")-1 -> 0.0063052412 | K22: =INDEX('Fcst Walk'!$J$5:$J$69,MATCH($C22,'Fcst Walk'!$A$5:$A$69,0))/INDEX('Fcst Walk'!$F$5:$F$69,MATCH($C22,'Fcst Walk'!$A$5:$A$69,0))-1 -> 0.023 | L22: =INDEX('Fcst Walk'!$N$5:$N$69,MATCH($C22,'Fcst Walk'!$A$5:$A$69,0))/INDEX('Fcst Walk'!$J$5:$J$69,MATCH($C22,'Fcst Walk'!$A$5:$A$69,0))-1 -> 0.026 | M22: =INDEX('Fcst Walk'!$R$5:$R$69,MATCH($C22,'Fcst Walk'!$A$5:$A$69,0))/INDEX('Fcst Walk'!$N$5:$N$69,MATCH($C22,'Fcst Walk'!$A$5:$A$69,0))-1 -> 0.019 | N22: =INDEX('Fcst Walk'!$J$5:$J$69,MATCH($C22,'Fcst Walk'!$A$5:$A$69,0))/$D22-1 -> 0.048839845 | O22: =INDEX('Fcst Walk'!$N$5:$N$69,MATCH($C22,'Fcst Walk'!$A$5:$A$69,0))/$D22-1 -> 0.076109681 | P22: =INDEX('Fcst Walk'!$R$5:$R$69,MATCH($C22,'Fcst Walk'!$A$5:$A$69,0))/$D22-1 -> 0.096555765 | Q22: =INDEX('Fcst Walk'!$AM$5:$AM$69,MATCH($C22,'Fcst Walk'!$A$5:$A$69,0)) -> 0 | R22: =INDEX('Fcst Walk'!$AN$5:$AN$69,MATCH($C22,'Fcst Walk'!$A$5:$A$69,0)) | S22: =AVERAGE(INDEX('Realpage - His. Rent Change'!$I$2:$AV$577,MATCH($C22,'Realpage - His. Rent Change'!$A$2:$A$577,0),0)) -> 0.0574675 | U22: =IF(T22="",S22,AVERAGE(S22,T22)) -> 0.0574675 | V22: =IF(H22>=0,0,-H22/U22) -> 0
B23: =ROW()-4 -> 19 | C23: Baton Rouge, LA | D23: =SUMIFS('Realpage Data'!$R$2:$R$899,'Realpage Data'!$A$2:$A$899,$C23,'Realpage Data'!$F$2:$F$899,"Rent Roll (Rev/OSF)") -> 1.2681901 | E23: =SUMIFS('Realpage Data'!$R$2:$R$899,'Realpage Data'!$A$2:$A$899,$C23,'Realpage Data'!$F$2:$F$899,"Asking RPSF") -> 1.316 | F23: =SUMIFS('Realpage Data'!$R$2:$R$899,'Realpage Data'!$A$2:$A$899,$C23,'Realpage Data'!$F$2:$F$899,"Effective RPSF") -> 1.3 | G23: =E23/$D23-1 -> 0.037699298 | H23: =F23/$D23-1 -> 0.025082893 | I23: =SUMIFS('RP - Unit Starts'!$AC$2:$AC$451,'RP - Unit Starts'!$A$2:$A$451,$C23,'RP - Unit Starts'!$F$2:$F$451,"Annual Unit Starts")/SUMIFS('RP - Unit Starts'!$AC$2:$AC$451,'RP - Unit Starts'!$A$2:$A$451,$C23,'RP - Unit Starts'!$F$2:$F$451,"Existing Units") -> 0.0059971168 | J23: =SUMIFS('Realpage Data'!$V$2:$V$899,'Realpage Data'!$A$2:$A$899,$C23,'Realpage Data'!$F$2:$F$899,"Existing Units")/SUMIFS('Realpage Data'!$R$2:$R$899,'Realpage Data'!$A$2:$A$899,$C23,'Realpage Data'!$F$2:$F$899,"Existing Units")-1 -> 0.0059971168 | K23: =INDEX('Fcst Walk'!$J$5:$J$69,MATCH($C23,'Fcst Walk'!$A$5:$A$69,0))/INDEX('Fcst Walk'!$F$5:$F$69,MATCH($C23,'Fcst Walk'!$A$5:$A$69,0))-1 -> 0.03 | L23: =INDEX('Fcst Walk'!$N$5:$N$69,MATCH($C23,'Fcst Walk'!$A$5:$A$69,0))/INDEX('Fcst Walk'!$J$5:$J$69,MATCH($C23,'Fcst Walk'!$A$5:$A$69,0))-1 -> 0.023 | M23: =INDEX('Fcst Walk'!$R$5:$R$69,MATCH($C23,'Fcst Walk'!$A$5:$A$69,0))/INDEX('Fcst Walk'!$N$5:$N$69,MATCH($C23,'Fcst Walk'!$A$5:$A$69,0))-1 -> 0.016 | N23: =INDEX('Fcst Walk'!$J$5:$J$69,MATCH($C23,'Fcst Walk'!$A$5:$A$69,0))/$D23-1 -> 0.05583538 | O23: =INDEX('Fcst Walk'!$N$5:$N$69,MATCH($C23,'Fcst Walk'!$A$5:$A$69,0))/$D23-1 -> 0.080119594 | P23: =INDEX('Fcst Walk'!$R$5:$R$69,MATCH($C23,'Fcst Walk'!$A$5:$A$69,0))/$D23-1 -> 0.097401507 | Q23: =INDEX('Fcst Walk'!$AM$5:$AM$69,MATCH($C23,'Fcst Walk'!$A$5:$A$69,0)) -> 0 | R23: =INDEX('Fcst Walk'!$AN$5:$AN$69,MATCH($C23,'Fcst Walk'!$A$5:$A$69,0)) | S23: =AVERAGE(INDEX('Realpage - His. Rent Change'!$I$2:$AV$577,MATCH($C23,'Realpage - His. Rent Change'!$A$2:$A$577,0),0)) -> 0.032635 | U23: =IF(T23="",S23,AVERAGE(S23,T23)) -> 0.032635 | V23: =IF(H23>=0,0,-H23/U23) -> 0
B24: =ROW()-4 -> 20 | C24: Kansas City, MO-KS | D24: =SUMIFS('Realpage Data'!$R$2:$R$899,'Realpage Data'!$A$2:$A$899,$C24,'Realpage Data'!$F$2:$F$899,"Rent Roll (Rev/OSF)") -> 1.4911626 | E24: =SUMIFS('Realpage Data'!$R$2:$R$899,'Realpage Data'!$A$2:$A$899,$C24,'Realpage Data'!$F$2:$F$899,"Asking RPSF") -> 1.536 | F24: =SUMIFS('Realpage Data'!$R$2:$R$899,'Realpage Data'!$A$2:$A$899,$C24,'Realpage Data'!$F$2:$F$899,"Effective RPSF") -> 1.523 | G24: =E24/$D24-1 -> 0.030068776 | H24: =F24/$D24-1 -> 0.021350746 | I24: =SUMIFS('RP - Unit Starts'!$AC$2:$AC$451,'RP - Unit Starts'!$A$2:$A$451,$C24,'RP - Unit Starts'!$F$2:$F$451,"Annual Unit Starts")/SUMIFS('RP - Unit Starts'!$AC$2:$AC$451,'RP - Unit Starts'!$A$2:$A$451,$C24,'RP - Unit Starts'!$F$2:$F$451,"Existing Units") -> 0.025479466 | J24: =SUMIFS('Realpage Data'!$V$2:$V$899,'Realpage Data'!$A$2:$A$899,$C24,'Realpage Data'!$F$2:$F$899,"Existing Units")/SUMIFS('Realpage Data'!$R$2:$R$899,'Realpage Data'!$A$2:$A$899,$C24,'Realpage Data'!$F$2:$F$899,"Existing Units")-1 -> 0.019850949 | K24: =INDEX('Fcst Walk'!$J$5:$J$69,MATCH($C24,'Fcst Walk'!$A$5:$A$69,0))/INDEX('Fcst Walk'!$F$5:$F$69,MATCH($C24,'Fcst Walk'!$A$5:$A$69,0))-1 -> 0.022 | L24: =INDEX('Fcst Walk'!$N$5:$N$69,MATCH($C24,'Fcst Walk'!$A$5:$A$69,0))/INDEX('Fcst Walk'!$J$5:$J$69,MATCH($C24,'Fcst Walk'!$A$5:$A$69,0))-1 -> 0.02 | M24: =INDEX('Fcst Walk'!$R$5:$R$69,MATCH($C24,'Fcst Walk'!$A$5:$A$69,0))/INDEX('Fcst Walk'!$N$5:$N$69,MATCH($C24,'Fcst Walk'!$A$5:$A$69,0))-1 -> 0.019 | N24: =INDEX('Fcst Walk'!$J$5:$J$69,MATCH($C24,'Fcst Walk'!$A$5:$A$69,0))/$D24-1 -> 0.043820462 | O24: =INDEX('Fcst Walk'!$N$5:$N$69,MATCH($C24,'Fcst Walk'!$A$5:$A$69,0))/$D24-1 -> 0.064696871 | P24: =INDEX('Fcst Walk'!$R$5:$R$69,MATCH($C24,'Fcst Walk'!$A$5:$A$69,0))/$D24-1 -> 0.084926112 | Q24: =INDEX('Fcst Walk'!$AM$5:$AM$69,MATCH($C24,'Fcst Walk'!$A$5:$A$69,0)) -> 0 | R24: =INDEX('Fcst Walk'!$AN$5:$AN$69,MATCH($C24,'Fcst Walk'!$A$5:$A$69,0)) | S24: =AVERAGE(INDEX('Realpage - His. Rent Change'!$I$2:$AV$577,MATCH($C24,'Realpage - His. Rent Change'!$A$2:$A$577,0),0)) -> 0.05285 | T24: 0.0367 | U24: =IF(T24="",S24,AVERAGE(S24,T24)) -> 0.044775 | V24: =IF(H24>=0,0,-H24/U24) -> 0
B25: =ROW()-4 -> 21 | C25: Minneapolis-St. Paul-Bloomington, MN-WI | D25: =SUMIFS('Realpage Data'!$R$2:$R$899,'Realpage Data'!$A$2:$A$899,$C25,'Realpage Data'!$F$2:$F$899,"Rent Roll (Rev/OSF)") -> 1.8554404 | E25: =SUMIFS('Realpage Data'!$R$2:$R$899,'Realpage Data'!$A$2:$A$899,$C25,'Realpage Data'!$F$2:$F$899,"Asking RPSF") -> 1.911 | F25: =SUMIFS('Realpage Data'!$R$2:$R$899,'Realpage Data'!$A$2:$A$899,$C25,'Realpage Data'!$F$2:$F$899,"Effective RPSF") -> 1.884 | G25: =E25/$D25-1 -> 0.029944173 | H25: =F25/$D25-1 -> 0.015392371 | I25: =SUMIFS('RP - Unit Starts'!$AC$2:$AC$451,'RP - Unit Starts'!$A$2:$A$451,$C25,'RP - Unit Starts'!$F$2:$F$451,"Annual Unit Starts")/SUMIFS('RP - Unit Starts'!$AC$2:$AC$451,'RP - Unit Starts'!$A$2:$A$451,$C25,'RP - Unit Starts'!$F$2:$F$451,"Existing Units") -> 0.0093966239 | J25: =SUMIFS('Realpage Data'!$V$2:$V$899,'Realpage Data'!$A$2:$A$899,$C25,'Realpage Data'!$F$2:$F$899,"Existing Units")/SUMIFS('Realpage Data'!$R$2:$R$899,'Realpage Data'!$A$2:$A$899,$C25,'Realpage Data'!$F$2:$F$899,"Existing Units")-1 -> 0.0072399254 | K25: =INDEX('Fcst Walk'!$J$5:$J$69,MATCH($C25,'Fcst Walk'!$A$5:$A$69,0))/INDEX('Fcst Walk'!$F$5:$F$69,MATCH($C25,'Fcst Walk'!$A$5:$A$69,0))-1 -> 0.019 | L25: =INDEX('Fcst Walk'!$N$5:$N$69,MATCH($C25,'Fcst Walk'!$A$5:$A$69,0))/INDEX('Fcst Walk'!$J$5:$J$69,MATCH($C25,'Fcst Walk'!$A$5:$A$69,0))-1 -> 0.021 | M25: =INDEX('Fcst Walk'!$R$5:$R$69,MATCH($C25,'Fcst Walk'!$A$5:$A$69,0))/INDEX('Fcst Walk'!$N$5:$N$69,MATCH($C25,'Fcst Walk'!$A$5:$A$69,0))-1 -> 0.021 | N25: =INDEX('Fcst Walk'!$J$5:$J$69,MATCH($C25,'Fcst Walk'!$A$5:$A$69,0))/$D25-1 -> 0.034684826 | O25: =INDEX('Fcst Walk'!$N$5:$N$69,MATCH($C25,'Fcst Walk'!$A$5:$A$69,0))/$D25-1 -> 0.056413208 | P25: =INDEX('Fcst Walk'!$R$5:$R$69,MATCH($C25,'Fcst Walk'!$A$5:$A$69,0))/$D25-1 -> 0.078597885 | Q25: =INDEX('Fcst Walk'!$AM$5:$AM$69,MATCH($C25,'Fcst Walk'!$A$5:$A$69,0)) -> 0 | R25: =INDEX('Fcst Walk'!$AN$5:$AN$69,MATCH($C25,'Fcst Walk'!$A$5:$A$69,0)) | S25: =AVERAGE(INDEX('Realpage - His. Rent Change'!$I$2:$AV$577,MATCH($C25,'Realpage - His. Rent Change'!$A$2:$A$577,0),0)) -> 0.0401575 | T25: 0.0264 | U25: =IF(T25="",S25,AVERAGE(S25,T25)) -> 0.03327875 | V25: =IF(H25>=0,0,-H25/U25) -> 0
B26: =ROW()-4 -> 22 | C26: West Palm Beach-Boca Raton-Delray Beach, FL | D26: =SUMIFS('Realpage Data'!$R$2:$R$899,'Realpage Data'!$A$2:$A$899,$C26,'Realpage Data'!$F$2:$F$899,"Rent Roll (Rev/OSF)") -> 2.4319646 | E26: =SUMIFS('Realpage Data'!$R$2:$R$899,'Realpage Data'!$A$2:$A$899,$C26,'Realpage Data'!$F$2:$F$899,"Asking RPSF") -> 2.461 | F26: =SUMIFS('Realpage Data'!$R$2:$R$899,'Realpage Data'!$A$2:$A$899,$C26,'Realpage Data'!$F$2:$F$899,"Effective RPSF") -> 2.449 | G26: =E26/$D26-1 -> 0.011939077 | H26: =F26/$D26-1 -> 0.007004795 | I26: =SUMIFS('RP - Unit Starts'!$AC$2:$AC$451,'RP - Unit Starts'!$A$2:$A$451,$C26,'RP - Unit Starts'!$F$2:$F$451,"Annual Unit Starts")/SUMIFS('RP - Unit Starts'!$AC$2:$AC$451,'RP - Unit Starts'!$A$2:$A$451,$C26,'RP - Unit Starts'!$F$2:$F$451,"Existing Units") -> 0.022218027 | J26: =SUMIFS('Realpage Data'!$V$2:$V$899,'Realpage Data'!$A$2:$A$899,$C26,'Realpage Data'!$F$2:$F$899,"Existing Units")/SUMIFS('Realpage Data'!$R$2:$R$899,'Realpage Data'!$A$2:$A$899,$C26,'Realpage Data'!$F$2:$F$899,"Existing Units")-1 -> 0.024090926 | K26: =INDEX('Fcst Walk'!$J$5:$J$69,MATCH($C26,'Fcst Walk'!$A$5:$A$69,0))/INDEX('Fcst Walk'!$F$5:$F$69,MATCH($C26,'Fcst Walk'!$A$5:$A$69,0))-1 -> 0.027 | L26: =INDEX('Fcst Walk'!$N$5:$N$69,MATCH($C26,'Fcst Walk'!$A$5:$A$69,0))/INDEX('Fcst Walk'!$J$5:$J$69,MATCH($C26,'Fcst Walk'!$A$5:$A$69,0))-1 -> 0.031 | M26: =INDEX('Fcst Walk'!$R$5:$R$69,MATCH($C26,'Fcst Walk'!$A$5:$A$69,0))/INDEX('Fcst Walk'!$N$5:$N$69,MATCH($C26,'Fcst Walk'!$A$5:$A$69,0))-1 -> 0.036 | N26: =INDEX('Fcst Walk'!$J$5:$J$69,MATCH($C26,'Fcst Walk'!$A$5:$A$69,0))/$D26-1 -> 0.034193925 | O26: =INDEX('Fcst Walk'!$N$5:$N$69,MATCH($C26,'Fcst Walk'!$A$5:$A$69,0))/$D26-1 -> 0.066253936 | P26: =INDEX('Fcst Walk'!$R$5:$R$69,MATCH($C26,'Fcst Walk'!$A$5:$A$69,0))/$D26-1 -> 0.10463908 | Q26: =INDEX('Fcst Walk'!$AM$5:$AM$69,MATCH($C26,'Fcst Walk'!$A$5:$A$69,0)) -> 0 | R26: =INDEX('Fcst Walk'!$AN$5:$AN$69,MATCH($C26,'Fcst Walk'!$A$5:$A$69,0)) | S26: =AVERAGE(INDEX('Realpage - His. Rent Change'!$I$2:$AV$577,MATCH($C26,'Realpage - His. Rent Change'!$A$2:$A$577,0),0)) -> 0.0611375 | T26: 0.0503 | U26: =IF(T26="",S26,AVERAGE(S26,T26)) -> 0.05571875 | V26: =IF(H26>=0,0,-H26/U26) -> 0
B27: =ROW()-4 -> 23 | C27: Myrtle Beach-Conway-North Myrtle Beach, SC | D27: =SUMIFS('Realpage Data'!$R$2:$R$899,'Realpage Data'!$A$2:$A$899,$C27,'Realpage Data'!$F$2:$F$899,"Rent Roll (Rev/OSF)") -> 1.4608809 | E27: =SUMIFS('Realpage Data'!$R$2:$R$899,'Realpage Data'!$A$2:$A$899,$C27,'Realpage Data'!$F$2:$F$899,"Asking RPSF") -> 1.531 | F27: =SUMIFS('Realpage Data'!$R$2:$R$899,'Realpage Data'!$A$2:$A$899,$C27,'Realpage Data'!$F$2:$F$899,"Effective RPSF") -> 1.466 | G27: =E27/$D27-1 -> 0.047997809 | H27: =F27/$D27-1 -> 0.0035041075 | I27: =SUMIFS('RP - Unit Starts'!$AC$2:$AC$451,'RP - Unit Starts'!$A$2:$A$451,$C27,'RP - Unit Starts'!$F$2:$F$451,"Annual Unit Starts")/SUMIFS('RP - Unit Starts'!$AC$2:$AC$451,'RP - Unit Starts'!$A$2:$A$451,$C27,'RP - Unit Starts'!$F$2:$F$451,"Existing Units") -> 0.010620863 | J27: =SUMIFS('Realpage Data'!$V$2:$V$899,'Realpage Data'!$A$2:$A$899,$C27,'Realpage Data'!$F$2:$F$899,"Existing Units")/SUMIFS('Realpage Data'!$R$2:$R$899,'Realpage Data'!$A$2:$A$899,$C27,'Realpage Data'!$F$2:$F$899,"Existing Units")-1 -> 0.0055977694 | K27: =INDEX('Fcst Walk'!$J$5:$J$69,MATCH($C27,'Fcst Walk'!$A$5:$A$69,0))/INDEX('Fcst Walk'!$F$5:$F$69,MATCH($C27,'Fcst Walk'!$A$5:$A$69,0))-1 -> 0.016 | L27: =INDEX('Fcst Walk'!$N$5:$N$69,MATCH($C27,'Fcst Walk'!$A$5:$A$69,0))/INDEX('Fcst Walk'!$J$5:$J$69,MATCH($C27,'Fcst Walk'!$A$5:$A$69,0))-1 -> 0.025 | M27: =INDEX('Fcst Walk'!$R$5:$R$69,MATCH($C27,'Fcst Walk'!$A$5:$A$69,0))/INDEX('Fcst Walk'!$N$5:$N$69,MATCH($C27,'Fcst Walk'!$A$5:$A$69,0))-1 -> 0.032 | N27: =INDEX('Fcst Walk'!$J$5:$J$69,MATCH($C27,'Fcst Walk'!$A$5:$A$69,0))/$D27-1 -> 0.019560173 | O27: =INDEX('Fcst Walk'!$N$5:$N$69,MATCH($C27,'Fcst Walk'!$A$5:$A$69,0))/$D27-1 -> 0.045049178 | P27: =INDEX('Fcst Walk'!$R$5:$R$69,MATCH($C27,'Fcst Walk'!$A$5:$A$69,0))/$D27-1 -> 0.078490751 | Q27: =INDEX('Fcst Walk'!$AM$5:$AM$69,MATCH($C27,'Fcst Walk'!$A$5:$A$69,0)) -> 0 | R27: =INDEX('Fcst Walk'!$AN$5:$AN$69,MATCH($C27,'Fcst Walk'!$A$5:$A$69,0)) | S27: =AVERAGE(INDEX('Realpage - His. Rent Change'!$I$2:$AV$577,MATCH($C27,'Realpage - His. Rent Change'!$A$2:$A$577,0),0)) -> 0.061405 | U27: =IF(T27="",S27,AVERAGE(S27,T27)) -> 0.061405 | V27: =IF(H27>=0,0,-H27/U27) -> 0
B28: =ROW()-4 -> 24 | C28: Lakeland-Winter Haven, FL | D28: =SUMIFS('Realpage Data'!$R$2:$R$899,'Realpage Data'!$A$2:$A$899,$C28,'Realpage Data'!$F$2:$F$899,"Rent Roll (Rev/OSF)") -> 1.4876528 | E28: =SUMIFS('Realpage Data'!$R$2:$R$899,'Realpage Data'!$A$2:$A$899,$C28,'Realpage Data'!$F$2:$F$899,"Asking RPSF") -> 1.539 | F28: =SUMIFS('Realpage Data'!$R$2:$R$899,'Realpage Data'!$A$2:$A$899,$C28,'Realpage Data'!$F$2:$F$899,"Effective RPSF") -> 1.485 | G28: =E28/$D28-1 -> 0.034515603 | H28: =F28/$D28-1 -> -0.00178319 | I28: =SUMIFS('RP - Unit Starts'!$AC$2:$AC$451,'RP - Unit Starts'!$A$2:$A$451,$C28,'RP - Unit Starts'!$F$2:$F$451,"Annual Unit Starts")/SUMIFS('RP - Unit Starts'!$AC$2:$AC$451,'RP - Unit Starts'!$A$2:$A$451,$C28,'RP - Unit Starts'!$F$2:$F$451,"Existing Units") -> 0.004371926 | J28: =SUMIFS('Realpage Data'!$V$2:$V$899,'Realpage Data'!$A$2:$A$899,$C28,'Realpage Data'!$F$2:$F$899,"Existing Units")/SUMIFS('Realpage Data'!$R$2:$R$899,'Realpage Data'!$A$2:$A$899,$C28,'Realpage Data'!$F$2:$F$899,"Existing Units")-1 -> 0.038748796 | K28: =INDEX('Fcst Walk'!$J$5:$J$69,MATCH($C28,'Fcst Walk'!$A$5:$A$69,0))/INDEX('Fcst Walk'!$F$5:$F$69,MATCH($C28,'Fcst Walk'!$A$5:$A$69,0))-1 -> 0.016 | L28: =INDEX('Fcst Walk'!$N$5:$N$69,MATCH($C28,'Fcst Walk'!$A$5:$A$69,0))/INDEX('Fcst Walk'!$J$5:$J$69,MATCH($C28,'Fcst Walk'!$A$5:$A$69,0))-1 -> 0.02 | M28: =INDEX('Fcst Walk'!$R$5:$R$69,MATCH($C28,'Fcst Walk'!$A$5:$A$69,0))/INDEX('Fcst Walk'!$N$5:$N$69,MATCH($C28,'Fcst Walk'!$A$5:$A$69,0))-1 -> 0.021 | N28: =INDEX('Fcst Walk'!$J$5:$J$69,MATCH($C28,'Fcst Walk'!$A$5:$A$69,0))/$D28-1 -> 0.014188279 | O28: =INDEX('Fcst Walk'!$N$5:$N$69,MATCH($C28,'Fcst Walk'!$A$5:$A$69,0))/$D28-1 -> 0.034472045 | P28: =INDEX('Fcst Walk'!$R$5:$R$69,MATCH($C28,'Fcst Walk'!$A$5:$A$69,0))/$D28-1 -> 0.056195957 | Q28: =INDEX('Fcst Walk'!$AM$5:$AM$69,MATCH($C28,'Fcst Walk'!$A$5:$A$69,0)) -> 0.049355652 | R28: =INDEX('Fcst Walk'!$AN$5:$AN$69,MATCH($C28,'Fcst Walk'!$A$5:$A$69,0)) | S28: =AVERAGE(INDEX('Realpage - His. Rent Change'!$I$2:$AV$577,MATCH($C28,'Realpage - His. Rent Change'!$A$2:$A$577,0),0)) -> 0.061055 | U28: =IF(T28="",S28,AVERAGE(S28,T28)) -> 0.061055 | V28: =IF(H28>=0,0,-H28/U28) -> 0.02920629
B29: =ROW()-4 -> 25 | C29: St. Louis, MO-IL | D29: =SUMIFS('Realpage Data'!$R$2:$R$899,'Realpage Data'!$A$2:$A$899,$C29,'Realpage Data'!$F$2:$F$899,"Rent Roll (Rev/OSF)") -> 1.5559508 | E29: =SUMIFS('Realpage Data'!$R$2:$R$899,'Realpage Data'!$A$2:$A$899,$C29,'Realpage Data'!$F$2:$F$899,"Asking RPSF") -> 1.573 | F29: =SUMIFS('Realpage Data'!$R$2:$R$899,'Realpage Data'!$A$2:$A$899,$C29,'Realpage Data'!$F$2:$F$899,"Effective RPSF") -> 1.559 | G29: =E29/$D29-1 -> 0.010957396 | H29: =F29/$D29-1 -> 0.0019596825 | I29: =SUMIFS('RP - Unit Starts'!$AC$2:$AC$451,'RP - Unit Starts'!$A$2:$A$451,$C29,'RP - Unit Starts'!$F$2:$F$451,"Annual Unit Starts")/SUMIFS('RP - Unit Starts'!$AC$2:$AC$451,'RP - Unit Starts'!$A$2:$A$451,$C29,'RP - Unit Starts'!$F$2:$F$451,"Existing Units") -> 0.011046634 | J29: =SUMIFS('Realpage Data'!$V$2:$V$899,'Realpage Data'!$A$2:$A$899,$C29,'Realpage Data'!$F$2:$F$899,"Existing Units")/SUMIFS('Realpage Data'!$R$2:$R$899,'Realpage Data'!$A$2:$A$899,$C29,'Realpage Data'!$F$2:$F$899,"Existing Units")-1 -> 0.0085189179 | K29: =INDEX('Fcst Walk'!$J$5:$J$69,MATCH($C29,'Fcst Walk'!$A$5:$A$69,0))/INDEX('Fcst Walk'!$F$5:$F$69,MATCH($C29,'Fcst Walk'!$A$5:$A$69,0))-1 -> 0.023 | L29: =INDEX('Fcst Walk'!$N$5:$N$69,MATCH($C29,'Fcst Walk'!$A$5:$A$69,0))/INDEX('Fcst Walk'!$J$5:$J$69,MATCH($C29,'Fcst Walk'!$A$5:$A$69,0))-1 -> 0.023 | M29: =INDEX('Fcst Walk'!$R$5:$R$69,MATCH($C29,'Fcst Walk'!$A$5:$A$69,0))/INDEX('Fcst Walk'!$N$5:$N$69,MATCH($C29,'Fcst Walk'!$A$5:$A$69,0))-1 -> 0.025 | N29: =INDEX('Fcst Walk'!$J$5:$J$69,MATCH($C29,'Fcst Walk'!$A$5:$A$69,0))/$D29-1 -> 0.025004755 | O29: =INDEX('Fcst Walk'!$N$5:$N$69,MATCH($C29,'Fcst Walk'!$A$5:$A$69,0))/$D29-1 -> 0.048579865 | P29: =INDEX('Fcst Walk'!$R$5:$R$69,MATCH($C29,'Fcst Walk'!$A$5:$A$69,0))/$D29-1 -> 0.074794361 | Q29: =INDEX('Fcst Walk'!$AM$5:$AM$69,MATCH($C29,'Fcst Walk'!$A$5:$A$69,0)) -> 0.53469497 | R29: =INDEX('Fcst Walk'!$AN$5:$AN$69,MATCH($C29,'Fcst Walk'!$A$5:$A$69,0)) | S29: =AVERAGE(INDEX('Realpage - His. Rent Change'!$I$2:$AV$577,MATCH($C29,'Realpage - His. Rent Change'!$A$2:$A$577,0),0)) -> 0.0515725 | U29: =IF(T29="",S29,AVERAGE(S29,T29)) -> 0.0515725 | V29: =IF(H29>=0,0,-H29/U29) -> 0
B30: =ROW()-4 -> 26 | C30: Greensboro-High Point/Winston-Salem/Burlington, NC | D30: =SUMIFS('Realpage Data'!$R$2:$R$899,'Realpage Data'!$A$2:$A$899,$C30,'Realpage Data'!$F$2:$F$899,"Rent Roll (Rev/OSF)") -> 1.3173564 | E30: =SUMIFS('Realpage Data'!$R$2:$R$899,'Realpage Data'!$A$2:$A$899,$C30,'Realpage Data'!$F$2:$F$899,"Asking RPSF") -> 1.34 | F30: =SUMIFS('Realpage Data'!$R$2:$R$899,'Realpage Data'!$A$2:$A$899,$C30,'Realpage Data'!$F$2:$F$899,"Effective RPSF") -> 1.323 | G30: =E30/$D30-1 -> 0.017188641 | H30: =F30/$D30-1 -> 0.0042840088 | I30: =SUMIFS('RP - Unit Starts'!$AC$2:$AC$451,'RP - Unit Starts'!$A$2:$A$451,$C30,'RP - Unit Starts'!$F$2:$F$451,"Annual Unit Starts")/SUMIFS('RP - Unit Starts'!$AC$2:$AC$451,'RP - Unit Starts'!$A$2:$A$451,$C30,'RP - Unit Starts'!$F$2:$F$451,"Existing Units") -> 0.015879717 | J30: =SUMIFS('Realpage Data'!$V$2:$V$899,'Realpage Data'!$A$2:$A$899,$C30,'Realpage Data'!$F$2:$F$899,"Existing Units")/SUMIFS('Realpage Data'!$R$2:$R$899,'Realpage Data'!$A$2:$A$899,$C30,'Realpage Data'!$F$2:$F$899,"Existing Units")-1 -> 0.011752542 | K30: =INDEX('Fcst Walk'!$J$5:$J$69,MATCH($C30,'Fcst Walk'!$A$5:$A$69,0))/INDEX('Fcst Walk'!$F$5:$F$69,MATCH($C30,'Fcst Walk'!$A$5:$A$69,0))-1 -> 0.026 | L30: =INDEX('Fcst Walk'!$N$5:$N$69,MATCH($C30,'Fcst Walk'!$A$5:$A$69,0))/INDEX('Fcst Walk'!$J$5:$J$69,MATCH($C30,'Fcst Walk'!$A$5:$A$69,0))-1 -> 0.028 | M30: =INDEX('Fcst Walk'!$R$5:$R$69,MATCH($C30,'Fcst Walk'!$A$5:$A$69,0))/INDEX('Fcst Walk'!$N$5:$N$69,MATCH($C30,'Fcst Walk'!$A$5:$A$69,0))-1 -> 0.027 | N30: =INDEX('Fcst Walk'!$J$5:$J$69,MATCH($C30,'Fcst Walk'!$A$5:$A$69,0))/$D30-1 -> 0.030395393 | O30: =INDEX('Fcst Walk'!$N$5:$N$69,MATCH($C30,'Fcst Walk'!$A$5:$A$69,0))/$D30-1 -> 0.059246464 | P30: =INDEX('Fcst Walk'!$R$5:$R$69,MATCH($C30,'Fcst Walk'!$A$5:$A$69,0))/$D30-1 -> 0.087846119 | Q30: =INDEX('Fcst Walk'!$AM$5:$AM$69,MATCH($C30,'Fcst Walk'!$A$5:$A$69,0)) -> 0.60584901 | R30: =INDEX('Fcst Walk'!$AN$5:$AN$69,MATCH($C30,'Fcst Walk'!$A$5:$A$69,0)) | S30: =AVERAGE(INDEX('Realpage - His. Rent Change'!$I$2:$AV$577,MATCH($C30,'Realpage - His. Rent Change'!$A$2:$A$577,0),0)) -> 0.05962 | U30: =IF(T30="",S30,AVERAGE(S30,T30)) -> 0.05962 | V30: =IF(H30>=0,0,-H30/U30) -> 0
B31: =ROW()-4 -> 27 | C31: Charleston-North Charleston, SC | D31: =SUMIFS('Realpage Data'!$R$2:$R$899,'Realpage Data'!$A$2:$A$899,$C31,'Realpage Data'!$F$2:$F$899,"Rent Roll (Rev/OSF)") -> 1.8198717 | E31: =SUMIFS('Realpage Data'!$R$2:$R$899,'Realpage Data'!$A$2:$A$899,$C31,'Realpage Data'!$F$2:$F$899,"Asking RPSF") -> 1.867 | F31: =SUMIFS('Realpage Data'!$R$2:$R$899,'Realpage Data'!$A$2:$A$899,$C31,'Realpage Data'!$F$2:$F$899,"Effective RPSF") -> 1.83 | G31: =E31/$D31-1 -> 0.02589652 | H31: =F31/$D31-1 -> 0.0055654159 | I31: =SUMIFS('RP - Unit Starts'!$AC$2:$AC$451,'RP - Unit Starts'!$A$2:$A$451,$C31,'RP - Unit Starts'!$F$2:$F$451,"Annual Unit Starts")/SUMIFS('RP - Unit Starts'!$AC$2:$AC$451,'RP - Unit Starts'!$A$2:$A$451,$C31,'RP - Unit Starts'!$F$2:$F$451,"Existing Units") -> 0.029310723 | J31: =SUMIFS('Realpage Data'!$V$2:$V$899,'Realpage Data'!$A$2:$A$899,$C31,'Realpage Data'!$F$2:$F$899,"Existing Units")/SUMIFS('Realpage Data'!$R$2:$R$899,'Realpage Data'!$A$2:$A$899,$C31,'Realpage Data'!$F$2:$F$899,"Existing Units")-1 -> 0.023974856 | K31: =INDEX('Fcst Walk'!$J$5:$J$69,MATCH($C31,'Fcst Walk'!$A$5:$A$69,0))/INDEX('Fcst Walk'!$F$5:$F$69,MATCH($C31,'Fcst Walk'!$A$5:$A$69,0))-1 -> 0.025 | L31: =INDEX('Fcst Walk'!$N$5:$N$69,MATCH($C31,'Fcst Walk'!$A$5:$A$69,0))/INDEX('Fcst Walk'!$J$5:$J$69,MATCH($C31,'Fcst Walk'!$A$5:$A$69,0))-1 -> 0.024 | M31: =INDEX('Fcst Walk'!$R$5:$R$69,MATCH($C31,'Fcst Walk'!$A$5:$A$69,0))/INDEX('Fcst Walk'!$N$5:$N$69,MATCH($C31,'Fcst Walk'!$A$5:$A$69,0))-1 -> 0.022 | N31: =INDEX('Fcst Walk'!$J$5:$J$69,MATCH($C31,'Fcst Walk'!$A$5:$A$69,0))/$D31-1 -> 0.030704551 | O31: =INDEX('Fcst Walk'!$N$5:$N$69,MATCH($C31,'Fcst Walk'!$A$5:$A$69,0))/$D31-1 -> 0.055441461 | P31: =INDEX('Fcst Walk'!$R$5:$R$69,MATCH($C31,'Fcst Walk'!$A$5:$A$69,0))/$D31-1 -> 0.078661173 | Q31: =INDEX('Fcst Walk'!$AM$5:$AM$69,MATCH($C31,'Fcst Walk'!$A$5:$A$69,0)) -> 0.6128969 | R31: =INDEX('Fcst Walk'!$AN$5:$AN$69,MATCH($C31,'Fcst Walk'!$A$5:$A$69,0)) | S31: =AVERAGE(INDEX('Realpage - His. Rent Change'!$I$2:$AV$577,MATCH($C31,'Realpage - His. Rent Change'!$A$2:$A$577,0),0)) -> 0.06082 | U31: =IF(T31="",S31,AVERAGE(S31,T31)) -> 0.06082 | V31: =IF(H31>=0,0,-H31/U31) -> 0
